Workbook

Sheet 3月
C2: SuccessHolders 勤務報告書 | M2: (西暦) | O2: 2023 | Q2: 年 | R2: ='2月'!R2+1 -> 3 | S2: 月分 | X2: ≪入力方法について≫
C3: 社員1 | Q3: 勤務日数： | S3: =COUNTA(E20:E50)&"日" -> 0日 | X3: ・太枠内の記載をお願いします。
C4: 派遣先企業名 | N4: 派遣先事業所名 | Y4: 業務内容等は必要があれば記載をお願いします。「入力例」タブをご確認ください。
C5: 派遣先住所
C6: 就業部署名 | N6: 連絡先 | X6: ・休憩時間が複数ある場合
C7: 業務に伴う責任の程度 | F7: (業務内容) | N7: 役職名 | R7: 部下 人数 | Y7: 休憩1-4に休憩時間を入力してください。
C8: 実際の就業場所 | M8: 勤怠パターン | O8: 勤務時間 | R8: 休憩時間 | T8: 規定時間 | Y8: 休憩1-4の、合計時間をJ列の「休憩時間」に直接入力してください。
P9: ～ | T9: =Q9-O9-R9 -> 0 | Y9: G列とI列の入力は不要です。
P10: ～ | T10: =Q10-O10-R10 -> 0
P11: ～ | T11: =Q11-O11-R11 -> 0 | X11: ・深夜時間の勤務の場合、時間は下記のように退勤時刻（例 34：00）の記載をお願いします。
P12: ～ | T12: =Q12-O12-R12 -> 0 | Y12: 例：18：00～翌日10：00の場合
P13: ～ | T13: =Q13-O13-R13 -> 0 | Z13: 出勤時刻（18：00） 退勤時刻（34：00）
B14: 氏名 | C14: 氏名 | O14: フレックスタイム制 | Z14: 18時＋6時間（18時～24時合計）+10時間（0時～10時合計）＝34時間
O15: 変形労働時間制
Y16: 休憩時間が1時間以外で複数ある場合は、J列の計算式を削除して休憩時間を直接入力してください↓
C17: 例 | E17: 0.375 | F17: 0.76041667 | G17: 0.5 | I17: 0.54166667 | X17: 例 | Y17: 0.5 | Z17: 0.54166667 | AA17: 0.71875 | AB17: 0.72916667 | AC17: 0.77083333 | AD17: 0.79166667 | AE17: 0.89583333 | AF17: 0.91666667
Y18: 休憩1 | AA18: 休憩2 | AC18: 休憩3 | AE18: 休憩4
A19: 祝日判定 | C19: 月 日 | D19: 曜 日 | E19: 出勤 時刻 | F19: 退勤 時刻 | G19: 休憩 時刻 | J19: 休憩 時間 | K19: 所定 時間 | L19: 法定外 残業 | M19: 深夜 時間 | N19: 不就労 | O19: 業務内容・作業進捗状況・その他 | T19: 出勤時刻(KOT) | U19: 退勤時刻 (KOT) | V19: 所定時間 (KOT) | W19: 所定時間 (調整) | Y19: 開始 | Z19: 終了 | AA19: 開始 | AB19: 終了 | AC19: 開始 | AD19: 終了 | AE19: 開始 | AF19: 終了 | AG19: 休憩時間
A20: =IF(COUNTIFS(祝日参照用!A:A,C20)=1,1,IF(D20="土",1,IF(D20="日",1,0))) -> 0 | C20: =IFERROR(DATE(O2,R2,1),"") -> 44986 | D20: =TEXT(C20,"aaa") -> 水 | H20: ～ | J20: =IFERROR(IF(G20="",0,I20-G20),"") -> 0 | K20: =IFERROR(IF(E20="",0,F20-E20-J20),"") -> 0 | L20: =IF(E20="",0,IF($A20=1,$K20,IF($C20="",0,IF($K20-$T$9<0,0,$K20-$T$9)))) -> 0 | T20: =E20 -> 0 | U20: =F20 -> 0 | V20: =IFERROR(IF(T20="",0,U20-T20-J20),"") -> 0 | W20: =IFERROR(FLOOR(K20,TIME(0,VLOOKUP($C$3,#REF!,22,0),0)),"") | AG20: =(Z20-Y20)+(AB20-AA20)+(AD20-AC20)+(AF20-AE20) -> 0
A21: =IF(COUNTIFS(祝日参照用!A:A,C21)=1,1,IF(D21="土",1,IF(D21="日",1,0))) -> 0 | C21: =IF(C20="","",IF(DAY(C20+1)=1,"",C20+1)) -> 44987 | D21: =TEXT(C21,"aaa") -> 木 | H21: ～ | J21: =IFERROR(IF(G21="",0,I21-G21),"") -> 0 | K21: =IFERROR(IF(E21="",0,F21-E21-J21),"") -> 0 | L21: =IF(E21="",0,IF($A21=1,$K21,IF($C21="",0,IF($K21-$T$9<0,0,$K21-$T$9)))) -> 0 | T21: =E21 -> 0 | U21: =F21 -> 0 | V21: =IFERROR(IF(T21="",0,U21-T21-J21),"") -> 0 | W21: =IFERROR(FLOOR(K21,TIME(0,VLOOKUP($C$3,#REF!,22,0),0)),"") | AG21: =(Z21-Y21)+(AB21-AA21)+(AD21-AC21)+(AF21-AE21) -> 0
A22: =IF(COUNTIFS(祝日参照用!A:A,C22)=1,1,IF(D22="土",1,IF(D22="日",1,0))) -> 0 | C22: =IF(C21="","",IF(DAY(C21+1)=1,"",C21+1)) -> 44988 | D22: =TEXT(C22,"aaa") -> 金 | H22: ～ | J22: =IFERROR(IF(G22="",0,I22-G22),"") -> 0 | K22: =IFERROR(IF(E22="",0,F22-E22-J22),"") -> 0 | L22: =IF(E22="",0,IF($A22=1,$K22,IF($C22="",0,IF($K22-$T$9<0,0,$K22-$T$9)))) -> 0 | T22: =E22 -> 0 | U22: =F22 -> 0 | V22: =IFERROR(IF(T22="",0,U22-T22-J22),"") -> 0 | W22: =IFERROR(FLOOR(K22,TIME(0,VLOOKUP($C$3,#REF!,22,0),0)),"") | AG22: =(Z22-Y22)+(AB22-AA22)+(AD22-AC22)+(AF22-AE22) -> 0
A23: =IF(COUNTIFS(祝日参照用!A:A,C23)=1,1,IF(D23="土",1,IF(D23="日",1,0))) -> 1 | C23: =IF(C22="","",IF(DAY(C22+1)=1,"",C22+1)) -> 44989 | D23: =TEXT(C23,"aaa") -> 土 | H23: ～ | J23: =IFERROR(IF(G23="",0,I23-G23),"") -> 0 | K23: =IFERROR(IF(E23="",0,F23-E23-J23),"") -> 0 | L23: =IF(E23="",0,IF($A23=1,$K23,IF($C23="",0,IF($K23-$T$9<0,0,$K23-$T$9)))) -> 0 | T23: =E23 -> 0 | U23: =F23 -> 0 | V23: =IFERROR(IF(T23="",0,U23-T23-J23),"") -> 0 | W23: =IFERROR(FLOOR(K23,TIME(0,VLOOKUP($C$3,#REF!,22,0),0)),"") | AG23: =(Z23-Y23)+(AB23-AA23)+(AD23-AC23)+(AF23-AE23) -> 0
A24: =IF(COUNTIFS(祝日参照用!A:A,C24)=1,1,IF(D24="土",1,IF(D24="日",1,0))) -> 1 | C24: =IF(C23="","",IF(DAY(C23+1)=1,"",C23+1)) -> 44990 | D24: =TEXT(C24,"aaa") -> 日 | H24: ～ | J24: =IFERROR(IF(G24="",0,I24-G24),"") -> 0 | K24: =IFERROR(IF(E24="",0,F24-E24-J24),"") -> 0 | L24: =IF(E24="",0,IF($A24=1,$K24,IF($C24="",0,IF($K24-$T$9<0,0,$K24-$T$9)))) -> 0 | T24: =E24 -> 0 | U24: =F24 -> 0 | V24: =IFERROR(IF(T24="",0,U24-T24-J24),"") -> 0 | W24: =IFERROR(FLOOR(K24,TIME(0,VLOOKUP($C$3,#REF!,22,0),0)),"") | AG24: =(Z24-Y24)+(AB24-AA24)+(AD24-AC24)+(AF24-AE24) -> 0
A25: =IF(COUNTIFS(祝日参照用!A:A,C25)=1,1,IF(D25="土",1,IF(D25="日",1,0))) -> 0 | C25: =IF(C24="","",IF(DAY(C24+1)=1,"",C24+1)) -> 44991 | D25: =TEXT(C25,"aaa") -> 月 | H25: ～ | J25: =IFERROR(IF(G25="",0,I25-G25),"") -> 0 | K25: =IFERROR(IF(E25="",0,F25-E25-J25),"") -> 0 | L25: =IF(E25="",0,IF($A25=1,$K25,IF($C25="",0,IF($K25-$T$9<0,0,$K25-$T$9)))) -> 0 | T25: =E25 -> 0 | U25: =F25 -> 0 | V25: =IFERROR(IF(T25="",0,U25-T25-J25),"") -> 0 | W25: =IFERROR(FLOOR(K25,TIME(0,VLOOKUP($C$3,#REF!,22,0),0)),"") | AG25: =(Z25-Y25)+(AB25-AA25)+(AD25-AC25)+(AF25-AE25) -> 0
A26: =IF(COUNTIFS(祝日参照用!A:A,C26)=1,1,IF(D26="土",1,IF(D26="日",1,0))) -> 0 | C26: =IF(C25="","",IF(DAY(C25+1)=1,"",C25+1)) -> 44992 | D26: =TEXT(C26,"aaa") -> 火 | H26: ～ | J26: =IFERROR(IF(G26="",0,I26-G26),"") -> 0 | K26: =IFERROR(IF(E26="",0,F26-E26-J26),"") -> 0 | L26: =IF(E26="",0,IF($A26=1,$K26,IF($C26="",0,IF($K26-$T$9<0,0,$K26-$T$9)))) -> 0 | T26: =E26 -> 0 | U26: =F26 -> 0 | V26: =IFERROR(IF(T26="",0,U26-T26-J26),"") -> 0 | W26: =IFERROR(FLOOR(K26,TIME(0,VLOOKUP($C$3,#REF!,22,0),0)),"") | AG26: =(Z26-Y26)+(AB26-AA26)+(AD26-AC26)+(AF26-AE26) -> 0
A27: =IF(COUNTIFS(祝日参照用!A:A,C27)=1,1,IF(D27="土",1,IF(D27="日",1,0))) -> 0 | C27: =IF(C26="","",IF(DAY(C26+1)=1,"",C26+1)) -> 44993 | D27: =TEXT(C27,"aaa") -> 水 | H27: ～ | J27: =IFERROR(IF(G27="",0,I27-G27),"") -> 0 | K27: =IFERROR(IF(E27="",0,F27-E27-J27),"") -> 0 | L27: =IF(E27="",0,IF($A27=1,$K27,IF($C27="",0,IF($K27-$T$9<0,0,$K27-$T$9)))) -> 0 | T27: =E27 -> 0 | U27: =F27 -> 0 | V27: =IFERROR(IF(T27="",0,U27-T27-J27),"") -> 0 | W27: =IFERROR(FLOOR(K27,TIME(0,VLOOKUP($C$3,#REF!,22,0),0)),"") | AG27: =(Z27-Y27)+(AB27-AA27)+(AD27-AC27)+(AF27-AE27) -> 0
A28: =IF(COUNTIFS(祝日参照用!A:A,C28)=1,1,IF(D28="土",1,IF(D28="日",1,0))) -> 0 | C28: =IF(C27="","",IF(DAY(C27+1)=1,"",C27+1)) -> 44994 | D28: =TEXT(C28,"aaa") -> 木 | H28: ～ | J28: =IFERROR(IF(G28="",0,I28-G28),"") -> 0 | K28: =IFERROR(IF(E28="",0,F28-E28-J28),"") -> 0 | L28: =IF(E28="",0,IF($A28=1,$K28,IF($C28="",0,IF($K28-$T$9<0,0,$K28-$T$9)))) -> 0 | T28: =E28 -> 0 | U28: =F28 -> 0 | V28: =IFERROR(IF(T28="",0,U28-T28-J28),"") -> 0 | W28: =IFERROR(FLOOR(K28,TIME(0,VLOOKUP($C$3,#REF!,22,0),0)),"") | AG28: =(Z28-Y28)+(AB28-AA28)+(AD28-AC28)+(AF28-AE28) -> 0
A29: =IF(COUNTIFS(祝日参照用!A:A,C29)=1,1,IF(D29="土",1,IF(D29="日",1,0))) -> 0 | C29: =IF(C28="","",IF(DAY(C28+1)=1,"",C28+1)) -> 44995 | D29: =TEXT(C29,"aaa") -> 金 | H29: ～ | J29: =IFERROR(IF(G29="",0,I29-G29),"") -> 0 | K29: =IFERROR(IF(E29="",0,F29-E29-J29),"") -> 0 | L29: =IF(E29="",0,IF($A29=1,$K29,IF($C29="",0,IF($K29-$T$9<0,0,$K29-$T$9)))) -> 0 | T29: =E29 -> 0 | U29: =F29 -> 0 | V29: =IFERROR(IF(T29="",0,U29-T29-J29),"") -> 0 | W29: =IFERROR(FLOOR(K29,TIME(0,VLOOKUP($C$3,#REF!,22,0),0)),"") | AG29: =(Z29-Y29)+(AB29-AA29)+(AD29-AC29)+(AF29-AE29) -> 0
A30: =IF(COUNTIFS(祝日参照用!A:A,C30)=1,1,IF(D30="土",1,IF(D30="日",1,0))) -> 1 | C30: =IF(C29="","",IF(DAY(C29+1)=1,"",C29+1)) -> 44996 | D30: =TEXT(C30,"aaa") -> 土 | H30: ～ | J30: =IFERROR(IF(G30="",0,I30-G30),"") -> 0 | K30: =IFERROR(IF(E30="",0,F30-E30-J30),"") -> 0 | L30: =IF(E30="",0,IF($A30=1,$K30,IF($C30="",0,IF($K30-$T$9<0,0,$K30-$T$9)))) -> 0 | T30: =E30 -> 0 | U30: =F30 -> 0 | V30: =IFERROR(IF(T30="",0,U30-T30-J30),"") -> 0 | W30: =IFERROR(FLOOR(K30,TIME(0,VLOOKUP($C$3,#REF!,22,0),0)),"") | AG30: =(Z30-Y30)+(AB30-AA30)+(AD30-AC30)+(AF30-AE30) -> 0
A31: =IF(COUNTIFS(祝日参照用!A:A,C31)=1,1,IF(D31="土",1,IF(D31="日",1,0))) -> 1 | C31: =IF(C30="","",IF(DAY(C30+1)=1,"",C30+1)) -> 44997 | D31: =TEXT(C31,"aaa") -> 日 | H31: ～ | J31: =IFERROR(IF(G31="",0,I31-G31),"") -> 0 | K31: =IFERROR(IF(E31="",0,F31-E31-J31),"") -> 0 | L31: =IF(E31="",0,IF($A31=1,$K31,IF($C31="",0,IF($K31-$T$9<0,0,$K31-$T$9)))) -> 0 | T31: =E31 -> 0 | U31: =F31 -> 0 | V31: =IFERROR(IF(T31="",0,U31-T31-J31),"") -> 0 | W31: =IFERROR(FLOOR(K31,TIME(0,VLOOKUP($C$3,#REF!,22,0),0)),"") | AG31: =(Z31-Y31)+(AB31-AA31)+(AD31-AC31)+(AF31-AE31) -> 0
A32: =IF(COUNTIFS(祝日参照用!A:A,C32)=1,1,IF(D32="土",1,IF(D32="日",1,0))) -> 0 | C32: =IF(C31="","",IF(DAY(C31+1)=1,"",C31+1)) -> 44998 | D32: =TEXT(C32,"aaa") -> 月 | H32: ～ | J32: =IFERROR(IF(G32="",0,I32-G32),"") -> 0 | K32: =IFERROR(IF(E32="",0,F32-E32-J32),"") -> 0 | L32: =IF(E32="",0,IF($A32=1,$K32,IF($C32="",0,IF($K32-$T$9<0,0,$K32-$T$9)))) -> 0 | T32: =E32 -> 0 | U32: =F32 -> 0 | V32: =IFERROR(IF(T32="",0,U32-T32-J32),"") -> 0 | W32: =IFERROR(FLOOR(K32,TIME(0,VLOOKUP($C$3,#REF!,22,0),0)),"") | AG32: =(Z32-Y32)+(AB32-AA32)+(AD32-AC32)+(AF32-AE32) -> 0
... A50: =IF(COUNTIFS(祝日参照用!A:A,C50)=1,1,IF(D50="土",1,IF(D50="日",1,0))) -> 0 | C50: =IF(C49="","",IF(DAY(C49+1)=1,"",C49+1)) -> 45016 | D50: =TEXT(C50,"aaa") -> 金 | H50: ～ | J50: =IFERROR(IF(G50="",0,I50-G50),"") -> 0 | K50: =IFERROR(IF(E50="",0,F50-E50-J50),"") -> 0 | L50: =IF(E50="",0,IF($A50=1,$K50,IF($C50="",0,IF($K50-$T$9<0,0,$K50-$T$9)))) -> 0 | T50: =E50 -> 0 | U50: =F50 -> 0 | V50: =IFERROR(IF(T50="",0,U50-T50-J50),"") -> 0 | W50: =IFERROR(FLOOR(K50,TIME(0,VLOOKUP($C$3,#REF!,22,0),0)),"") | AG50: =(Z50-Y50)+(AB50-AA50)+(AD50-AC50)+(AF50-AE50) -> 0
J51: =SUM(J20:J50) -> 0 | K51: =SUM(K20:K50) -> 0 | L51: =SUM(L20:L50) -> 0 | M51: =SUM(M20:M50) -> 0 | N51: =SUM(N20:N50) -> 0 | V51: =SUM(V20:V50) -> 0 | W51: =SUM(W20:W50) -> 0

Sheet 2月
C2: SuccessHolders 勤務報告書 | M2: (西暦) | O2: 2023 | Q2: 年 | R2: ='1月'!R2+1 -> 2 | S2: 月分 | X2: ≪入力方法について≫
C3: 社員1 | Q3: 勤務日数： | S3: =COUNTA(E20:E50)&"日" -> 0日 | X3: ・太枠内の記載をお願いします。
C4: 派遣先企業名 | N4: 派遣先事業所名 | Y4: 業務内容等は必要があれば記載をお願いします。「入力例」タブをご確認ください。
C5: 派遣先住所
C6: 就業部署名 | N6: 連絡先 | X6: ・休憩時間が複数ある場合
C7: 業務に伴う責任の程度 | F7: (業務内容) | N7: 役職名 | R7: 部下 人数 | Y7: 休憩1-4に休憩時間を入力してください。
C8: 実際の就業場所 | M8: 勤怠パターン | O8: 勤務時間 | R8: 休憩時間 | T8: 規定時間 | Y8: 休憩1-4の、合計時間をJ列の「休憩時間」に直接入力してください。
P9: ～ | T9: =Q9-O9-R9 -> 0 | Y9: G列とI列の入力は不要です。
P10: ～ | T10: =Q10-O10-R10 -> 0
P11: ～ | T11: =Q11-O11-R11 -> 0 | X11: ・深夜時間の勤務の場合、時間は下記のように退勤時刻（例 34：00）の記載をお願いします。
P12: ～ | T12: =Q12-O12-R12 -> 0 | Y12: 例：18：00～翌日10：00の場合
P13: ～ | T13: =Q13-O13-R13 -> 0 | Z13: 出勤時刻（18：00） 退勤時刻（34：00）
B14: 氏名 | C14: 氏名 | O14: フレックスタイム制 | Z14: 18時＋6時間（18時～24時合計）+10時間（0時～10時合計）＝34時間
O15: 変形労働時間制
Y16: 休憩時間が1時間以外で複数ある場合は、J列の計算式を削除して休憩時間を直接入力してください↓
C17: 例 | E17: 0.375 | F17: 0.76041667 | G17: 0.5 | I17: 0.54166667 | X17: 例 | Y17: 0.5 | Z17: 0.54166667 | AA17: 0.71875 | AB17: 0.72916667 | AC17: 0.77083333 | AD17: 0.79166667 | AE17: 0.89583333 | AF17: 0.91666667
Y18: 休憩1 | AA18: 休憩2 | AC18: 休憩3 | AE18: 休憩4
A19: 祝日判定 | C19: 月 日 | D19: 曜 日 | E19: 出勤 時刻 | F19: 退勤 時刻 | G19: 休憩 時刻 | J19: 休憩 時間 | K19: 所定 時間 | L19: 法定外 残業 | M19: 深夜 時間 | N19: 不就労 | O19: 業務内容・作業進捗状況・その他 | T19: 出勤時刻(KOT) | U19: 退勤時刻 (KOT) | V19: 所定時間 (KOT) | W19: 所定時間 (調整) | Y19: 開始 | Z19: 終了 | AA19: 開始 | AB19: 終了 | AC19: 開始 | AD19: 終了 | AE19: 開始 | AF19: 終了 | AG19: 休憩時間
A20: =IF(COUNTIFS(祝日参照用!A:A,C20)=1,1,IF(D20="土",1,IF(D20="日",1,0))) -> 0 | C20: =IFERROR(DATE(O2,R2,1),"") -> 44958 | D20: =TEXT(C20,"aaa") -> 水 | H20: ～ | J20: =IFERROR(IF(G20="",0,I20-G20),"") -> 0 | K20: =IFERROR(IF(E20="",0,F20-E20-J20),"") -> 0 | L20: =IF(E20="",0,IF($A20=1,$K20,IF($C20="",0,IF($K20-$T$9<0,0,$K20-$T$9)))) -> 0 | T20: =E20 -> 0 | U20: =F20 -> 0 | V20: =IFERROR(IF(T20="",0,U20-T20-J20),"") -> 0 | W20: =IFERROR(FLOOR(K20,TIME(0,VLOOKUP($C$3,#REF!,22,0),0)),"") | AG20: =(Z20-Y20)+(AB20-AA20)+(AD20-AC20)+(AF20-AE20) -> 0
A21: =IF(COUNTIFS(祝日参照用!A:A,C21)=1,1,IF(D21="土",1,IF(D21="日",1,0))) -> 0 | C21: =IF(C20="","",IF(DAY(C20+1)=1,"",C20+1)) -> 44959 | D21: =TEXT(C21,"aaa") -> 木 | H21: ～ | J21: =IFERROR(IF(G21="",0,I21-G21),"") -> 0 | K21: =IFERROR(IF(E21="",0,F21-E21-J21),"") -> 0 | L21: =IF(E21="",0,IF($A21=1,$K21,IF($C21="",0,IF($K21-$T$9<0,0,$K21-$T$9)))) -> 0 | T21: =E21 -> 0 | U21: =F21 -> 0 | V21: =IFERROR(IF(T21="",0,U21-T21-J21),"") -> 0 | W21: =IFERROR(FLOOR(K21,TIME(0,VLOOKUP($C$3,#REF!,22,0),0)),"") | AG21: =(Z21-Y21)+(AB21-AA21)+(AD21-AC21)+(AF21-AE21) -> 0
A22: =IF(COUNTIFS(祝日参照用!A:A,C22)=1,1,IF(D22="土",1,IF(D22="日",1,0))) -> 0 | C22: =IF(C21="","",IF(DAY(C21+1)=1,"",C21+1)) -> 44960 | D22: =TEXT(C22,"aaa") -> 金 | H22: ～ | J22: =IFERROR(IF(G22="",0,I22-G22),"") -> 0 | K22: =IFERROR(IF(E22="",0,F22-E22-J22),"") -> 0 | L22: =IF(E22="",0,IF($A22=1,$K22,IF($C22="",0,IF($K22-$T$9<0,0,$K22-$T$9)))) -> 0 | T22: =E22 -> 0 | U22: =F22 -> 0 | V22: =IFERROR(IF(T22="",0,U22-T22-J22),"") -> 0 | W22: =IFERROR(FLOOR(K22,TIME(0,VLOOKUP($C$3,#REF!,22,0),0)),"") | AG22: =(Z22-Y22)+(AB22-AA22)+(AD22-AC22)+(AF22-AE22) -> 0
A23: =IF(COUNTIFS(祝日参照用!A:A,C23)=1,1,IF(D23="土",1,IF(D23="日",1,0))) -> 1 | C23: =IF(C22="","",IF(DAY(C22+1)=1,"",C22+1)) -> 44961 | D23: =TEXT(C23,"aaa") -> 土 | H23: ～ | J23: =IFERROR(IF(G23="",0,I23-G23),"") -> 0 | K23: =IFERROR(IF(E23="",0,F23-E23-J23),"") -> 0 | L23: =IF(E23="",0,IF($A23=1,$K23,IF($C23="",0,IF($K23-$T$9<0,0,$K23-$T$9)))) -> 0 | T23: =E23 -> 0 | U23: =F23 -> 0 | V23: =IFERROR(IF(T23="",0,U23-T23-J23),"") -> 0 | W23: =IFERROR(FLOOR(K23,TIME(0,VLOOKUP($C$3,#REF!,22,0),0)),"") | AG23: =(Z23-Y23)+(AB23-AA23)+(AD23-AC23)+(AF23-AE23) -> 0
A24: =IF(COUNTIFS(祝日参照用!A:A,C24)=1,1,IF(D24="土",1,IF(D24="日",1,0))) -> 1 | C24: =IF(C23="","",IF(DAY(C23+1)=1,"",C23+1)) -> 44962 | D24: =TEXT(C24,"aaa") -> 日 | H24: ～ | J24: =IFERROR(IF(G24="",0,I24-G24),"") -> 0 | K24: =IFERROR(IF(E24="",0,F24-E24-J24),"") -> 0 | L24: =IF(E24="",0,IF($A24=1,$K24,IF($C24="",0,IF($K24-$T$9<0,0,$K24-$T$9)))) -> 0 | T24: =E24 -> 0 | U24: =F24 -> 0 | V24: =IFERROR(IF(T24="",0,U24-T24-J24),"") -> 0 | W24: =IFERROR(FLOOR(K24,TIME(0,VLOOKUP($C$3,#REF!,22,0),0)),"") | AG24: =(Z24-Y24)+(AB24-AA24)+(AD24-AC24)+(AF24-AE24) -> 0
A25: =IF(COUNTIFS(祝日参照用!A:A,C25)=1,1,IF(D25="土",1,IF(D25="日",1,0))) -> 0 | C25: =IF(C24="","",IF(DAY(C24+1)=1,"",C24+1)) -> 44963 | D25: =TEXT(C25,"aaa") -> 月 | H25: ～ | J25: =IFERROR(IF(G25="",0,I25-G25),"") -> 0 | K25: =IFERROR(IF(E25="",0,F25-E25-J25),"") -> 0 | L25: =IF(E25="",0,IF($A25=1,$K25,IF($C25="",0,IF($K25-$T$9<0,0,$K25-$T$9)))) -> 0 | T25: =E25 -> 0 | U25: =F25 -> 0 | V25: =IFERROR(IF(T25="",0,U25-T25-J25),"") -> 0 | W25: =IFERROR(FLOOR(K25,TIME(0,VLOOKUP($C$3,#REF!,22,0),0)),"") | AG25: =(Z25-Y25)+(AB25-AA25)+(AD25-AC25)+(AF25-AE25) -> 0
A26: =IF(COUNTIFS(祝日参照用!A:A,C26)=1,1,IF(D26="土",1,IF(D26="日",1,0))) -> 0 | C26: =IF(C25="","",IF(DAY(C25+1)=1,"",C25+1)) -> 44964 | D26: =TEXT(C26,"aaa") -> 火 | H26: ～ | J26: =IFERROR(IF(G26="",0,I26-G26),"") -> 0 | K26: =IFERROR(IF(E26="",0,F26-E26-J26),"") -> 0 | L26: =IF(E26="",0,IF($A26=1,$K26,IF($C26="",0,IF($K26-$T$9<0,0,$K26-$T$9)))) -> 0 | T26: =E26 -> 0 | U26: =F26 -> 0 | V26: =IFERROR(IF(T26="",0,U26-T26-J26),"") -> 0 | W26: =IFERROR(FLOOR(K26,TIME(0,VLOOKUP($C$3,#REF!,22,0),0)),"") | AG26: =(Z26-Y26)+(AB26-AA26)+(AD26-AC26)+(AF26-AE26) -> 0
A27: =IF(COUNTIFS(祝日参照用!A:A,C27)=1,1,IF(D27="土",1,IF(D27="日",1,0))) -> 0 | C27: =IF(C26="","",IF(DAY(C26+1)=1,"",C26+1)) -> 44965 | D27: =TEXT(C27,"aaa") -> 水 | H27: ～ | J27: =IFERROR(IF(G27="",0,I27-G27),"") -> 0 | K27: =IFERROR(IF(E27="",0,F27-E27-J27),"") -> 0 | L27: =IF(E27="",0,IF($A27=1,$K27,IF($C27="",0,IF($K27-$T$9<0,0,$K27-$T$9)))) -> 0 | T27: =E27 -> 0 | U27: =F27 -> 0 | V27: =IFERROR(IF(T27="",0,U27-T27-J27),"") -> 0 | W27: =IFERROR(FLOOR(K27,TIME(0,VLOOKUP($C$3,#REF!,22,0),0)),"") | AG27: =(Z27-Y27)+(AB27-AA27)+(AD27-AC27)+(AF27-AE27) -> 0
A28: =IF(COUNTIFS(祝日参照用!A:A,C28)=1,1,IF(D28="土",1,IF(D28="日",1,0))) -> 0 | C28: =IF(C27="","",IF(DAY(C27+1)=1,"",C27+1)) -> 44966 | D28: =TEXT(C28,"aaa") -> 木 | H28: ～ | J28: =IFERROR(IF(G28="",0,I28-G28),"") -> 0 | K28: =IFERROR(IF(E28="",0,F28-E28-J28),"") -> 0 | L28: =IF(E28="",0,IF($A28=1,$K28,IF($C28="",0,IF($K28-$T$9<0,0,$K28-$T$9)))) -> 0 | T28: =E28 -> 0 | U28: =F28 -> 0 | V28: =IFERROR(IF(T28="",0,U28-T28-J28),"") -> 0 | W28: =IFERROR(FLOOR(K28,TIME(0,VLOOKUP($C$3,#REF!,22,0),0)),"") | AG28: =(Z28-Y28)+(AB28-AA28)+(AD28-AC28)+(AF28-AE28) -> 0
A29: =IF(COUNTIFS(祝日参照用!A:A,C29)=1,1,IF(D29="土",1,IF(D29="日",1,0))) -> 0 | C29: =IF(C28="","",IF(DAY(C28+1)=1,"",C28+1)) -> 44967 | D29: =TEXT(C29,"aaa") -> 金 | H29: ～ | J29: =IFERROR(IF(G29="",0,I29-G29),"") -> 0 | K29: =IFERROR(IF(E29="",0,F29-E29-J29),"") -> 0 | L29: =IF(E29="",0,IF($A29=1,$K29,IF($C29="",0,IF($K29-$T$9<0,0,$K29-$T$9)))) -> 0 | T29: =E29 -> 0 | U29: =F29 -> 0 | V29: =IFERROR(IF(T29="",0,U29-T29-J29),"") -> 0 | W29: =IFERROR(FLOOR(K29,TIME(0,VLOOKUP($C$3,#REF!,22,0),0)),"") | AG29: =(Z29-Y29)+(AB29-AA29)+(AD29-AC29)+(AF29-AE29) -> 0
A30: =IF(COUNTIFS(祝日参照用!A:A,C30)=1,1,IF(D30="土",1,IF(D30="日",1,0))) -> 1 | C30: =IF(C29="","",IF(DAY(C29+1)=1,"",C29+1)) -> 44968 | D30: =TEXT(C30,"aaa") -> 土 | H30: ～ | J30: =IFERROR(IF(G30="",0,I30-G30),"") -> 0 | K30: =IFERROR(IF(E30="",0,F30-E30-J30),"") -> 0 | L30: =IF(E30="",0,IF($A30=1,$K30,IF($C30="",0,IF($K30-$T$9<0,0,$K30-$T$9)))) -> 0 | T30: =E30 -> 0 | U30: =F30 -> 0 | V30: =IFERROR(IF(T30="",0,U30-T30-J30),"") -> 0 | W30: =IFERROR(FLOOR(K30,TIME(0,VLOOKUP($C$3,#REF!,22,0),0)),"") | AG30: =(Z30-Y30)+(AB30-AA30)+(AD30-AC30)+(AF30-AE30) -> 0
A31: =IF(COUNTIFS(祝日参照用!A:A,C31)=1,1,IF(D31="土",1,IF(D31="日",1,0))) -> 1 | C31: =IF(C30="","",IF(DAY(C30+1)=1,"",C30+1)) -> 44969 | D31: =TEXT(C31,"aaa") -> 日 | H31: ～ | J31: =IFERROR(IF(G31="",0,I31-G31),"") -> 0 | K31: =IFERROR(IF(E31="",0,F31-E31-J31),"") -> 0 | L31: =IF(E31="",0,IF($A31=1,$K31,IF($C31="",0,IF($K31-$T$9<0,0,$K31-$T$9)))) -> 0 | T31: =E31 -> 0 | U31: =F31 -> 0 | V31: =IFERROR(IF(T31="",0,U31-T31-J31),"") -> 0 | W31: =IFERROR(FLOOR(K31,TIME(0,VLOOKUP($C$3,#REF!,22,0),0)),"") | AG31: =(Z31-Y31)+(AB31-AA31)+(AD31-AC31)+(AF31-AE31) -> 0
A32: =IF(COUNTIFS(祝日参照用!A:A,C32)=1,1,IF(D32="土",1,IF(D32="日",1,0))) -> 0 | C32: =IF(C31="","",IF(DAY(C31+1)=1,"",C31+1)) -> 44970 | D32: =TEXT(C32,"aaa") -> 月 | H32: ～ | J32: =IFERROR(IF(G32="",0,I32-G32),"") -> 0 | K32: =IFERROR(IF(E32="",0,F32-E32-J32),"") -> 0 | L32: =IF(E32="",0,IF($A32=1,$K32,IF($C32="",0,IF($K32-$T$9<0,0,$K32-$T$9)))) -> 0 | T32: =E32 -> 0 | U32: =F32 -> 0 | V32: =IFERROR(IF(T32="",0,U32-T32-J32),"") -> 0 | W32: =IFERROR(FLOOR(K32,TIME(0,VLOOKUP($C$3,#REF!,22,0),0)),"") | AG32: =(Z32-Y32)+(AB32-AA32)+(AD32-AC32)+(AF32-AE32) -> 0
... A50: =IF(COUNTIFS(祝日参照用!A:A,C50)=1,1,IF(D50="土",1,IF(D50="日",1,0))) -> 0 | C50: =IF(C49="","",IF(DAY(C49+1)=1,"",C49+1)) | D50: =TEXT(C50,"aaa") | H50: ～ | J50: =IFERROR(IF(G50="",0,I50-G50),"") -> 0 | K50: =IFERROR(IF(E50="",0,F50-E50-J50),"") -> 0 | L50: =IF(E50="",0,IF($A50=1,$K50,IF($C50="",0,IF($K50-$T$9<0,0,$K50-$T$9)))) -> 0 | T50: =E50 -> 0 | U50: =F50 -> 0 | V50: =IFERROR(IF(T50="",0,U50-T50-J50),"") -> 0 | W50: =IFERROR(FLOOR(K50,TIME(0,VLOOKUP($C$3,#REF!,22,0),0)),"") | AG50: =(Z50-Y50)+(AB50-AA50)+(AD50-AC50)+(AF50-AE50) -> 0
J51: =SUM(J20:J50) -> 0 | K51: =SUM(K20:K50) -> 0 | L51: =SUM(L20:L50) -> 0 | M51: =SUM(M20:M50) -> 0 | N51: =SUM(N20:N50) -> 0 | V51: =SUM(V20:V50) -> 0 | W51: =SUM(W20:W50) -> 0

Sheet 1月
C2: SuccessHolders 勤務報告書 | M2: (西暦) | O2: 2023 | Q2: 年 | R2: 1 | S2: 月分 | X2: ≪入力方法について≫
C3: 社員1 | Q3: 勤務日数： | S3: =COUNTA(E20:E50)&"日" -> 0日 | X3: ・太枠内の記載をお願いします。
C4: 派遣先企業名 | N4: 派遣先事業所名 | Y4: 業務内容等は必要があれば記載をお願いします。「入力例」タブをご確認ください。
C5: 派遣先住所
C6: 就業部署名 | N6: 連絡先 | X6: ・休憩時間が複数ある場合
C7: 業務に伴う責任の程度 | F7: (業務内容) | N7: 役職名 | R7: 部下 人数 | Y7: 休憩1-4に休憩時間を入力してください。
C8: 実際の就業場所 | M8: 勤怠パターン | O8: 勤務時間 | R8: 休憩時間 | T8: 規定時間 | Y8: 休憩1-4の、合計時間をJ列の「休憩時間」に直接入力してください。
P9: ～ | T9: =Q9-O9-R9 -> 0 | Y9: G列とI列の入力は不要です。
P10: ～ | T10: =Q10-O10-R10 -> 0
P11: ～ | T11: =Q11-O11-R11 -> 0 | X11: ・深夜時間の勤務の場合、時間は下記のように退勤時刻（例 34：00）の記載をお願いします。
P12: ～ | T12: =Q12-O12-R12 -> 0 | Y12: 例：18：00～翌日10：00の場合
P13: ～ | T13: =Q13-O13-R13 -> 0 | Z13: 出勤時刻（18：00） 退勤時刻（34：00）
B14: 氏名 | C14: 氏名 | O14: フレックスタイム制 | Z14: 18時＋6時間（18時～24時合計）+10時間（0時～10時合計）＝34時間
O15: 変形労働時間制
Y16: 休憩時間が1時間以外で複数ある場合は、J列の計算式を削除して休憩時間を直接入力してください↓
C17: 例 | E17: 0.375 | F17: 0.76041667 | G17: 0.5 | I17: 0.54166667 | X17: 例 | Y17: 0.5 | Z17: 0.54166667 | AA17: 0.71875 | AB17: 0.72916667 | AC17: 0.77083333 | AD17: 0.79166667 | AE17: 0.89583333 | AF17: 0.91666667
Y18: 休憩1 | AA18: 休憩2 | AC18: 休憩3 | AE18: 休憩4
A19: 祝日判定 | C19: 月 日 | D19: 曜 日 | E19: 出勤 時刻 | F19: 退勤 時刻 | G19: 休憩 時刻 | J19: 休憩 時間 | K19: 所定 時間 | L19: 法定外 残業 | M19: 深夜 時間 | N19: 不就労 | O19: 業務内容・作業進捗状況・その他 | T19: 出勤時刻(KOT) | U19: 退勤時刻 (KOT) | V19: 所定時間 (KOT) | W19: 所定時間 (調整) | Y19: 開始 | Z19: 終了 | AA19: 開始 | AB19: 終了 | AC19: 開始 | AD19: 終了 | AE19: 開始 | AF19: 終了 | AG19: 休憩時間
A20: =IF(COUNTIFS(祝日参照用!A:A,C20)=1,1,IF(D20="土",1,IF(D20="日",1,0))) -> 1 | C20: =IFERROR(DATE(O2,R2,1),"") -> 44927 | D20: =TEXT(C20,"aaa") -> 日 | H20: ～ | J20: =IFERROR(IF(G20="",0,I20-G20),"") -> 0 | K20: =IFERROR(IF(E20="",0,F20-E20-J20),"") -> 0 | L20: =IF(E20="",0,IF($A20=1,$K20,IF($C20="",0,IF($K20-$T$9<0,0,$K20-$T$9)))) -> 0 | T20: =E20 -> 0 | U20: =F20 -> 0 | V20: =IFERROR(IF(T20="",0,U20-T20-J20),"") -> 0 | W20: =IFERROR(FLOOR(K20,TIME(0,VLOOKUP($C$3,#REF!,22,0),0)),"") | AG20: =(Z20-Y20)+(AB20-AA20)+(AD20-AC20)+(AF20-AE20) -> 0
A21: =IF(COUNTIFS(祝日参照用!A:A,C21)=1,1,IF(D21="土",1,IF(D21="日",1,0))) -> 1 | C21: =IF(C20="","",IF(DAY(C20+1)=1,"",C20+1)) -> 44928 | D21: =TEXT(C21,"aaa") -> 月 | H21: ～ | J21: =IFERROR(IF(G21="",0,I21-G21),"") -> 0 | K21: =IFERROR(IF(E21="",0,F21-E21-J21),"") -> 0 | L21: =IF(E21="",0,IF($A21=1,$K21,IF($C21="",0,IF($K21-$T$9<0,0,$K21-$T$9)))) -> 0 | T21: =E21 -> 0 | U21: =F21 -> 0 | V21: =IFERROR(IF(T21="",0,U21-T21-J21),"") -> 0 | W21: =IFERROR(FLOOR(K21,TIME(0,VLOOKUP($C$3,#REF!,22,0),0)),"") | AG21: =(Z21-Y21)+(AB21-AA21)+(AD21-AC21)+(AF21-AE21) -> 0
A22: =IF(COUNTIFS(祝日参照用!A:A,C22)=1,1,IF(D22="土",1,IF(D22="日",1,0))) -> 1 | C22: =IF(C21="","",IF(DAY(C21+1)=1,"",C21+1)) -> 44929 | D22: =TEXT(C22,"aaa") -> 火 | H22: ～ | J22: =IFERROR(IF(G22="",0,I22-G22),"") -> 0 | K22: =IFERROR(IF(E22="",0,F22-E22-J22),"") -> 0 | L22: =IF(E22="",0,IF($A22=1,$K22,IF($C22="",0,IF($K22-$T$9<0,0,$K22-$T$9)))) -> 0 | T22: =E22 -> 0 | U22: =F22 -> 0 | V22: =IFERROR(IF(T22="",0,U22-T22-J22),"") -> 0 | W22: =IFERROR(FLOOR(K22,TIME(0,VLOOKUP($C$3,#REF!,22,0),0)),"") | AG22: =(Z22-Y22)+(AB22-AA22)+(AD22-AC22)+(AF22-AE22) -> 0
A23: =IF(COUNTIFS(祝日参照用!A:A,C23)=1,1,IF(D23="土",1,IF(D23="日",1,0))) -> 0 | C23: =IF(C22="","",IF(DAY(C22+1)=1,"",C22+1)) -> 44930 | D23: =TEXT(C23,"aaa") -> 水 | H23: ～ | J23: =IFERROR(IF(G23="",0,I23-G23),"") -> 0 | K23: =IFERROR(IF(E23="",0,F23-E23-J23),"") -> 0 | L23: =IF(E23="",0,IF($A23=1,$K23,IF($C23="",0,IF($K23-$T$9<0,0,$K23-$T$9)))) -> 0 | T23: =E23 -> 0 | U23: =F23 -> 0 | V23: =IFERROR(IF(T23="",0,U23-T23-J23),"") -> 0 | W23: =IFERROR(FLOOR(K23,TIME(0,VLOOKUP($C$3,#REF!,22,0),0)),"") | AG23: =(Z23-Y23)+(AB23-AA23)+(AD23-AC23)+(AF23-AE23) -> 0
A24: =IF(COUNTIFS(祝日参照用!A:A,C24)=1,1,IF(D24="土",1,IF(D24="日",1,0))) -> 0 | C24: =IF(C23="","",IF(DAY(C23+1)=1,"",C23+1)) -> 44931 | D24: =TEXT(C24,"aaa") -> 木 | H24: ～ | J24: =IFERROR(IF(G24="",0,I24-G24),"") -> 0 | K24: =IFERROR(IF(E24="",0,F24-E24-J24),"") -> 0 | L24: =IF(E24="",0,IF($A24=1,$K24,IF($C24="",0,IF($K24-$T$9<0,0,$K24-$T$9)))) -> 0 | T24: =E24 -> 0 | U24: =F24 -> 0 | V24: =IFERROR(IF(T24="",0,U24-T24-J24),"") -> 0 | W24: =IFERROR(FLOOR(K24,TIME(0,VLOOKUP($C$3,#REF!,22,0),0)),"") | AG24: =(Z24-Y24)+(AB24-AA24)+(AD24-AC24)+(AF24-AE24) -> 0
A25: =IF(COUNTIFS(祝日参照用!A:A,C25)=1,1,IF(D25="土",1,IF(D25="日",1,0))) -> 0 | C25: =IF(C24="","",IF(DAY(C24+1)=1,"",C24+1)) -> 44932 | D25: =TEXT(C25,"aaa") -> 金 | H25: ～ | J25: =IFERROR(IF(G25="",0,I25-G25),"") -> 0 | K25: =IFERROR(IF(E25="",0,F25-E25-J25),"") -> 0 | L25: =IF(E25="",0,IF($A25=1,$K25,IF($C25="",0,IF($K25-$T$9<0,0,$K25-$T$9)))) -> 0 | T25: =E25 -> 0 | U25: =F25 -> 0 | V25: =IFERROR(IF(T25="",0,U25-T25-J25),"") -> 0 | W25: =IFERROR(FLOOR(K25,TIME(0,VLOOKUP($C$3,#REF!,22,0),0)),"") | AG25: =(Z25-Y25)+(AB25-AA25)+(AD25-AC25)+(AF25-AE25) -> 0
A26: =IF(COUNTIFS(祝日参照用!A:A,C26)=1,1,IF(D26="土",1,IF(D26="日",1,0))) -> 1 | C26: =IF(C25="","",IF(DAY(C25+1)=1,"",C25+1)) -> 44933 | D26: =TEXT(C26,"aaa") -> 土 | H26: ～ | J26: =IFERROR(IF(G26="",0,I26-G26),"") -> 0 | K26: =IFERROR(IF(E26="",0,F26-E26-J26),"") -> 0 | L26: =IF(E26="",0,IF($A26=1,$K26,IF($C26="",0,IF($K26-$T$9<0,0,$K26-$T$9)))) -> 0 | T26: =E26 -> 0 | U26: =F26 -> 0 | V26: =IFERROR(IF(T26="",0,U26-T26-J26),"") -> 0 | W26: =IFERROR(FLOOR(K26,TIME(0,VLOOKUP($C$3,#REF!,22,0),0)),"") | AG26: =(Z26-Y26)+(AB26-AA26)+(AD26-AC26)+(AF26-AE26) -> 0
A27: =IF(COUNTIFS(祝日参照用!A:A,C27)=1,1,IF(D27="土",1,IF(D27="日",1,0))) -> 1 | C27: =IF(C26="","",IF(DAY(C26+1)=1,"",C26+1)) -> 44934 | D27: =TEXT(C27,"aaa") -> 日 | H27: ～ | J27: =IFERROR(IF(G27="",0,I27-G27),"") -> 0 | K27: =IFERROR(IF(E27="",0,F27-E27-J27),"") -> 0 | L27: =IF(E27="",0,IF($A27=1,$K27,IF($C27="",0,IF($K27-$T$9<0,0,$K27-$T$9)))) -> 0 | T27: =E27 -> 0 | U27: =F27 -> 0 | V27: =IFERROR(IF(T27="",0,U27-T27-J27),"") -> 0 | W27: =IFERROR(FLOOR(K27,TIME(0,VLOOKUP($C$3,#REF!,22,0),0)),"") | AG27: =(Z27-Y27)+(AB27-AA27)+(AD27-AC27)+(AF27-AE27) -> 0
A28: =IF(COUNTIFS(祝日参照用!A:A,C28)=1,1,IF(D28="土",1,IF(D28="日",1,0))) -> 1 | C28: =IF(C27="","",IF(DAY(C27+1)=1,"",C27+1)) -> 44935 | D28: =TEXT(C28,"aaa") -> 月 | H28: ～ | J28: =IFERROR(IF(G28="",0,I28-G28),"") -> 0 | K28: =IFERROR(IF(E28="",0,F28-E28-J28),"") -> 0 | L28: =IF(E28="",0,IF($A28=1,$K28,IF($C28="",0,IF($K28-$T$9<0,0,$K28-$T$9)))) -> 0 | T28: =E28 -> 0 | U28: =F28 -> 0 | V28: =IFERROR(IF(T28="",0,U28-T28-J28),"") -> 0 | W28: =IFERROR(FLOOR(K28,TIME(0,VLOOKUP($C$3,#REF!,22,0),0)),"") | AG28: =(Z28-Y28)+(AB28-AA28)+(AD28-AC28)+(AF28-AE28) -> 0
A29: =IF(COUNTIFS(祝日参照用!A:A,C29)=1,1,IF(D29="土",1,IF(D29="日",1,0))) -> 0 | C29: =IF(C28="","",IF(DAY(C28+1)=1,"",C28+1)) -> 44936 | D29: =TEXT(C29,"aaa") -> 火 | H29: ～ | J29: =IFERROR(IF(G29="",0,I29-G29),"") -> 0 | K29: =IFERROR(IF(E29="",0,F29-E29-J29),"") -> 0 | L29: =IF(E29="",0,IF($A29=1,$K29,IF($C29="",0,IF($K29-$T$9<0,0,$K29-$T$9)))) -> 0 | T29: =E29 -> 0 | U29: =F29 -> 0 | V29: =IFERROR(IF(T29="",0,U29-T29-J29),"") -> 0 | W29: =IFERROR(FLOOR(K29,TIME(0,VLOOKUP($C$3,#REF!,22,0),0)),"") | AG29: =(Z29-Y29)+(AB29-AA29)+(AD29-AC29)+(AF29-AE29) -> 0
A30: =IF(COUNTIFS(祝日参照用!A:A,C30)=1,1,IF(D30="土",1,IF(D30="日",1,0))) -> 0 | C30: =IF(C29="","",IF(DAY(C29+1)=1,"",C29+1)) -> 44937 | D30: =TEXT(C30,"aaa") -> 水 | H30: ～ | J30: =IFERROR(IF(G30="",0,I30-G30),"") -> 0 | K30: =IFERROR(IF(E30="",0,F30-E30-J30),"") -> 0 | L30: =IF(E30="",0,IF($A30=1,$K30,IF($C30="",0,IF($K30-$T$9<0,0,$K30-$T$9)))) -> 0 | T30: =E30 -> 0 | U30: =F30 -> 0 | V30: =IFERROR(IF(T30="",0,U30-T30-J30),"") -> 0 | W30: =IFERROR(FLOOR(K30,TIME(0,VLOOKUP($C$3,#REF!,22,0),0)),"") | AG30: =(Z30-Y30)+(AB30-AA30)+(AD30-AC30)+(AF30-AE30) -> 0
A31: =IF(COUNTIFS(祝日参照用!A:A,C31)=1,1,IF(D31="土",1,IF(D31="日",1,0))) -> 0 | C31: =IF(C30="","",IF(DAY(C30+1)=1,"",C30+1)) -> 44938 | D31: =TEXT(C31,"aaa") -> 木 | H31: ～ | J31: =IFERROR(IF(G31="",0,I31-G31),"") -> 0 | K31: =IFERROR(IF(E31="",0,F31-E31-J31),"") -> 0 | L31: =IF(E31="",0,IF($A31=1,$K31,IF($C31="",0,IF($K31-$T$9<0,0,$K31-$T$9)))) -> 0 | T31: =E31 -> 0 | U31: =F31 -> 0 | V31: =IFERROR(IF(T31="",0,U31-T31-J31),"") -> 0 | W31: =IFERROR(FLOOR(K31,TIME(0,VLOOKUP($C$3,#REF!,22,0),0)),"") | AG31: =(Z31-Y31)+(AB31-AA31)+(AD31-AC31)+(AF31-AE31) -> 0
A32: =IF(COUNTIFS(祝日参照用!A:A,C32)=1,1,IF(D32="土",1,IF(D32="日",1,0))) -> 0 | C32: =IF(C31="","",IF(DAY(C31+1)=1,"",C31+1)) -> 44939 | D32: =TEXT(C32,"aaa") -> 金 | H32: ～ | J32: =IFERROR(IF(G32="",0,I32-G32),"") -> 0 | K32: =IFERROR(IF(E32="",0,F32-E32-J32),"") -> 0 | L32: =IF(E32="",0,IF($A32=1,$K32,IF($C32="",0,IF($K32-$T$9<0,0,$K32-$T$9)))) -> 0 | T32: =E32 -> 0 | U32: =F32 -> 0 | V32: =IFERROR(IF(T32="",0,U32-T32-J32),"") -> 0 | W32: =IFERROR(FLOOR(K32,TIME(0,VLOOKUP($C$3,#REF!,22,0),0)),"") | AG32: =(Z32-Y32)+(AB32-AA32)+(AD32-AC32)+(AF32-AE32) -> 0
... A50: =IF(COUNTIFS(祝日参照用!A:A,C50)=1,1,IF(D50="土",1,IF(D50="日",1,0))) -> 0 | C50: =IF(C49="","",IF(DAY(C49+1)=1,"",C49+1)) -> 44957 | D50: =TEXT(C50,"aaa") -> 火 | H50: ～ | J50: =IFERROR(IF(G50="",0,I50-G50),"") -> 0 | K50: =IFERROR(IF(E50="",0,F50-E50-J50),"") -> 0 | L50: =IF(E50="",0,IF($A50=1,$K50,IF($C50="",0,IF($K50-$T$9<0,0,$K50-$T$9)))) -> 0 | T50: =E50 -> 0 | U50: =F50 -> 0 | V50: =IFERROR(IF(T50="",0,U50-T50-J50),"") -> 0 | W50: =IFERROR(FLOOR(K50,TIME(0,VLOOKUP($C$3,#REF!,22,0),0)),"") | AG50: =(Z50-Y50)+(AB50-AA50)+(AD50-AC50)+(AF50-AE50) -> 0
J51: =SUM(J20:J50) -> 0 | K51: =SUM(K20:K50) -> 0 | L51: =SUM(L20:L50) -> 0 | M51: =SUM(M20:M50) -> 0 | N51: =SUM(N20:N50) -> 0 | V51: =SUM(V20:V50) -> 0 | W51: =SUM(W20:W50) -> 0

Sheet 12月
C2: SuccessHolders 勤務報告書 | M2: (西暦) | O2: 2022 | Q2: 年 | R2: ='11月'!R2+1 -> 13 | S2: 月分 | X2: ≪入力方法について≫
C3: 社員1 | Q3: 勤務日数： | S3: =COUNTA(E20:E50)&"日" -> 0日 | X3: ・太枠内の記載をお願いします。
C4: 派遣先企業名 | N4: 派遣先事業所名 | Y4: 業務内容等は必要があれば記載をお願いします。「入力例」タブをご確認ください。
C5: 派遣先住所
C6: 就業部署名 | N6: 連絡先 | X6: ・休憩時間が複数ある場合
C7: 業務に伴う責任の程度 | F7: (業務内容) | N7: 役職名 | R7: 部下 人数 | Y7: 休憩1-4に休憩時間を入力してください。
C8: 実際の就業場所 | M8: 勤怠パターン | O8: 勤務時間 | R8: 休憩時間 | T8: 規定時間 | Y8: 休憩1-4の、合計時間をJ列の「休憩時間」に直接入力してください。
P9: ～ | T9: =Q9-O9-R9 -> 0 | Y9: G列とI列の入力は不要です。
P10: ～ | T10: =Q10-O10-R10 -> 0
P11: ～ | T11: =Q11-O11-R11 -> 0 | X11: ・深夜時間の勤務の場合、時間は下記のように退勤時刻（例 34：00）の記載をお願いします。
P12: ～ | T12: =Q12-O12-R12 -> 0 | Y12: 例：18：00～翌日10：00の場合
P13: ～ | T13: =Q13-O13-R13 -> 0 | Z13: 出勤時刻（18：00） 退勤時刻（34：00）
B14: 氏名 | C14: 氏名 | O14: フレックスタイム制 | Z14: 18時＋6時間（18時～24時合計）+10時間（0時～10時合計）＝34時間
O15: 変形労働時間制
Y16: 休憩時間が1時間以外で複数ある場合は、J列の計算式を削除して休憩時間を直接入力してください↓
C17: 例 | E17: 0.375 | F17: 0.76041667 | G17: 0.5 | I17: 0.54166667 | X17: 例 | Y17: 0.5 | Z17: 0.54166667 | AA17: 0.71875 | AB17: 0.72916667 | AC17: 0.77083333 | AD17: 0.79166667 | AE17: 0.89583333 | AF17: 0.91666667
Y18: 休憩1 | AA18: 休憩2 | AC18: 休憩3 | AE18: 休憩4
A19: 祝日判定 | C19: 月 日 | D19: 曜 日 | E19: 出勤 時刻 | F19: 退勤 時刻 | G19: 休憩 時刻 | J19: 休憩 時間 | K19: 所定 時間 | L19: 法定外 残業 | M19: 深夜 時間 | N19: 不就労 | O19: 業務内容・作業進捗状況・その他 | T19: 出勤時刻(KOT) | U19: 退勤時刻 (KOT) | V19: 所定時間 (KOT) | W19: 所定時間 (調整) | Y19: 開始 | Z19: 終了 | AA19: 開始 | AB19: 終了 | AC19: 開始 | AD19: 終了 | AE19: 開始 | AF19: 終了 | AG19: 休憩時間
A20: =IF(COUNTIFS(祝日参照用!A:A,C20)=1,1,IF(D20="土",1,IF(D20="日",1,0))) -> 1 | C20: =IFERROR(DATE(O2,R2,1),"") -> 44927 | D20: =TEXT(C20,"aaa") -> 日 | H20: ～ | J20: =IFERROR(IF(G20="",0,I20-G20),"") -> 0 | K20: =IFERROR(IF(E20="",0,F20-E20-J20),"") -> 0 | L20: =IF(E20="",0,IF($A20=1,$K20,IF($C20="",0,IF($K20-$T$9<0,0,$K20-$T$9)))) -> 0 | T20: =E20 -> 0 | U20: =F20 -> 0 | V20: =IFERROR(IF(T20="",0,U20-T20-J20),"") -> 0 | W20: =IFERROR(FLOOR(K20,TIME(0,VLOOKUP($C$3,#REF!,22,0),0)),"") | AG20: =(Z20-Y20)+(AB20-AA20)+(AD20-AC20)+(AF20-AE20) -> 0
A21: =IF(COUNTIFS(祝日参照用!A:A,C21)=1,1,IF(D21="土",1,IF(D21="日",1,0))) -> 1 | C21: =IF(C20="","",IF(DAY(C20+1)=1,"",C20+1)) -> 44928 | D21: =TEXT(C21,"aaa") -> 月 | H21: ～ | J21: =IFERROR(IF(G21="",0,I21-G21),"") -> 0 | K21: =IFERROR(IF(E21="",0,F21-E21-J21),"") -> 0 | L21: =IF(E21="",0,IF($A21=1,$K21,IF($C21="",0,IF($K21-$T$9<0,0,$K21-$T$9)))) -> 0 | T21: =E21 -> 0 | U21: =F21 -> 0 | V21: =IFERROR(IF(T21="",0,U21-T21-J21),"") -> 0 | W21: =IFERROR(FLOOR(K21,TIME(0,VLOOKUP($C$3,#REF!,22,0),0)),"") | AG21: =(Z21-Y21)+(AB21-AA21)+(AD21-AC21)+(AF21-AE21) -> 0
A22: =IF(COUNTIFS(祝日参照用!A:A,C22)=1,1,IF(D22="土",1,IF(D22="日",1,0))) -> 1 | C22: =IF(C21="","",IF(DAY(C21+1)=1,"",C21+1)) -> 44929 | D22: =TEXT(C22,"aaa") -> 火 | H22: ～ | J22: =IFERROR(IF(G22="",0,I22-G22),"") -> 0 | K22: =IFERROR(IF(E22="",0,F22-E22-J22),"") -> 0 | L22: =IF(E22="",0,IF($A22=1,$K22,IF($C22="",0,IF($K22-$T$9<0,0,$K22-$T$9)))) -> 0 | T22: =E22 -> 0 | U22: =F22 -> 0 | V22: =IFERROR(IF(T22="",0,U22-T22-J22),"") -> 0 | W22: =IFERROR(FLOOR(K22,TIME(0,VLOOKUP($C$3,#REF!,22,0),0)),"") | AG22: =(Z22-Y22)+(AB22-AA22)+(AD22-AC22)+(AF22-AE22) -> 0
A23: =IF(COUNTIFS(祝日参照用!A:A,C23)=1,1,IF(D23="土",1,IF(D23="日",1,0))) -> 0 | C23: =IF(C22="","",IF(DAY(C22+1)=1,"",C22+1)) -> 44930 | D23: =TEXT(C23,"aaa") -> 水 | H23: ～ | J23: =IFERROR(IF(G23="",0,I23-G23),"") -> 0 | K23: =IFERROR(IF(E23="",0,F23-E23-J23),"") -> 0 | L23: =IF(E23="",0,IF($A23=1,$K23,IF($C23="",0,IF($K23-$T$9<0,0,$K23-$T$9)))) -> 0 | T23: =E23 -> 0 | U23: =F23 -> 0 | V23: =IFERROR(IF(T23="",0,U23-T23-J23),"") -> 0 | W23: =IFERROR(FLOOR(K23,TIME(0,VLOOKUP($C$3,#REF!,22,0),0)),"") | AG23: =(Z23-Y23)+(AB23-AA23)+(AD23-AC23)+(AF23-AE23) -> 0
A24: =IF(COUNTIFS(祝日参照用!A:A,C24)=1,1,IF(D24="土",1,IF(D24="日",1,0))) -> 0 | C24: =IF(C23="","",IF(DAY(C23+1)=1,"",C23+1)) -> 44931 | D24: =TEXT(C24,"aaa") -> 木 | H24: ～ | J24: =IFERROR(IF(G24="",0,I24-G24),"") -> 0 | K24: =IFERROR(IF(E24="",0,F24-E24-J24),"") -> 0 | L24: =IF(E24="",0,IF($A24=1,$K24,IF($C24="",0,IF($K24-$T$9<0,0,$K24-$T$9)))) -> 0 | T24: =E24 -> 0 | U24: =F24 -> 0 | V24: =IFERROR(IF(T24="",0,U24-T24-J24),"") -> 0 | W24: =IFERROR(FLOOR(K24,TIME(0,VLOOKUP($C$3,#REF!,22,0),0)),"") | AG24: =(Z24-Y24)+(AB24-AA24)+(AD24-AC24)+(AF24-AE24) -> 0
A25: =IF(COUNTIFS(祝日参照用!A:A,C25)=1,1,IF(D25="土",1,IF(D25="日",1,0))) -> 0 | C25: =IF(C24="","",IF(DAY(C24+1)=1,"",C24+1)) -> 44932 | D25: =TEXT(C25,"aaa") -> 金 | H25: ～ | J25: =IFERROR(IF(G25="",0,I25-G25),"") -> 0 | K25: =IFERROR(IF(E25="",0,F25-E25-J25),"") -> 0 | L25: =IF(E25="",0,IF($A25=1,$K25,IF($C25="",0,IF($K25-$T$9<0,0,$K25-$T$9)))) -> 0 | T25: =E25 -> 0 | U25: =F25 -> 0 | V25: =IFERROR(IF(T25="",0,U25-T25-J25),"") -> 0 | W25: =IFERROR(FLOOR(K25,TIME(0,VLOOKUP($C$3,#REF!,22,0),0)),"") | AG25: =(Z25-Y25)+(AB25-AA25)+(AD25-AC25)+(AF25-AE25) -> 0
A26: =IF(COUNTIFS(祝日参照用!A:A,C26)=1,1,IF(D26="土",1,IF(D26="日",1,0))) -> 1 | C26: =IF(C25="","",IF(DAY(C25+1)=1,"",C25+1)) -> 44933 | D26: =TEXT(C26,"aaa") -> 土 | H26: ～ | J26: =IFERROR(IF(G26="",0,I26-G26),"") -> 0 | K26: =IFERROR(IF(E26="",0,F26-E26-J26),"") -> 0 | L26: =IF(E26="",0,IF($A26=1,$K26,IF($C26="",0,IF($K26-$T$9<0,0,$K26-$T$9)))) -> 0 | T26: =E26 -> 0 | U26: =F26 -> 0 | V26: =IFERROR(IF(T26="",0,U26-T26-J26),"") -> 0 | W26: =IFERROR(FLOOR(K26,TIME(0,VLOOKUP($C$3,#REF!,22,0),0)),"") | AG26: =(Z26-Y26)+(AB26-AA26)+(AD26-AC26)+(AF26-AE26) -> 0
A27: =IF(COUNTIFS(祝日参照用!A:A,C27)=1,1,IF(D27="土",1,IF(D27="日",1,0))) -> 1 | C27: =IF(C26="","",IF(DAY(C26+1)=1,"",C26+1)) -> 44934 | D27: =TEXT(C27,"aaa") -> 日 | H27: ～ | J27: =IFERROR(IF(G27="",0,I27-G27),"") -> 0 | K27: =IFERROR(IF(E27="",0,F27-E27-J27),"") -> 0 | L27: =IF(E27="",0,IF($A27=1,$K27,IF($C27="",0,IF($K27-$T$9<0,0,$K27-$T$9)))) -> 0 | T27: =E27 -> 0 | U27: =F27 -> 0 | V27: =IFERROR(IF(T27="",0,U27-T27-J27),"") -> 0 | W27: =IFERROR(FLOOR(K27,TIME(0,VLOOKUP($C$3,#REF!,22,0),0)),"") | AG27: =(Z27-Y27)+(AB27-AA27)+(AD27-AC27)+(AF27-AE27) -> 0
A28: =IF(COUNTIFS(祝日参照用!A:A,C28)=1,1,IF(D28="土",1,IF(D28="日",1,0))) -> 1 | C28: =IF(C27="","",IF(DAY(C27+1)=1,"",C27+1)) -> 44935 | D28: =TEXT(C28,"aaa") -> 月 | H28: ～ | J28: =IFERROR(IF(G28="",0,I28-G28),"") -> 0 | K28: =IFERROR(IF(E28="",0,F28-E28-J28),"") -> 0 | L28: =IF(E28="",0,IF($A28=1,$K28,IF($C28="",0,IF($K28-$T$9<0,0,$K28-$T$9)))) -> 0 | T28: =E28 -> 0 | U28: =F28 -> 0 | V28: =IFERROR(IF(T28="",0,U28-T28-J28),"") -> 0 | W28: =IFERROR(FLOOR(K28,TIME(0,VLOOKUP($C$3,#REF!,22,0),0)),"") | AG28: =(Z28-Y28)+(AB28-AA28)+(AD28-AC28)+(AF28-AE28) -> 0
A29: =IF(COUNTIFS(祝日参照用!A:A,C29)=1,1,IF(D29="土",1,IF(D29="日",1,0))) -> 0 | C29: =IF(C28="","",IF(DAY(C28+1)=1,"",C28+1)) -> 44936 | D29: =TEXT(C29,"aaa") -> 火 | H29: ～ | J29: =IFERROR(IF(G29="",0,I29-G29),"") -> 0 | K29: =IFERROR(IF(E29="",0,F29-E29-J29),"") -> 0 | L29: =IF(E29="",0,IF($A29=1,$K29,IF($C29="",0,IF($K29-$T$9<0,0,$K29-$T$9)))) -> 0 | T29: =E29 -> 0 | U29: =F29 -> 0 | V29: =IFERROR(IF(T29="",0,U29-T29-J29),"") -> 0 | W29: =IFERROR(FLOOR(K29,TIME(0,VLOOKUP($C$3,#REF!,22,0),0)),"") | AG29: =(Z29-Y29)+(AB29-AA29)+(AD29-AC29)+(AF29-AE29) -> 0
A30: =IF(COUNTIFS(祝日参照用!A:A,C30)=1,1,IF(D30="土",1,IF(D30="日",1,0))) -> 0 | C30: =IF(C29="","",IF(DAY(C29+1)=1,"",C29+1)) -> 44937 | D30: =TEXT(C30,"aaa") -> 水 | H30: ～ | J30: =IFERROR(IF(G30="",0,I30-G30),"") -> 0 | K30: =IFERROR(IF(E30="",0,F30-E30-J30),"") -> 0 | L30: =IF(E30="",0,IF($A30=1,$K30,IF($C30="",0,IF($K30-$T$9<0,0,$K30-$T$9)))) -> 0 | T30: =E30 -> 0 | U30: =F30 -> 0 | V30: =IFERROR(IF(T30="",0,U30-T30-J30),"") -> 0 | W30: =IFERROR(FLOOR(K30,TIME(0,VLOOKUP($C$3,#REF!,22,0),0)),"") | AG30: =(Z30-Y30)+(AB30-AA30)+(AD30-AC30)+(AF30-AE30) -> 0
A31: =IF(COUNTIFS(祝日参照用!A:A,C31)=1,1,IF(D31="土",1,IF(D31="日",1,0))) -> 0 | C31: =IF(C30="","",IF(DAY(C30+1)=1,"",C30+1)) -> 44938 | D31: =TEXT(C31,"aaa") -> 木 | H31: ～ | J31: =IFERROR(IF(G31="",0,I31-G31),"") -> 0 | K31: =IFERROR(IF(E31="",0,F31-E31-J31),"") -> 0 | L31: =IF(E31="",0,IF($A31=1,$K31,IF($C31="",0,IF($K31-$T$9<0,0,$K31-$T$9)))) -> 0 | T31: =E31 -> 0 | U31: =F31 -> 0 | V31: =IFERROR(IF(T31="",0,U31-T31-J31),"") -> 0 | W31: =IFERROR(FLOOR(K31,TIME(0,VLOOKUP($C$3,#REF!,22,0),0)),"") | AG31: =(Z31-Y31)+(AB31-AA31)+(AD31-AC31)+(AF31-AE31) -> 0
A32: =IF(COUNTIFS(祝日参照用!A:A,C32)=1,1,IF(D32="土",1,IF(D32="日",1,0))) -> 0 | C32: =IF(C31="","",IF(DAY(C31+1)=1,"",C31+1)) -> 44939 | D32: =TEXT(C32,"aaa") -> 金 | H32: ～ | J32: =IFERROR(IF(G32="",0,I32-G32),"") -> 0 | K32: =IFERROR(IF(E32="",0,F32-E32-J32),"") -> 0 | L32: =IF(E32="",0,IF($A32=1,$K32,IF($C32="",0,IF($K32-$T$9<0,0,$K32-$T$9)))) -> 0 | T32: =E32 -> 0 | U32: =F32 -> 0 | V32: =IFERROR(IF(T32="",0,U32-T32-J32),"") -> 0 | W32: =IFERROR(FLOOR(K32,TIME(0,VLOOKUP($C$3,#REF!,22,0),0)),"") | AG32: =(Z32-Y32)+(AB32-AA32)+(AD32-AC32)+(AF32-AE32) -> 0
... A50: =IF(COUNTIFS(祝日参照用!A:A,C50)=1,1,IF(D50="土",1,IF(D50="日",1,0))) -> 0 | C50: =IF(C49="","",IF(DAY(C49+1)=1,"",C49+1)) -> 44957 | D50: =TEXT(C50,"aaa") -> 火 | H50: ～ | J50: =IFERROR(IF(G50="",0,I50-G50),"") -> 0 | K50: =IFERROR(IF(E50="",0,F50-E50-J50),"") -> 0 | L50: =IF(E50="",0,IF($A50=1,$K50,IF($C50="",0,IF($K50-$T$9<0,0,$K50-$T$9)))) -> 0 | T50: =E50 -> 0 | U50: =F50 -> 0 | V50: =IFERROR(IF(T50="",0,U50-T50-J50),"") -> 0 | W50: =IFERROR(FLOOR(K50,TIME(0,VLOOKUP($C$3,#REF!,22,0),0)),"") | AG50: =(Z50-Y50)+(AB50-AA50)+(AD50-AC50)+(AF50-AE50) -> 0
J51: =SUM(J20:J50) -> 0 | K51: =SUM(K20:K50) -> 0 | L51: =SUM(L20:L50) -> 0 | M51: =SUM(M20:M50) -> 0 | N51: =SUM(N20:N50) -> 0 | V51: =SUM(V20:V50) -> 0 | W51: =SUM(W20:W50) -> 0

Sheet 11月
C2: SuccessHolders 勤務報告書 | M2: (西暦) | O2: 2022 | Q2: 年 | R2: ='10月'!R2+1 -> 12 | S2: 月分 | X2: ≪入力方法について≫
C3: 社員1 | Q3: 勤務日数： | S3: =COUNTA(E20:E50)&"日" -> 0日 | X3: ・太枠内の記載をお願いします。
C4: 派遣先企業名 | N4: 派遣先事業所名 | Y4: 業務内容等は必要があれば記載をお願いします。「入力例」タブをご確認ください。
C5: 派遣先住所
C6: 就業部署名 | N6: 連絡先 | X6: ・休憩時間が複数ある場合
C7: 業務に伴う責任の程度 | F7: (業務内容) | N7: 役職名 | R7: 部下 人数 | Y7: 休憩1-4に休憩時間を入力してください。
C8: 実際の就業場所 | M8: 勤怠パターン | O8: 勤務時間 | R8: 休憩時間 | T8: 規定時間 | Y8: 休憩1-4の、合計時間をJ列の「休憩時間」に直接入力してください。
P9: ～ | T9: =Q9-O9-R9 -> 0 | Y9: G列とI列の入力は不要です。
P10: ～ | T10: =Q10-O10-R10 -> 0
P11: ～ | T11: =Q11-O11-R11 -> 0 | X11: ・深夜時間の勤務の場合、時間は下記のように退勤時刻（例 34：00）の記載をお願いします。
P12: ～ | T12: =Q12-O12-R12 -> 0 | Y12: 例：18：00～翌日10：00の場合
P13: ～ | T13: =Q13-O13-R13 -> 0 | Z13: 出勤時刻（18：00） 退勤時刻（34：00）
B14: 氏名 | C14: 氏名 | O14: フレックスタイム制 | Z14: 18時＋6時間（18時～24時合計）+10時間（0時～10時合計）＝34時間
O15: 変形労働時間制
Y16: 休憩時間が1時間以外で複数ある場合は、J列の計算式を削除して休憩時間を直接入力してください↓
C17: 例 | E17: 0.375 | F17: 0.76041667 | G17: 0.5 | I17: 0.54166667 | X17: 例 | Y17: 0.5 | Z17: 0.54166667 | AA17: 0.71875 | AB17: 0.72916667 | AC17: 0.77083333 | AD17: 0.79166667 | AE17: 0.89583333 | AF17: 0.91666667
Y18: 休憩1 | AA18: 休憩2 | AC18: 休憩3 | AE18: 休憩4
A19: 祝日判定 | C19: 月 日 | D19: 曜 日 | E19: 出勤 時刻 | F19: 退勤 時刻 | G19: 休憩 時刻 | J19: 休憩 時間 | K19: 所定 時間 | L19: 法定外 残業 | M19: 深夜 時間 | N19: 不就労 | O19: 業務内容・作業進捗状況・その他 | T19: 出勤時刻(KOT) | U19: 退勤時刻 (KOT) | V19: 所定時間 (KOT) | W19: 所定時間 (調整) | Y19: 開始 | Z19: 終了 | AA19: 開始 | AB19: 終了 | AC19: 開始 | AD19: 終了 | AE19: 開始 | AF19: 終了 | AG19: 休憩時間
A20: =IF(COUNTIFS(祝日参照用!A:A,C20)=1,1,IF(D20="土",1,IF(D20="日",1,0))) -> 0 | C20: =IFERROR(DATE(O2,R2,1),"") -> 44896 | D20: =TEXT(C20,"aaa") -> 木 | H20: ～ | J20: =IFERROR(IF(G20="",0,I20-G20),"") -> 0 | K20: =IFERROR(IF(E20="",0,F20-E20-J20),"") -> 0 | L20: =IF(E20="",0,IF($A20=1,$K20,IF($C20="",0,IF($K20-$T$9<0,0,$K20-$T$9)))) -> 0 | T20: =E20 -> 0 | U20: =F20 -> 0 | V20: =IFERROR(IF(T20="",0,U20-T20-J20),"") -> 0 | W20: =IFERROR(FLOOR(K20,TIME(0,VLOOKUP($C$3,#REF!,22,0),0)),"") | AG20: =(Z20-Y20)+(AB20-AA20)+(AD20-AC20)+(AF20-AE20) -> 0
A21: =IF(COUNTIFS(祝日参照用!A:A,C21)=1,1,IF(D21="土",1,IF(D21="日",1,0))) -> 0 | C21: =IF(C20="","",IF(DAY(C20+1)=1,"",C20+1)) -> 44897 | D21: =TEXT(C21,"aaa") -> 金 | H21: ～ | J21: =IFERROR(IF(G21="",0,I21-G21),"") -> 0 | K21: =IFERROR(IF(E21="",0,F21-E21-J21),"") -> 0 | L21: =IF(E21="",0,IF($A21=1,$K21,IF($C21="",0,IF($K21-$T$9<0,0,$K21-$T$9)))) -> 0 | T21: =E21 -> 0 | U21: =F21 -> 0 | V21: =IFERROR(IF(T21="",0,U21-T21-J21),"") -> 0 | W21: =IFERROR(FLOOR(K21,TIME(0,VLOOKUP($C$3,#REF!,22,0),0)),"") | AG21: =(Z21-Y21)+(AB21-AA21)+(AD21-AC21)+(AF21-AE21) -> 0
A22: =IF(COUNTIFS(祝日参照用!A:A,C22)=1,1,IF(D22="土",1,IF(D22="日",1,0))) -> 1 | C22: =IF(C21="","",IF(DAY(C21+1)=1,"",C21+1)) -> 44898 | D22: =TEXT(C22,"aaa") -> 土 | H22: ～ | J22: =IFERROR(IF(G22="",0,I22-G22),"") -> 0 | K22: =IFERROR(IF(E22="",0,F22-E22-J22),"") -> 0 | L22: =IF(E22="",0,IF($A22=1,$K22,IF($C22="",0,IF($K22-$T$9<0,0,$K22-$T$9)))) -> 0 | T22: =E22 -> 0 | U22: =F22 -> 0 | V22: =IFERROR(IF(T22="",0,U22-T22-J22),"") -> 0 | W22: =IFERROR(FLOOR(K22,TIME(0,VLOOKUP($C$3,#REF!,22,0),0)),"") | AG22: =(Z22-Y22)+(AB22-AA22)+(AD22-AC22)+(AF22-AE22) -> 0
A23: =IF(COUNTIFS(祝日参照用!A:A,C23)=1,1,IF(D23="土",1,IF(D23="日",1,0))) -> 1 | C23: =IF(C22="","",IF(DAY(C22+1)=1,"",C22+1)) -> 44899 | D23: =TEXT(C23,"aaa") -> 日 | H23: ～ | J23: =IFERROR(IF(G23="",0,I23-G23),"") -> 0 | K23: =IFERROR(IF(E23="",0,F23-E23-J23),"") -> 0 | L23: =IF(E23="",0,IF($A23=1,$K23,IF($C23="",0,IF($K23-$T$9<0,0,$K23-$T$9)))) -> 0 | T23: =E23 -> 0 | U23: =F23 -> 0 | V23: =IFERROR(IF(T23="",0,U23-T23-J23),"") -> 0 | W23: =IFERROR(FLOOR(K23,TIME(0,VLOOKUP($C$3,#REF!,22,0),0)),"") | AG23: =(Z23-Y23)+(AB23-AA23)+(AD23-AC23)+(AF23-AE23) -> 0
A24: =IF(COUNTIFS(祝日参照用!A:A,C24)=1,1,IF(D24="土",1,IF(D24="日",1,0))) -> 0 | C24: =IF(C23="","",IF(DAY(C23+1)=1,"",C23+1)) -> 44900 | D24: =TEXT(C24,"aaa") -> 月 | H24: ～ | J24: =IFERROR(IF(G24="",0,I24-G24),"") -> 0 | K24: =IFERROR(IF(E24="",0,F24-E24-J24),"") -> 0 | L24: =IF(E24="",0,IF($A24=1,$K24,IF($C24="",0,IF($K24-$T$9<0,0,$K24-$T$9)))) -> 0 | T24: =E24 -> 0 | U24: =F24 -> 0 | V24: =IFERROR(IF(T24="",0,U24-T24-J24),"") -> 0 | W24: =IFERROR(FLOOR(K24,TIME(0,VLOOKUP($C$3,#REF!,22,0),0)),"") | AG24: =(Z24-Y24)+(AB24-AA24)+(AD24-AC24)+(AF24-AE24) -> 0
A25: =IF(COUNTIFS(祝日参照用!A:A,C25)=1,1,IF(D25="土",1,IF(D25="日",1,0))) -> 0 | C25: =IF(C24="","",IF(DAY(C24+1)=1,"",C24+1)) -> 44901 | D25: =TEXT(C25,"aaa") -> 火 | H25: ～ | J25: =IFERROR(IF(G25="",0,I25-G25),"") -> 0 | K25: =IFERROR(IF(E25="",0,F25-E25-J25),"") -> 0 | L25: =IF(E25="",0,IF($A25=1,$K25,IF($C25="",0,IF($K25-$T$9<0,0,$K25-$T$9)))) -> 0 | T25: =E25 -> 0 | U25: =F25 -> 0 | V25: =IFERROR(IF(T25="",0,U25-T25-J25),"") -> 0 | W25: =IFERROR(FLOOR(K25,TIME(0,VLOOKUP($C$3,#REF!,22,0),0)),"") | AG25: =(Z25-Y25)+(AB25-AA25)+(AD25-AC25)+(AF25-AE25) -> 0
A26: =IF(COUNTIFS(祝日参照用!A:A,C26)=1,1,IF(D26="土",1,IF(D26="日",1,0))) -> 0 | C26: =IF(C25="","",IF(DAY(C25+1)=1,"",C25+1)) -> 44902 | D26: =TEXT(C26,"aaa") -> 水 | H26: ～ | J26: =IFERROR(IF(G26="",0,I26-G26),"") -> 0 | K26: =IFERROR(IF(E26="",0,F26-E26-J26),"") -> 0 | L26: =IF(E26="",0,IF($A26=1,$K26,IF($C26="",0,IF($K26-$T$9<0,0,$K26-$T$9)))) -> 0 | T26: =E26 -> 0 | U26: =F26 -> 0 | V26: =IFERROR(IF(T26="",0,U26-T26-J26),"") -> 0 | W26: =IFERROR(FLOOR(K26,TIME(0,VLOOKUP($C$3,#REF!,22,0),0)),"") | AG26: =(Z26-Y26)+(AB26-AA26)+(AD26-AC26)+(AF26-AE26) -> 0
A27: =IF(COUNTIFS(祝日参照用!A:A,C27)=1,1,IF(D27="土",1,IF(D27="日",1,0))) -> 0 | C27: =IF(C26="","",IF(DAY(C26+1)=1,"",C26+1)) -> 44903 | D27: =TEXT(C27,"aaa") -> 木 | H27: ～ | J27: =IFERROR(IF(G27="",0,I27-G27),"") -> 0 | K27: =IFERROR(IF(E27="",0,F27-E27-J27),"") -> 0 | L27: =IF(E27="",0,IF($A27=1,$K27,IF($C27="",0,IF($K27-$T$9<0,0,$K27-$T$9)))) -> 0 | T27: =E27 -> 0 | U27: =F27 -> 0 | V27: =IFERROR(IF(T27="",0,U27-T27-J27),"") -> 0 | W27: =IFERROR(FLOOR(K27,TIME(0,VLOOKUP($C$3,#REF!,22,0),0)),"") | AG27: =(Z27-Y27)+(AB27-AA27)+(AD27-AC27)+(AF27-AE27) -> 0
A28: =IF(COUNTIFS(祝日参照用!A:A,C28)=1,1,IF(D28="土",1,IF(D28="日",1,0))) -> 0 | C28: =IF(C27="","",IF(DAY(C27+1)=1,"",C27+1)) -> 44904 | D28: =TEXT(C28,"aaa") -> 金 | H28: ～ | J28: =IFERROR(IF(G28="",0,I28-G28),"") -> 0 | K28: =IFERROR(IF(E28="",0,F28-E28-J28),"") -> 0 | L28: =IF(E28="",0,IF($A28=1,$K28,IF($C28="",0,IF($K28-$T$9<0,0,$K28-$T$9)))) -> 0 | T28: =E28 -> 0 | U28: =F28 -> 0 | V28: =IFERROR(IF(T28="",0,U28-T28-J28),"") -> 0 | W28: =IFERROR(FLOOR(K28,TIME(0,VLOOKUP($C$3,#REF!,22,0),0)),"") | AG28: =(Z28-Y28)+(AB28-AA28)+(AD28-AC28)+(AF28-AE28) -> 0
A29: =IF(COUNTIFS(祝日参照用!A:A,C29)=1,1,IF(D29="土",1,IF(D29="日",1,0))) -> 1 | C29: =IF(C28="","",IF(DAY(C28+1)=1,"",C28+1)) -> 44905 | D29: =TEXT(C29,"aaa") -> 土 | H29: ～ | J29: =IFERROR(IF(G29="",0,I29-G29),"") -> 0 | K29: =IFERROR(IF(E29="",0,F29-E29-J29),"") -> 0 | L29: =IF(E29="",0,IF($A29=1,$K29,IF($C29="",0,IF($K29-$T$9<0,0,$K29-$T$9)))) -> 0 | T29: =E29 -> 0 | U29: =F29 -> 0 | V29: =IFERROR(IF(T29="",0,U29-T29-J29),"") -> 0 | W29: =IFERROR(FLOOR(K29,TIME(0,VLOOKUP($C$3,#REF!,22,0),0)),"") | AG29: =(Z29-Y29)+(AB29-AA29)+(AD29-AC29)+(AF29-AE29) -> 0
A30: =IF(COUNTIFS(祝日参照用!A:A,C30)=1,1,IF(D30="土",1,IF(D30="日",1,0))) -> 1 | C30: =IF(C29="","",IF(DAY(C29+1)=1,"",C29+1)) -> 44906 | D30: =TEXT(C30,"aaa") -> 日 | H30: ～ | J30: =IFERROR(IF(G30="",0,I30-G30),"") -> 0 | K30: =IFERROR(IF(E30="",0,F30-E30-J30),"") -> 0 | L30: =IF(E30="",0,IF($A30=1,$K30,IF($C30="",0,IF($K30-$T$9<0,0,$K30-$T$9)))) -> 0 | T30: =E30 -> 0 | U30: =F30 -> 0 | V30: =IFERROR(IF(T30="",0,U30-T30-J30),"") -> 0 | W30: =IFERROR(FLOOR(K30,TIME(0,VLOOKUP($C$3,#REF!,22,0),0)),"") | AG30: =(Z30-Y30)+(AB30-AA30)+(AD30-AC30)+(AF30-AE30) -> 0
A31: =IF(COUNTIFS(祝日参照用!A:A,C31)=1,1,IF(D31="土",1,IF(D31="日",1,0))) -> 0 | C31: =IF(C30="","",IF(DAY(C30+1)=1,"",C30+1)) -> 44907 | D31: =TEXT(C31,"aaa") -> 月 | H31: ～ | J31: =IFERROR(IF(G31="",0,I31-G31),"") -> 0 | K31: =IFERROR(IF(E31="",0,F31-E31-J31),"") -> 0 | L31: =IF(E31="",0,IF($A31=1,$K31,IF($C31="",0,IF($K31-$T$9<0,0,$K31-$T$9)))) -> 0 | T31: =E31 -> 0 | U31: =F31 -> 0 | V31: =IFERROR(IF(T31="",0,U31-T31-J31),"") -> 0 | W31: =IFERROR(FLOOR(K31,TIME(0,VLOOKUP($C$3,#REF!,22,0),0)),"") | AG31: =(Z31-Y31)+(AB31-AA31)+(AD31-AC31)+(AF31-AE31) -> 0
A32: =IF(COUNTIFS(祝日参照用!A:A,C32)=1,1,IF(D32="土",1,IF(D32="日",1,0))) -> 0 | C32: =IF(C31="","",IF(DAY(C31+1)=1,"",C31+1)) -> 44908 | D32: =TEXT(C32,"aaa") -> 火 | H32: ～ | J32: =IFERROR(IF(G32="",0,I32-G32),"") -> 0 | K32: =IFERROR(IF(E32="",0,F32-E32-J32),"") -> 0 | L32: =IF(E32="",0,IF($A32=1,$K32,IF($C32="",0,IF($K32-$T$9<0,0,$K32-$T$9)))) -> 0 | T32: =E32 -> 0 | U32: =F32 -> 0 | V32: =IFERROR(IF(T32="",0,U32-T32-J32),"") -> 0 | W32: =IFERROR(FLOOR(K32,TIME(0,VLOOKUP($C$3,#REF!,22,0),0)),"") | AG32: =(Z32-Y32)+(AB32-AA32)+(AD32-AC32)+(AF32-AE32) -> 0
... A50: =IF(COUNTIFS(祝日参照用!A:A,C50)=1,1,IF(D50="土",1,IF(D50="日",1,0))) -> 1 | C50: =IF(C49="","",IF(DAY(C49+1)=1,"",C49+1)) -> 44926 | D50: =TEXT(C50,"aaa") -> 土 | H50: ～ | J50: =IFERROR(IF(G50="",0,I50-G50),"") -> 0 | K50: =IFERROR(IF(E50="",0,F50-E50-J50),"") -> 0 | L50: =IF(E50="",0,IF($A50=1,$K50,IF($C50="",0,IF($K50-$T$9<0,0,$K50-$T$9)))) -> 0 | T50: =E50 -> 0 | U50: =F50 -> 0 | V50: =IFERROR(IF(T50="",0,U50-T50-J50),"") -> 0 | W50: =IFERROR(FLOOR(K50,TIME(0,VLOOKUP($C$3,#REF!,22,0),0)),"") | AG50: =(Z50-Y50)+(AB50-AA50)+(AD50-AC50)+(AF50-AE50) -> 0
J51: =SUM(J20:J50) -> 0 | K51: =SUM(K20:K50) -> 0 | L51: =SUM(L20:L50) -> 0 | M51: =SUM(M20:M50) -> 0 | N51: =SUM(N20:N50) -> 0 | V51: =SUM(V20:V50) -> 0 | W51: =SUM(W20:W50) -> 0

Sheet 10月
C2: SuccessHolders 勤務報告書 | M2: (西暦) | O2: 2022 | Q2: 年 | R2: ='9月'!R2+1 -> 11 | S2: 月分 | X2: ≪入力方法について≫
C3: 社員1 | Q3: 勤務日数： | S3: =COUNTA(E20:E50)&"日" -> 0日 | X3: ・太枠内の記載をお願いします。
C4: 派遣先企業名 | N4: 派遣先事業所名 | Y4: 業務内容等は必要があれば記載をお願いします。「入力例」タブをご確認ください。
C5: 派遣先住所
C6: 就業部署名 | N6: 連絡先 | X6: ・休憩時間が複数ある場合
C7: 業務に伴う責任の程度 | F7: (業務内容) | N7: 役職名 | R7: 部下 人数 | Y7: 休憩1-4に休憩時間を入力してください。
C8: 実際の就業場所 | M8: 勤怠パターン | O8: 勤務時間 | R8: 休憩時間 | T8: 規定時間 | Y8: 休憩1-4の、合計時間をJ列の「休憩時間」に直接入力してください。
P9: ～ | T9: =Q9-O9-R9 -> 0 | Y9: G列とI列の入力は不要です。
P10: ～ | T10: =Q10-O10-R10 -> 0
P11: ～ | T11: =Q11-O11-R11 -> 0 | X11: ・深夜時間の勤務の場合、時間は下記のように退勤時刻（例 34：00）の記載をお願いします。
P12: ～ | T12: =Q12-O12-R12 -> 0 | Y12: 例：18：00～翌日10：00の場合
P13: ～ | T13: =Q13-O13-R13 -> 0 | Z13: 出勤時刻（18：00） 退勤時刻（34：00）
B14: 氏名 | C14: 氏名 | O14: フレックスタイム制 | Z14: 18時＋6時間（18時～24時合計）+10時間（0時～10時合計）＝34時間
O15: 変形労働時間制
Y16: 休憩時間が1時間以外で複数ある場合は、J列の計算式を削除して休憩時間を直接入力してください↓
C17: 例 | E17: 0.375 | F17: 0.76041667 | G17: 0.5 | I17: 0.54166667 | X17: 例 | Y17: 0.5 | Z17: 0.54166667 | AA17: 0.71875 | AB17: 0.72916667 | AC17: 0.77083333 | AD17: 0.79166667 | AE17: 0.89583333 | AF17: 0.91666667
Y18: 休憩1 | AA18: 休憩2 | AC18: 休憩3 | AE18: 休憩4
A19: 祝日判定 | C19: 月 日 | D19: 曜 日 | E19: 出勤 時刻 | F19: 退勤 時刻 | G19: 休憩 時刻 | J19: 休憩 時間 | K19: 所定 時間 | L19: 法定外 残業 | M19: 深夜 時間 | N19: 不就労 | O19: 業務内容・作業進捗状況・その他 | T19: 出勤時刻(KOT) | U19: 退勤時刻 (KOT) | V19: 所定時間 (KOT) | W19: 所定時間 (調整) | Y19: 開始 | Z19: 終了 | AA19: 開始 | AB19: 終了 | AC19: 開始 | AD19: 終了 | AE19: 開始 | AF19: 終了 | AG19: 休憩時間
A20: =IF(COUNTIFS(祝日参照用!A:A,C20)=1,1,IF(D20="土",1,IF(D20="日",1,0))) -> 0 | C20: =IFERROR(DATE(O2,R2,1),"") -> 44866 | D20: =TEXT(C20,"aaa") -> 火 | H20: ～ | J20: =IFERROR(IF(G20="",0,I20-G20),"") -> 0 | K20: =IFERROR(IF(E20="",0,F20-E20-J20),"") -> 0 | L20: =IF(E20="",0,IF($A20=1,$K20,IF($C20="",0,IF($K20-$T$9<0,0,$K20-$T$9)))) -> 0 | T20: =E20 -> 0 | U20: =F20 -> 0 | V20: =IFERROR(IF(T20="",0,U20-T20-J20),"") -> 0 | W20: =IFERROR(FLOOR(K20,TIME(0,VLOOKUP($C$3,#REF!,22,0),0)),"") | AG20: =(Z20-Y20)+(AB20-AA20)+(AD20-AC20)+(AF20-AE20) -> 0
A21: =IF(COUNTIFS(祝日参照用!A:A,C21)=1,1,IF(D21="土",1,IF(D21="日",1,0))) -> 0 | C21: =IF(C20="","",IF(DAY(C20+1)=1,"",C20+1)) -> 44867 | D21: =TEXT(C21,"aaa") -> 水 | H21: ～ | J21: =IFERROR(IF(G21="",0,I21-G21),"") -> 0 | K21: =IFERROR(IF(E21="",0,F21-E21-J21),"") -> 0 | L21: =IF(E21="",0,IF($A21=1,$K21,IF($C21="",0,IF($K21-$T$9<0,0,$K21-$T$9)))) -> 0 | T21: =E21 -> 0 | U21: =F21 -> 0 | V21: =IFERROR(IF(T21="",0,U21-T21-J21),"") -> 0 | W21: =IFERROR(FLOOR(K21,TIME(0,VLOOKUP($C$3,#REF!,22,0),0)),"") | AG21: =(Z21-Y21)+(AB21-AA21)+(AD21-AC21)+(AF21-AE21) -> 0
A22: =IF(COUNTIFS(祝日参照用!A:A,C22)=1,1,IF(D22="土",1,IF(D22="日",1,0))) -> 1 | C22: =IF(C21="","",IF(DAY(C21+1)=1,"",C21+1)) -> 44868 | D22: =TEXT(C22,"aaa") -> 木 | H22: ～ | J22: =IFERROR(IF(G22="",0,I22-G22),"") -> 0 | K22: =IFERROR(IF(E22="",0,F22-E22-J22),"") -> 0 | L22: =IF(E22="",0,IF($A22=1,$K22,IF($C22="",0,IF($K22-$T$9<0,0,$K22-$T$9)))) -> 0 | T22: =E22 -> 0 | U22: =F22 -> 0 | V22: =IFERROR(IF(T22="",0,U22-T22-J22),"") -> 0 | W22: =IFERROR(FLOOR(K22,TIME(0,VLOOKUP($C$3,#REF!,22,0),0)),"") | AG22: =(Z22-Y22)+(AB22-AA22)+(AD22-AC22)+(AF22-AE22) -> 0
A23: =IF(COUNTIFS(祝日参照用!A:A,C23)=1,1,IF(D23="土",1,IF(D23="日",1,0))) -> 0 | C23: =IF(C22="","",IF(DAY(C22+1)=1,"",C22+1)) -> 44869 | D23: =TEXT(C23,"aaa") -> 金 | H23: ～ | J23: =IFERROR(IF(G23="",0,I23-G23),"") -> 0 | K23: =IFERROR(IF(E23="",0,F23-E23-J23),"") -> 0 | L23: =IF(E23="",0,IF($A23=1,$K23,IF($C23="",0,IF($K23-$T$9<0,0,$K23-$T$9)))) -> 0 | T23: =E23 -> 0 | U23: =F23 -> 0 | V23: =IFERROR(IF(T23="",0,U23-T23-J23),"") -> 0 | W23: =IFERROR(FLOOR(K23,TIME(0,VLOOKUP($C$3,#REF!,22,0),0)),"") | AG23: =(Z23-Y23)+(AB23-AA23)+(AD23-AC23)+(AF23-AE23) -> 0
A24: =IF(COUNTIFS(祝日参照用!A:A,C24)=1,1,IF(D24="土",1,IF(D24="日",1,0))) -> 1 | C24: =IF(C23="","",IF(DAY(C23+1)=1,"",C23+1)) -> 44870 | D24: =TEXT(C24,"aaa") -> 土 | H24: ～ | J24: =IFERROR(IF(G24="",0,I24-G24),"") -> 0 | K24: =IFERROR(IF(E24="",0,F24-E24-J24),"") -> 0 | L24: =IF(E24="",0,IF($A24=1,$K24,IF($C24="",0,IF($K24-$T$9<0,0,$K24-$T$9)))) -> 0 | T24: =E24 -> 0 | U24: =F24 -> 0 | V24: =IFERROR(IF(T24="",0,U24-T24-J24),"") -> 0 | W24: =IFERROR(FLOOR(K24,TIME(0,VLOOKUP($C$3,#REF!,22,0),0)),"") | AG24: =(Z24-Y24)+(AB24-AA24)+(AD24-AC24)+(AF24-AE24) -> 0
A25: =IF(COUNTIFS(祝日参照用!A:A,C25)=1,1,IF(D25="土",1,IF(D25="日",1,0))) -> 1 | C25: =IF(C24="","",IF(DAY(C24+1)=1,"",C24+1)) -> 44871 | D25: =TEXT(C25,"aaa") -> 日 | H25: ～ | J25: =IFERROR(IF(G25="",0,I25-G25),"") -> 0 | K25: =IFERROR(IF(E25="",0,F25-E25-J25),"") -> 0 | L25: =IF(E25="",0,IF($A25=1,$K25,IF($C25="",0,IF($K25-$T$9<0,0,$K25-$T$9)))) -> 0 | T25: =E25 -> 0 | U25: =F25 -> 0 | V25: =IFERROR(IF(T25="",0,U25-T25-J25),"") -> 0 | W25: =IFERROR(FLOOR(K25,TIME(0,VLOOKUP($C$3,#REF!,22,0),0)),"") | AG25: =(Z25-Y25)+(AB25-AA25)+(AD25-AC25)+(AF25-AE25) -> 0
A26: =IF(COUNTIFS(祝日参照用!A:A,C26)=1,1,IF(D26="土",1,IF(D26="日",1,0))) -> 0 | C26: =IF(C25="","",IF(DAY(C25+1)=1,"",C25+1)) -> 44872 | D26: =TEXT(C26,"aaa") -> 月 | H26: ～ | J26: =IFERROR(IF(G26="",0,I26-G26),"") -> 0 | K26: =IFERROR(IF(E26="",0,F26-E26-J26),"") -> 0 | L26: =IF(E26="",0,IF($A26=1,$K26,IF($C26="",0,IF($K26-$T$9<0,0,$K26-$T$9)))) -> 0 | T26: =E26 -> 0 | U26: =F26 -> 0 | V26: =IFERROR(IF(T26="",0,U26-T26-J26),"") -> 0 | W26: =IFERROR(FLOOR(K26,TIME(0,VLOOKUP($C$3,#REF!,22,0),0)),"") | AG26: =(Z26-Y26)+(AB26-AA26)+(AD26-AC26)+(AF26-AE26) -> 0
A27: =IF(COUNTIFS(祝日参照用!A:A,C27)=1,1,IF(D27="土",1,IF(D27="日",1,0))) -> 0 | C27: =IF(C26="","",IF(DAY(C26+1)=1,"",C26+1)) -> 44873 | D27: =TEXT(C27,"aaa") -> 火 | H27: ～ | J27: =IFERROR(IF(G27="",0,I27-G27),"") -> 0 | K27: =IFERROR(IF(E27="",0,F27-E27-J27),"") -> 0 | L27: =IF(E27="",0,IF($A27=1,$K27,IF($C27="",0,IF($K27-$T$9<0,0,$K27-$T$9)))) -> 0 | T27: =E27 -> 0 | U27: =F27 -> 0 | V27: =IFERROR(IF(T27="",0,U27-T27-J27),"") -> 0 | W27: =IFERROR(FLOOR(K27,TIME(0,VLOOKUP($C$3,#REF!,22,0),0)),"") | AG27: =(Z27-Y27)+(AB27-AA27)+(AD27-AC27)+(AF27-AE27) -> 0
A28: =IF(COUNTIFS(祝日参照用!A:A,C28)=1,1,IF(D28="土",1,IF(D28="日",1,0))) -> 0 | C28: =IF(C27="","",IF(DAY(C27+1)=1,"",C27+1)) -> 44874 | D28: =TEXT(C28,"aaa") -> 水 | H28: ～ | J28: =IFERROR(IF(G28="",0,I28-G28),"") -> 0 | K28: =IFERROR(IF(E28="",0,F28-E28-J28),"") -> 0 | L28: =IF(E28="",0,IF($A28=1,$K28,IF($C28="",0,IF($K28-$T$9<0,0,$K28-$T$9)))) -> 0 | T28: =E28 -> 0 | U28: =F28 -> 0 | V28: =IFERROR(IF(T28="",0,U28-T28-J28),"") -> 0 | W28: =IFERROR(FLOOR(K28,TIME(0,VLOOKUP($C$3,#REF!,22,0),0)),"") | AG28: =(Z28-Y28)+(AB28-AA28)+(AD28-AC28)+(AF28-AE28) -> 0
A29: =IF(COUNTIFS(祝日参照用!A:A,C29)=1,1,IF(D29="土",1,IF(D29="日",1,0))) -> 0 | C29: =IF(C28="","",IF(DAY(C28+1)=1,"",C28+1)) -> 44875 | D29: =TEXT(C29,"aaa") -> 木 | H29: ～ | J29: =IFERROR(IF(G29="",0,I29-G29),"") -> 0 | K29: =IFERROR(IF(E29="",0,F29-E29-J29),"") -> 0 | L29: =IF(E29="",0,IF($A29=1,$K29,IF($C29="",0,IF($K29-$T$9<0,0,$K29-$T$9)))) -> 0 | T29: =E29 -> 0 | U29: =F29 -> 0 | V29: =IFERROR(IF(T29="",0,U29-T29-J29),"") -> 0 | W29: =IFERROR(FLOOR(K29,TIME(0,VLOOKUP($C$3,#REF!,22,0),0)),"") | AG29: =(Z29-Y29)+(AB29-AA29)+(AD29-AC29)+(AF29-AE29) -> 0
A30: =IF(COUNTIFS(祝日参照用!A:A,C30)=1,1,IF(D30="土",1,IF(D30="日",1,0))) -> 0 | C30: =IF(C29="","",IF(DAY(C29+1)=1,"",C29+1)) -> 44876 | D30: =TEXT(C30,"aaa") -> 金 | H30: ～ | J30: =IFERROR(IF(G30="",0,I30-G30),"") -> 0 | K30: =IFERROR(IF(E30="",0,F30-E30-J30),"") -> 0 | L30: =IF(E30="",0,IF($A30=1,$K30,IF($C30="",0,IF($K30-$T$9<0,0,$K30-$T$9)))) -> 0 | T30: =E30 -> 0 | U30: =F30 -> 0 | V30: =IFERROR(IF(T30="",0,U30-T30-J30),"") -> 0 | W30: =IFERROR(FLOOR(K30,TIME(0,VLOOKUP($C$3,#REF!,22,0),0)),"") | AG30: =(Z30-Y30)+(AB30-AA30)+(AD30-AC30)+(AF30-AE30) -> 0
A31: =IF(COUNTIFS(祝日参照用!A:A,C31)=1,1,IF(D31="土",1,IF(D31="日",1,0))) -> 1 | C31: =IF(C30="","",IF(DAY(C30+1)=1,"",C30+1)) -> 44877 | D31: =TEXT(C31,"aaa") -> 土 | H31: ～ | J31: =IFERROR(IF(G31="",0,I31-G31),"") -> 0 | K31: =IFERROR(IF(E31="",0,F31-E31-J31),"") -> 0 | L31: =IF(E31="",0,IF($A31=1,$K31,IF($C31="",0,IF($K31-$T$9<0,0,$K31-$T$9)))) -> 0 | T31: =E31 -> 0 | U31: =F31 -> 0 | V31: =IFERROR(IF(T31="",0,U31-T31-J31),"") -> 0 | W31: =IFERROR(FLOOR(K31,TIME(0,VLOOKUP($C$3,#REF!,22,0),0)),"") | AG31: =(Z31-Y31)+(AB31-AA31)+(AD31-AC31)+(AF31-AE31) -> 0
A32: =IF(COUNTIFS(祝日参照用!A:A,C32)=1,1,IF(D32="土",1,IF(D32="日",1,0))) -> 1 | C32: =IF(C31="","",IF(DAY(C31+1)=1,"",C31+1)) -> 44878 | D32: =TEXT(C32,"aaa") -> 日 | H32: ～ | J32: =IFERROR(IF(G32="",0,I32-G32),"") -> 0 | K32: =IFERROR(IF(E32="",0,F32-E32-J32),"") -> 0 | L32: =IF(E32="",0,IF($A32=1,$K32,IF($C32="",0,IF($K32-$T$9<0,0,$K32-$T$9)))) -> 0 | T32: =E32 -> 0 | U32: =F32 -> 0 | V32: =IFERROR(IF(T32="",0,U32-T32-J32),"") -> 0 | W32: =IFERROR(FLOOR(K32,TIME(0,VLOOKUP($C$3,#REF!,22,0),0)),"") | AG32: =(Z32-Y32)+(AB32-AA32)+(AD32-AC32)+(AF32-AE32) -> 0
... A50: =IF(COUNTIFS(祝日参照用!A:A,C50)=1,1,IF(D50="土",1,IF(D50="日",1,0))) -> 0 | C50: =IF(C49="","",IF(DAY(C49+1)=1,"",C49+1)) | D50: =TEXT(C50,"aaa") | H50: ～ | J50: =IFERROR(IF(G50="",0,I50-G50),"") -> 0 | K50: =IFERROR(IF(E50="",0,F50-E50-J50),"") -> 0 | L50: =IF(E50="",0,IF($A50=1,$K50,IF($C50="",0,IF($K50-$T$9<0,0,$K50-$T$9)))) -> 0 | T50: =E50 -> 0 | U50: =F50 -> 0 | V50: =IFERROR(IF(T50="",0,U50-T50-J50),"") -> 0 | W50: =IFERROR(FLOOR(K50,TIME(0,VLOOKUP($C$3,#REF!,22,0),0)),"") | AG50: =(Z50-Y50)+(AB50-AA50)+(AD50-AC50)+(AF50-AE50) -> 0
J51: =SUM(J20:J50) -> 0 | K51: =SUM(K20:K50) -> 0 | L51: =SUM(L20:L50) -> 0 | M51: =SUM(M20:M50) -> 0 | N51: =SUM(N20:N50) -> 0 | V51: =SUM(V20:V50) -> 0 | W51: =SUM(W20:W50) -> 0

Sheet 9月
C2: SuccessHolders 勤務報告書 | M2: (西暦) | O2: 2022 | Q2: 年 | R2: ='7月'!R2+1 -> 10 | S2: 月分 | X2: ≪入力方法について≫
C3: 社員1 | Q3: 勤務日数： | S3: =COUNTA(E20:E50)&"日" -> 0日 | X3: ・太枠内の記載をお願いします。
C4: 派遣先企業名 | N4: 派遣先事業所名 | Y4: 業務内容等は必要があれば記載をお願いします。「入力例」タブをご確認ください。
C5: 派遣先住所
C6: 就業部署名 | N6: 連絡先 | X6: ・休憩時間が複数ある場合
C7: 業務に伴う責任の程度 | F7: (業務内容) | N7: 役職名 | R7: 部下 人数 | Y7: 休憩1-4に休憩時間を入力してください。
C8: 実際の就業場所 | M8: 勤怠パターン | O8: 勤務時間 | R8: 休憩時間 | T8: 規定時間 | Y8: 休憩1-4の、合計時間をJ列の「休憩時間」に直接入力してください。
P9: ～ | T9: =Q9-O9-R9 -> 0 | Y9: G列とI列の入力は不要です。
P10: ～ | T10: =Q10-O10-R10 -> 0
P11: ～ | T11: =Q11-O11-R11 -> 0 | X11: ・深夜時間の勤務の場合、時間は下記のように退勤時刻（例 34：00）の記載をお願いします。
P12: ～ | T12: =Q12-O12-R12 -> 0 | Y12: 例：18：00～翌日10：00の場合
P13: ～ | T13: =Q13-O13-R13 -> 0 | Z13: 出勤時刻（18：00） 退勤時刻（34：00）
B14: 氏名 | C14: 氏名 | O14: フレックスタイム制 | Z14: 18時＋6時間（18時～24時合計）+10時間（0時～10時合計）＝34時間
O15: 変形労働時間制
Y16: 休憩時間が1時間以外で複数ある場合は、J列の計算式を削除して休憩時間を直接入力してください↓
C17: 例 | E17: 0.375 | F17: 0.76041667 | G17: 0.5 | I17: 0.54166667 | X17: 例 | Y17: 0.5 | Z17: 0.54166667 | AA17: 0.71875 | AB17: 0.72916667 | AC17: 0.77083333 | AD17: 0.79166667 | AE17: 0.89583333 | AF17: 0.91666667
Y18: 休憩1 | AA18: 休憩2 | AC18: 休憩3 | AE18: 休憩4
A19: 祝日判定 | C19: 月 日 | D19: 曜 日 | E19: 出勤 時刻 | F19: 退勤 時刻 | G19: 休憩 時刻 | J19: 休憩 時間 | K19: 所定 時間 | L19: 法定外 残業 | M19: 深夜 時間 | N19: 不就労 | O19: 業務内容・作業進捗状況・その他 | T19: 出勤時刻(KOT) | U19: 退勤時刻 (KOT) | V19: 所定時間 (KOT) | W19: 所定時間 (調整) | Y19: 開始 | Z19: 終了 | AA19: 開始 | AB19: 終了 | AC19: 開始 | AD19: 終了 | AE19: 開始 | AF19: 終了 | AG19: 休憩時間
A20: =IF(COUNTIFS(祝日参照用!A:A,C20)=1,1,IF(D20="土",1,IF(D20="日",1,0))) -> 1 | C20: =IFERROR(DATE(O2,R2,1),"") -> 44835 | D20: =TEXT(C20,"aaa") -> 土 | H20: ～ | J20: =IFERROR(IF(G20="",0,I20-G20),"") -> 0 | K20: =IFERROR(IF(E20="",0,F20-E20-J20),"") -> 0 | L20: =IF(E20="",0,IF($A20=1,$K20,IF($C20="",0,IF($K20-$T$9<0,0,$K20-$T$9)))) -> 0 | T20: =E20 -> 0 | U20: =F20 -> 0 | V20: =IFERROR(IF(T20="",0,U20-T20-J20),"") -> 0 | W20: =IFERROR(FLOOR(K20,TIME(0,VLOOKUP($C$3,#REF!,22,0),0)),"") | AG20: =(Z20-Y20)+(AB20-AA20)+(AD20-AC20)+(AF20-AE20) -> 0
A21: =IF(COUNTIFS(祝日参照用!A:A,C21)=1,1,IF(D21="土",1,IF(D21="日",1,0))) -> 1 | C21: =IF(C20="","",IF(DAY(C20+1)=1,"",C20+1)) -> 44836 | D21: =TEXT(C21,"aaa") -> 日 | H21: ～ | J21: =IFERROR(IF(G21="",0,I21-G21),"") -> 0 | K21: =IFERROR(IF(E21="",0,F21-E21-J21),"") -> 0 | L21: =IF(E21="",0,IF($A21=1,$K21,IF($C21="",0,IF($K21-$T$9<0,0,$K21-$T$9)))) -> 0 | T21: =E21 -> 0 | U21: =F21 -> 0 | V21: =IFERROR(IF(T21="",0,U21-T21-J21),"") -> 0 | W21: =IFERROR(FLOOR(K21,TIME(0,VLOOKUP($C$3,#REF!,22,0),0)),"") | AG21: =(Z21-Y21)+(AB21-AA21)+(AD21-AC21)+(AF21-AE21) -> 0
