Workbook

Sheet 2月
C2: SuccessHolders 勤務報告書 | M2: (西暦) | O2: 2025 | Q2: 年 | R2: 4 | S2: 月分 | X2: ≪入力方法について≫
C3: 社員1 | Q3: 勤務日数： | S3: =COUNTA(E20:E50)&"日" -> 21日 | X3: ・太枠内の記載をお願いします。
C4: 派遣先企業名 | F4: 株式会社アイテック | N4: 派遣先事業所名 | Q4: 野村證券株式会社 | Y4: 業務内容等は必要があれば記載をお願いします。「入力例」タブをご確認ください。
C5: 派遣先住所 | F5: 東京都江東区豊洲二丁目2番1号 豊洲ベイサイドクロスタワー
C6: 就業部署名 | F6: Corpデスクトップサポート | N6: 連絡先 | O6: 03-3211-1811 | X6: ・休憩時間が複数ある場合
C7: 業務に伴う責任の程度 | F7: (業務内容) サポートデスク | N7: 役職名 | R7: 部下 人数 | Y7: 休憩1-4に休憩時間を入力してください。
C8: 実際の就業場所 | F8: 野村証券株式会社 | M8: 勤怠パターン | O8: 勤務時間 | R8: 休憩時間 | T8: 規定時間 | Y8: 休憩1-4の、合計時間をJ列の「休憩時間」に直接入力してください。
O9: 0.4375 | P9: ～ | Q9: 0.79166667 | R9: 13:00~14:00 | T9: =Q9-O9-R9 -> #VALUE! | Y9: G列とI列の入力は不要です。
P10: ～ | T10: =Q10-O10-R10 -> 0
P11: ～ | T11: =Q11-O11-R11 -> 0 | X11: ・深夜時間の勤務の場合、時間は下記のように退勤時刻（例 34：00）の記載をお願いします。
P12: ～ | T12: =Q12-O12-R12 -> 0 | Y12: 例：18：00～翌日10：00の場合
P13: ～ | T13: =Q13-O13-R13 -> 0 | Z13: 出勤時刻（18：00） 退勤時刻（34：00）
B14: 氏名 | C14: 氏名 | F14: 佐久間翔太 | O14: フレックスタイム制 | Z14: 18時＋6時間（18時～24時合計）+10時間（0時～10時合計）＝34時間
O15: 変形労働時間制
Y16: 休憩時間が1時間以外で複数ある場合は、J列の計算式を削除して休憩時間を直接入力してください↓
C17: 例 | E17: 0.375 | F17: 0.76041667 | G17: 0.5 | I17: 0.54166667 | X17: 例 | Y17: 0.5 | Z17: 0.54166667 | AA17: 0.71875 | AB17: 0.72916667 | AC17: 0.77083333 | AD17: 0.79166667 | AE17: 0.89583333 | AF17: 0.91666667
Y18: 休憩1 | AA18: 休憩2 | AC18: 休憩3 | AE18: 休憩4
A19: 祝日判定 | C19: 月 日 | D19: 曜 日 | E19: 出勤 時刻 | F19: 退勤 時刻 | G19: 休憩 時刻 | J19: 休憩 時間 | K19: 所定 時間 | L19: 法定外 残業 | M19: 深夜 時間 | N19: 不就労 | O19: 業務内容・作業進捗状況・その他 | T19: 出勤時刻(KOT) | U19: 退勤時刻 (KOT) | V19: 所定時間 (KOT) | W19: 所定時間 (調整) | Y19: 開始 | Z19: 終了 | AA19: 開始 | AB19: 終了 | AC19: 開始 | AD19: 終了 | AE19: 開始 | AF19: 終了 | AG19: 休憩時間
A20: =IF(COUNTIFS(祝日参照用!A:A,C20)=1,1,IF(D20="土",1,IF(D20="日",1,0))) -> 0 | C20: =IFERROR(DATE(O2,R2,1),"") -> 45748 | D20: =TEXT(C20,"aaa") -> 火 | E20: 0.4375 | F20: 0.79166667 | G20: 0.54166667 | H20: ～ | I20: 0.58333333 | J20: =IFERROR(IF(G20="",0,I20-G20),"") -> 0.041666667 | K20: =IFERROR(IF(E20="",0,F20-E20-J20),"") -> 0.3125 | O20: サポートデスク | T20: =E20 -> 0.4375 | U20: =F20 -> 0.79166667 | V20: =IFERROR(IF(T20="",0,U20-T20-J20),"") -> 0.3125 | AG20: =(Z20-Y20)+(AB20-AA20)+(AD20-AC20)+(AF20-AE20) -> 0
A21: =IF(COUNTIFS(祝日参照用!A:A,C21)=1,1,IF(D21="土",1,IF(D21="日",1,0))) -> 0 | C21: =IF(C20="","",IF(DAY(C20+1)=1,"",C20+1)) -> 45749 | D21: =TEXT(C21,"aaa") -> 水 | E21: 0.4375 | F21: 0.79166667 | G21: 0.54166667 | H21: ～ | I21: 0.58333333 | J21: =IFERROR(IF(G21="",0,I21-G21),"") -> 0.041666667 | K21: =IFERROR(IF(E21="",0,F21-E21-J21),"") -> 0.3125 | O21: サポートデスク | T21: =E21 -> 0.4375 | U21: =F21 -> 0.79166667 | V21: =IFERROR(IF(T21="",0,U21-T21-J21),"") -> 0.3125 | W21: =IFERROR(FLOOR(K21,TIME(0,VLOOKUP($C$3,#REF!,22,0),0)),"") | AG21: =(Z21-Y21)+(AB21-AA21)+(AD21-AC21)+(AF21-AE21) -> 0
A22: =IF(COUNTIFS(祝日参照用!A:A,C22)=1,1,IF(D22="土",1,IF(D22="日",1,0))) -> 0 | C22: =IF(C21="","",IF(DAY(C21+1)=1,"",C21+1)) -> 45750 | D22: =TEXT(C22,"aaa") -> 木 | E22: 0.4375 | F22: 0.79166667 | G22: 0.54166667 | H22: ～ | I22: 0.58333333 | J22: =IFERROR(IF(G22="",0,I22-G22),"") -> 0.041666667 | K22: =IFERROR(IF(E22="",0,F22-E22-J22),"") -> 0.3125 | O22: サポートデスク | T22: =E22 -> 0.4375 | U22: =F22 -> 0.79166667 | V22: =IFERROR(IF(T22="",0,U22-T22-J22),"") -> 0.3125 | W22: =IFERROR(FLOOR(K22,TIME(0,VLOOKUP($C$3,#REF!,22,0),0)),"") | AG22: =(Z22-Y22)+(AB22-AA22)+(AD22-AC22)+(AF22-AE22) -> 0
A23: =IF(COUNTIFS(祝日参照用!A:A,C23)=1,1,IF(D23="土",1,IF(D23="日",1,0))) -> 0 | C23: =IF(C22="","",IF(DAY(C22+1)=1,"",C22+1)) -> 45751 | D23: =TEXT(C23,"aaa") -> 金 | E23: 0.4375 | F23: 0.79166667 | G23: 0.54166667 | H23: ～ | I23: 0.58333333 | J23: =IFERROR(IF(G23="",0,I23-G23),"") -> 0.041666667 | K23: =IFERROR(IF(E23="",0,F23-E23-J23),"") -> 0.3125 | O23: サポートデスク | T23: =E23 -> 0.4375 | U23: =F23 -> 0.79166667 | V23: =IFERROR(IF(T23="",0,U23-T23-J23),"") -> 0.3125 | W23: =IFERROR(FLOOR(K23,TIME(0,VLOOKUP($C$3,#REF!,22,0),0)),"") | AG23: =(Z23-Y23)+(AB23-AA23)+(AD23-AC23)+(AF23-AE23) -> 0
A24: =IF(COUNTIFS(祝日参照用!A:A,C24)=1,1,IF(D24="土",1,IF(D24="日",1,0))) -> 1 | C24: =IF(C23="","",IF(DAY(C23+1)=1,"",C23+1)) -> 45752 | D24: =TEXT(C24,"aaa") -> 土 | W24: =IFERROR(FLOOR(K24,TIME(0,VLOOKUP($C$3,#REF!,22,0),0)),"") | AG24: =(Z24-Y24)+(AB24-AA24)+(AD24-AC24)+(AF24-AE24) -> 0
A25: =IF(COUNTIFS(祝日参照用!A:A,C25)=1,1,IF(D25="土",1,IF(D25="日",1,0))) -> 1 | C25: =IF(C24="","",IF(DAY(C24+1)=1,"",C24+1)) -> 45753 | D25: =TEXT(C25,"aaa") -> 日 | W25: =IFERROR(FLOOR(K25,TIME(0,VLOOKUP($C$3,#REF!,22,0),0)),"") | AG25: =(Z25-Y25)+(AB25-AA25)+(AD25-AC25)+(AF25-AE25) -> 0
A26: =IF(COUNTIFS(祝日参照用!A:A,C26)=1,1,IF(D26="土",1,IF(D26="日",1,0))) -> 0 | C26: =IF(C25="","",IF(DAY(C25+1)=1,"",C25+1)) -> 45754 | D26: =TEXT(C26,"aaa") -> 月 | E26: 0.4375 | F26: 0.79166667 | G26: 0.54166667 | H26: ～ | I26: 0.58333333 | J26: =IFERROR(IF(G26="",0,I26-G26),"") -> 0.041666667 | K26: =IFERROR(IF(E26="",0,F26-E26-J26),"") -> 0.3125 | O26: サポートデスク | T26: =E26 -> 0.4375 | U26: =F26 -> 0.79166667 | V26: =IFERROR(IF(T26="",0,U26-T26-J26),"") -> 0.3125 | W26: =IFERROR(FLOOR(K26,TIME(0,VLOOKUP($C$3,#REF!,22,0),0)),"") | AG26: =(Z26-Y26)+(AB26-AA26)+(AD26-AC26)+(AF26-AE26) -> 0
A27: =IF(COUNTIFS(祝日参照用!A:A,C27)=1,1,IF(D27="土",1,IF(D27="日",1,0))) -> 0 | C27: =IF(C26="","",IF(DAY(C26+1)=1,"",C26+1)) -> 45755 | D27: =TEXT(C27,"aaa") -> 火 | E27: 0.4375 | F27: 0.79166667 | G27: 0.54166667 | H27: ～ | I27: 0.58333333 | J27: =IFERROR(IF(G27="",0,I27-G27),"") -> 0.041666667 | K27: =IFERROR(IF(E27="",0,F27-E27-J27),"") -> 0.3125 | O27: サポートデスク | T27: =E27 -> 0.4375 | U27: =F27 -> 0.79166667 | V27: =IFERROR(IF(T27="",0,U27-T27-J27),"") -> 0.3125 | W27: =IFERROR(FLOOR(K27,TIME(0,VLOOKUP($C$3,#REF!,22,0),0)),"") | AG27: =(Z27-Y27)+(AB27-AA27)+(AD27-AC27)+(AF27-AE27) -> 0
A28: =IF(COUNTIFS(祝日参照用!A:A,C28)=1,1,IF(D28="土",1,IF(D28="日",1,0))) -> 0 | C28: =IF(C27="","",IF(DAY(C27+1)=1,"",C27+1)) -> 45756 | D28: =TEXT(C28,"aaa") -> 水 | E28: 0.4375 | F28: 0.79166667 | G28: 0.54166667 | H28: ～ | I28: 0.58333333 | J28: =IFERROR(IF(G28="",0,I28-G28),"") -> 0.041666667 | K28: =IFERROR(IF(E28="",0,F28-E28-J28),"") -> 0.3125 | O28: サポートデスク | T28: =E28 -> 0.4375 | U28: =F28 -> 0.79166667 | V28: =IFERROR(IF(T28="",0,U28-T28-J28),"") -> 0.3125 | W28: =IFERROR(FLOOR(K28,TIME(0,VLOOKUP($C$3,#REF!,22,0),0)),"") | AG28: =(Z28-Y28)+(AB28-AA28)+(AD28-AC28)+(AF28-AE28) -> 0
A29: =IF(COUNTIFS(祝日参照用!A:A,C29)=1,1,IF(D29="土",1,IF(D29="日",1,0))) -> 0 | C29: =IF(C28="","",IF(DAY(C28+1)=1,"",C28+1)) -> 45757 | D29: =TEXT(C29,"aaa") -> 木 | E29: 0.4375 | F29: 0.79166667 | G29: 0.54166667 | H29: ～ | I29: 0.58333333 | J29: =IFERROR(IF(G29="",0,I29-G29),"") -> 0.041666667 | K29: =IFERROR(IF(E29="",0,F29-E29-J29),"") -> 0.3125 | O29: サポートデスク | T29: =E29 -> 0.4375 | U29: =F29 -> 0.79166667 | V29: =IFERROR(IF(T29="",0,U29-T29-J29),"") -> 0.3125 | W29: =IFERROR(FLOOR(K29,TIME(0,VLOOKUP($C$3,#REF!,22,0),0)),"") | AG29: =(Z29-Y29)+(AB29-AA29)+(AD29-AC29)+(AF29-AE29) -> 0
A30: =IF(COUNTIFS(祝日参照用!A:A,C30)=1,1,IF(D30="土",1,IF(D30="日",1,0))) -> 0 | C30: =IF(C29="","",IF(DAY(C29+1)=1,"",C29+1)) -> 45758 | D30: =TEXT(C30,"aaa") -> 金 | E30: 0.4375 | F30: 0.79166667 | G30: 0.54166667 | H30: ～ | I30: 0.58333333 | J30: =IFERROR(IF(G30="",0,I30-G30),"") -> 0.041666667 | K30: =IFERROR(IF(E30="",0,F30-E30-J30),"") -> 0.3125 | O30: サポートデスク | T30: =E30 -> 0.4375 | U30: =F30 -> 0.79166667 | V30: =IFERROR(IF(T30="",0,U30-T30-J30),"") -> 0.3125 | W30: =IFERROR(FLOOR(K30,TIME(0,VLOOKUP($C$3,#REF!,22,0),0)),"") | AG30: =(Z30-Y30)+(AB30-AA30)+(AD30-AC30)+(AF30-AE30) -> 0
A31: =IF(COUNTIFS(祝日参照用!A:A,C31)=1,1,IF(D31="土",1,IF(D31="日",1,0))) -> 1 | C31: =IF(C30="","",IF(DAY(C30+1)=1,"",C30+1)) -> 45759 | D31: =TEXT(C31,"aaa") -> 土 | W31: =IFERROR(FLOOR(K31,TIME(0,VLOOKUP($C$3,#REF!,22,0),0)),"") | AG31: =(Z31-Y31)+(AB31-AA31)+(AD31-AC31)+(AF31-AE31) -> 0
A32: =IF(COUNTIFS(祝日参照用!A:A,C32)=1,1,IF(D32="土",1,IF(D32="日",1,0))) -> 1 | C32: =IF(C31="","",IF(DAY(C31+1)=1,"",C31+1)) -> 45760 | D32: =TEXT(C32,"aaa") -> 日 | W32: =IFERROR(FLOOR(K32,TIME(0,VLOOKUP($C$3,#REF!,22,0),0)),"") | AG32: =(Z32-Y32)+(AB32-AA32)+(AD32-AC32)+(AF32-AE32) -> 0
A33: =IF(COUNTIFS(祝日参照用!A:A,C33)=1,1,IF(D33="土",1,IF(D33="日",1,0))) -> 0 | C33: =IF(C32="","",IF(DAY(C32+1)=1,"",C32+1)) -> 45761 | D33: =TEXT(C33,"aaa") -> 月 | E33: 0.4375 | F33: 0.79166667 | G33: 0.54166667 | H33: ～ | I33: 0.58333333 | J33: =IFERROR(IF(G33="",0,I33-G33),"") -> 0.041666667 | K33: =IFERROR(IF(E33="",0,F33-E33-J33),"") -> 0.3125 | O33: サポートデスク | T33: =E33 -> 0.4375 | U33: =F33 -> 0.79166667 | V33: =IFERROR(IF(T33="",0,U33-T33-J33),"") -> 0.3125 | W33: =IFERROR(FLOOR(K33,TIME(0,VLOOKUP($C$3,#REF!,22,0),0)),"") | AG33: =(Z33-Y33)+(AB33-AA33)+(AD33-AC33)+(AF33-AE33) -> 0
A34: =IF(COUNTIFS(祝日参照用!A:A,C34)=1,1,IF(D34="土",1,IF(D34="日",1,0))) -> 0 | C34: =IF(C33="","",IF(DAY(C33+1)=1,"",C33+1)) -> 45762 | D34: =TEXT(C34,"aaa") -> 火 | E34: 0.4375 | F34: 0.79166667 | G34: 0.54166667 | H34: ～ | I34: 0.58333333 | J34: =IFERROR(IF(G34="",0,I34-G34),"") -> 0.041666667 | K34: =IFERROR(IF(E34="",0,F34-E34-J34),"") -> 0.3125 | O34: サポートデスク | T34: =E34 -> 0.4375 | U34: =F34 -> 0.79166667 | V34: =IFERROR(IF(T34="",0,U34-T34-J34),"") -> 0.3125 | W34: =IFERROR(FLOOR(K34,TIME(0,VLOOKUP($C$3,#REF!,22,0),0)),"") | AG34: =(Z34-Y34)+(AB34-AA34)+(AD34-AC34)+(AF34-AE34) -> 0
A35: =IF(COUNTIFS(祝日参照用!A:A,C35)=1,1,IF(D35="土",1,IF(D35="日",1,0))) -> 0 | C35: =IF(C34="","",IF(DAY(C34+1)=1,"",C34+1)) -> 45763 | D35: =TEXT(C35,"aaa") -> 水 | E35: 0.4375 | F35: 0.79166667 | G35: 0.54166667 | H35: ～ | I35: 0.58333333 | J35: =IFERROR(IF(G35="",0,I35-G35),"") -> 0.041666667 | K35: =IFERROR(IF(E35="",0,F35-E35-J35),"") -> 0.3125 | O35: サポートデスク | T35: =E35 -> 0.4375 | U35: =F35 -> 0.79166667 | V35: =IFERROR(IF(T35="",0,U35-T35-J35),"") -> 0.3125 | AG35: =(Z35-Y35)+(AB35-AA35)+(AD35-AC35)+(AF35-AE35) -> 0
A36: =IF(COUNTIFS(祝日参照用!A:A,C36)=1,1,IF(D36="土",1,IF(D36="日",1,0))) -> 0 | C36: =IF(C35="","",IF(DAY(C35+1)=1,"",C35+1)) -> 45764 | D36: =TEXT(C36,"aaa") -> 木 | E36: 0.4375 | F36: 0.79166667 | G36: 0.54166667 | H36: ～ | I36: 0.58333333 | J36: =IFERROR(IF(G36="",0,I36-G36),"") -> 0.041666667 | K36: =IFERROR(IF(E36="",0,F36-E36-J36),"") -> 0.3125 | O36: サポートデスク | T36: =E36 -> 0.4375 | U36: =F36 -> 0.79166667 | V36: =IFERROR(IF(T36="",0,U36-T36-J36),"") -> 0.3125 | W36: =IFERROR(FLOOR(K36,TIME(0,VLOOKUP($C$3,#REF!,22,0),0)),"") | AG36: =(Z36-Y36)+(AB36-AA36)+(AD36-AC36)+(AF36-AE36) -> 0
A37: =IF(COUNTIFS(祝日参照用!A:A,C37)=1,1,IF(D37="土",1,IF(D37="日",1,0))) -> 0 | C37: =IF(C36="","",IF(DAY(C36+1)=1,"",C36+1)) -> 45765 | D37: =TEXT(C37,"aaa") -> 金 | E37: 0.4375 | F37: 0.79166667 | G37: 0.54166667 | H37: ～ | I37: 0.58333333 | J37: =IFERROR(IF(G37="",0,I37-G37),"") -> 0.041666667 | K37: =IFERROR(IF(E37="",0,F37-E37-J37),"") -> 0.3125 | O37: サポートデスク | T37: =E37 -> 0.4375 | U37: =F37 -> 0.79166667 | V37: =IFERROR(IF(T37="",0,U37-T37-J37),"") -> 0.3125 | W37: =IFERROR(FLOOR(K37,TIME(0,VLOOKUP($C$3,#REF!,22,0),0)),"") | AG37: =(Z37-Y37)+(AB37-AA37)+(AD37-AC37)+(AF37-AE37) -> 0
A38: =IF(COUNTIFS(祝日参照用!A:A,C38)=1,1,IF(D38="土",1,IF(D38="日",1,0))) -> 1 | C38: =IF(C37="","",IF(DAY(C37+1)=1,"",C37+1)) -> 45766 | D38: =TEXT(C38,"aaa") -> 土 | W38: =IFERROR(FLOOR(K38,TIME(0,VLOOKUP($C$3,#REF!,22,0),0)),"") | AG38: =(Z38-Y38)+(AB38-AA38)+(AD38-AC38)+(AF38-AE38) -> 0
A39: =IF(COUNTIFS(祝日参照用!A:A,C39)=1,1,IF(D39="土",1,IF(D39="日",1,0))) -> 1 | C39: =IF(C38="","",IF(DAY(C38+1)=1,"",C38+1)) -> 45767 | D39: =TEXT(C39,"aaa") -> 日 | AG39: =(Z39-Y39)+(AB39-AA39)+(AD39-AC39)+(AF39-AE39) -> 0
A40: =IF(COUNTIFS(祝日参照用!A:A,C40)=1,1,IF(D40="土",1,IF(D40="日",1,0))) -> 0 | C40: =IF(C39="","",IF(DAY(C39+1)=1,"",C39+1)) -> 45768 | D40: =TEXT(C40,"aaa") -> 月 | E40: 0.4375 | F40: 0.79166667 | G40: 0.54166667 | H40: ～ | I40: 0.58333333 | J40: =IFERROR(IF(G40="",0,I40-G40),"") -> 0.041666667 | K40: =IFERROR(IF(E40="",0,F40-E40-J40),"") -> 0.3125 | O40: サポートデスク | T40: =E40 -> 0.4375 | U40: =F40 -> 0.79166667 | V40: =IFERROR(IF(T40="",0,U40-T40-J40),"") -> 0.3125 | AG40: =(Z40-Y40)+(AB40-AA40)+(AD40-AC40)+(AF40-AE40) -> 0
A41: =IF(COUNTIFS(祝日参照用!A:A,C41)=1,1,IF(D41="土",1,IF(D41="日",1,0))) -> 0 | C41: =IF(C40="","",IF(DAY(C40+1)=1,"",C40+1)) -> 45769 | D41: =TEXT(C41,"aaa") -> 火 | E41: 0.4375 | F41: 0.79166667 | G41: 0.54166667 | H41: ～ | I41: 0.58333333 | J41: =IFERROR(IF(G41="",0,I41-G41),"") -> 0.041666667 | K41: =IFERROR(IF(E41="",0,F41-E41-J41),"") -> 0.3125 | O41: サポートデスク | T41: =E41 -> 0.4375 | U41: =F41 -> 0.79166667 | V41: =IFERROR(IF(T41="",0,U41-T41-J41),"") -> 0.3125 | AG41: =(Z41-Y41)+(AB41-AA41)+(AD41-AC41)+(AF41-AE41) -> 0
...

Sheet 社員10
C1: SuccessHolders 勤務報告書 | M1: (西暦) | O1: =#REF! -> #REF! | Q1: 年 | R1: =#REF! -> #REF! | S1: 月分 | Y1: 勤怠サマリーへ
C2: 社員10 | Q2: 勤務日数： | S2: =COUNTA(E14:E44)&"日" -> 0日
C3: 派遣先企業名 | F3: =VLOOKUP($C$2,#REF!,4,0) -> #REF! | N3: 派遣先事業所名
C4: 派遣先住所
C5: 就業部署名 | N5: 連絡先
C6: 業務に伴う 責任の程度 | F6: (業務内容) | N6: 役職名 | R6: 部下 人数
C7: 実際の就業場所 | M7: 勤怠パターン | O7: 勤務時間 | R7: 休憩時間 | T7: 規定時間
O8: 0.35416667 | P8: ～ | Q8: 0.72916667 | R8: 0.041666667 | T8: =Q8-O8-R8 -> 0.33333333
P9: ～ | T9: =Q9-O9-R9 -> 0
B10: 氏名 | C10: 氏名 | F10: =VLOOKUP($C$2,#REF!,3,0) -> #REF! | O10: フレックスタイム制 | S10: 非対象
O11: 変形労働時間制 | S11: 非対象
A13: 祝日判定 | B13: チェック | C13: 月 日 | D13: 曜 日 | E13: 出勤 時刻 | F13: 退勤 時刻 | G13: 休憩 時刻 | J13: 休憩 時間 | K13: 所定 時間 | L13: 法定外 残業 | M13: 深夜 時間 | N13: 不就労 | O13: 業務内容・作業進捗状況・その他 | T13: 出勤時刻(KOT) | U13: 退勤時刻 (KOT) | V13: 所定時間 (KOT) | W13: 所定時間 (調整) | X13: 日当計算
A14: =IF(COUNTIFS(祝日参照用!A:A,C14)=1,1,IF(D14="土",1,IF(D14="日",1,0))) -> 0 | C14: =IFERROR(DATE(O1,R1,1),"") | D14: =TEXT(C14,"ddd") | H14: =IF(G14="","","～") | J14: =IFERROR(IF(G14="",0,I14-G14),"") -> 0 | K14: =IFERROR(IF(E14="",0,F14-E14-J14),"") -> 0 | L14: =IF(E14="",0,IF($A14=1,$K14,IF($C14="",0,IF($K14-$T$8<0,0,$K14-$T$8)))) -> 0 | V14: =IFERROR(IF(T14="",0,U14-T14-J14),"") -> 0 | W14: =IFERROR(FLOOR(K14,TIME(0,VLOOKUP($C$2,#REF!,22,0),0)),"") | X14: =IF(VLOOKUP($C$2,#REF!,24,0)="日当",IF(K14=0,"",IF(K14<T$8,VLOOKUP($C$2,#REF!,21,0)*VALUE(K14-T$8)*24+VLOOKUP($C$2,#REF!,19,0),VLOOKUP($C$2,#REF!,20,0)*VALUE(K14-T$8)*24+VLOOKUP($C$2,#REF!,19,0))),"") -> #REF!
A15: =IF(COUNTIFS(祝日参照用!A:A,C15)=1,1,IF(D15="土",1,IF(D15="日",1,0))) -> 0 | C15: =IF(C14="","",IF(DAY(C14+1)=1,"",C14+1)) | D15: =TEXT(C15,"ddd") | H15: =IF(G15="","","～") | J15: =IFERROR(IF(G15="",0,I15-G15),"") -> 0 | K15: =IFERROR(IF(E15="",0,F15-E15-J15),"") -> 0 | L15: =IF(E15="",0,IF($A15=1,$K15,IF($C15="",0,IF($K15-$T$8<0,0,$K15-$T$8)))) -> 0 | V15: =IFERROR(IF(T15="",0,U15-T15-J15),"") -> 0 | W15: =IFERROR(FLOOR(K15,TIME(0,VLOOKUP($C$2,#REF!,22,0),0)),"") | X15: =IF(VLOOKUP($C$2,#REF!,24,0)="日当",IF(K15=0,"",IF(K15<T$8,VLOOKUP($C$2,#REF!,21,0)*VALUE(K15-T$8)*24+VLOOKUP($C$2,#REF!,19,0),VLOOKUP($C$2,#REF!,20,0)*VALUE(K15-T$8)*24+VLOOKUP($C$2,#REF!,19,0))),"") -> #REF!
A16: =IF(COUNTIFS(祝日参照用!A:A,C16)=1,1,IF(D16="土",1,IF(D16="日",1,0))) -> 0 | C16: =IF(C15="","",IF(DAY(C15+1)=1,"",C15+1)) | D16: =TEXT(C16,"ddd") | H16: =IF(G16="","","～") | J16: =IFERROR(IF(G16="",0,I16-G16),"") -> 0 | K16: =IFERROR(IF(E16="",0,F16-E16-J16),"") -> 0 | L16: =IF(E16="",0,IF($A16=1,$K16,IF($C16="",0,IF($K16-$T$8<0,0,$K16-$T$8)))) -> 0 | V16: =IFERROR(IF(T16="",0,U16-T16-J16),"") -> 0 | W16: =IFERROR(FLOOR(K16,TIME(0,VLOOKUP($C$2,#REF!,22,0),0)),"") | X16: =IF(VLOOKUP($C$2,#REF!,24,0)="日当",IF(K16=0,"",IF(K16<T$8,VLOOKUP($C$2,#REF!,21,0)*VALUE(K16-T$8)*24+VLOOKUP($C$2,#REF!,19,0),VLOOKUP($C$2,#REF!,20,0)*VALUE(K16-T$8)*24+VLOOKUP($C$2,#REF!,19,0))),"") -> #REF!
A17: =IF(COUNTIFS(祝日参照用!A:A,C17)=1,1,IF(D17="土",1,IF(D17="日",1,0))) -> 0 | C17: =IF(C16="","",IF(DAY(C16+1)=1,"",C16+1)) | D17: =TEXT(C17,"ddd") | H17: =IF(G17="","","～") | J17: =IFERROR(IF(G17="",0,I17-G17),"") -> 0 | K17: =IFERROR(IF(E17="",0,F17-E17-J17),"") -> 0 | L17: =IF(E17="",0,IF($A17=1,$K17,IF($C17="",0,IF($K17-$T$8<0,0,$K17-$T$8)))) -> 0 | V17: =IFERROR(IF(T17="",0,U17-T17-J17),"") -> 0 | W17: =IFERROR(FLOOR(K17,TIME(0,VLOOKUP($C$2,#REF!,22,0),0)),"") | X17: =IF(VLOOKUP($C$2,#REF!,24,0)="日当",IF(K17=0,"",IF(K17<T$8,VLOOKUP($C$2,#REF!,21,0)*VALUE(K17-T$8)*24+VLOOKUP($C$2,#REF!,19,0),VLOOKUP($C$2,#REF!,20,0)*VALUE(K17-T$8)*24+VLOOKUP($C$2,#REF!,19,0))),"") -> #REF!
A18: =IF(COUNTIFS(祝日参照用!A:A,C18)=1,1,IF(D18="土",1,IF(D18="日",1,0))) -> 0 | C18: =IF(C17="","",IF(DAY(C17+1)=1,"",C17+1)) | D18: =TEXT(C18,"ddd") | H18: =IF(G18="","","～") | J18: =IFERROR(IF(G18="",0,I18-G18),"") -> 0 | K18: =IFERROR(IF(E18="",0,F18-E18-J18),"") -> 0 | L18: =IF(E18="",0,IF($A18=1,$K18,IF($C18="",0,IF($K18-$T$8<0,0,$K18-$T$8)))) -> 0 | V18: =IFERROR(IF(T18="",0,U18-T18-J18),"") -> 0 | W18: =IFERROR(FLOOR(K18,TIME(0,VLOOKUP($C$2,#REF!,22,0),0)),"") | X18: =IF(VLOOKUP($C$2,#REF!,24,0)="日当",IF(K18=0,"",IF(K18<T$8,VLOOKUP($C$2,#REF!,21,0)*VALUE(K18-T$8)*24+VLOOKUP($C$2,#REF!,19,0),VLOOKUP($C$2,#REF!,20,0)*VALUE(K18-T$8)*24+VLOOKUP($C$2,#REF!,19,0))),"") -> #REF!
A19: =IF(COUNTIFS(祝日参照用!A:A,C19)=1,1,IF(D19="土",1,IF(D19="日",1,0))) -> 0 | C19: =IF(C18="","",IF(DAY(C18+1)=1,"",C18+1)) | D19: =TEXT(C19,"ddd") | H19: =IF(G19="","","～") | J19: =IFERROR(IF(G19="",0,I19-G19),"") -> 0 | K19: =IFERROR(IF(E19="",0,F19-E19-J19),"") -> 0 | L19: =IF(E19="",0,IF($A19=1,$K19,IF($C19="",0,IF($K19-$T$8<0,0,$K19-$T$8)))) -> 0 | V19: =IFERROR(IF(T19="",0,U19-T19-J19),"") -> 0 | W19: =IFERROR(FLOOR(K19,TIME(0,VLOOKUP($C$2,#REF!,22,0),0)),"") | X19: =IF(VLOOKUP($C$2,#REF!,24,0)="日当",IF(K19=0,"",IF(K19<T$8,VLOOKUP($C$2,#REF!,21,0)*VALUE(K19-T$8)*24+VLOOKUP($C$2,#REF!,19,0),VLOOKUP($C$2,#REF!,20,0)*VALUE(K19-T$8)*24+VLOOKUP($C$2,#REF!,19,0))),"") -> #REF!
A20: =IF(COUNTIFS(祝日参照用!A:A,C20)=1,1,IF(D20="土",1,IF(D20="日",1,0))) -> 0 | C20: =IF(C19="","",IF(DAY(C19+1)=1,"",C19+1)) | D20: =TEXT(C20,"ddd") | H20: =IF(G20="","","～") | J20: =IFERROR(IF(G20="",0,I20-G20),"") -> 0 | K20: =IFERROR(IF(E20="",0,F20-E20-J20),"") -> 0 | L20: =IF(E20="",0,IF($A20=1,$K20,IF($C20="",0,IF($K20-$T$8<0,0,$K20-$T$8)))) -> 0 | V20: =IFERROR(IF(T20="",0,U20-T20-J20),"") -> 0 | W20: =IFERROR(FLOOR(K20,TIME(0,VLOOKUP($C$2,#REF!,22,0),0)),"") | X20: =IF(VLOOKUP($C$2,#REF!,24,0)="日当",IF(K20=0,"",IF(K20<T$8,VLOOKUP($C$2,#REF!,21,0)*VALUE(K20-T$8)*24+VLOOKUP($C$2,#REF!,19,0),VLOOKUP($C$2,#REF!,20,0)*VALUE(K20-T$8)*24+VLOOKUP($C$2,#REF!,19,0))),"") -> #REF!
A21: =IF(COUNTIFS(祝日参照用!A:A,C21)=1,1,IF(D21="土",1,IF(D21="日",1,0))) -> 0 | C21: =IF(C20="","",IF(DAY(C20+1)=1,"",C20+1)) | D21: =TEXT(C21,"ddd") | H21: =IF(G21="","","～") | J21: =IFERROR(IF(G21="",0,I21-G21),"") -> 0 | K21: =IFERROR(IF(E21="",0,F21-E21-J21),"") -> 0 | L21: =IF(E21="",0,IF($A21=1,$K21,IF($C21="",0,IF($K21-$T$8<0,0,$K21-$T$8)))) -> 0 | V21: =IFERROR(IF(T21="",0,U21-T21-J21),"") -> 0 | W21: =IFERROR(FLOOR(K21,TIME(0,VLOOKUP($C$2,#REF!,22,0),0)),"") | X21: =IF(VLOOKUP($C$2,#REF!,24,0)="日当",IF(K21=0,"",IF(K21<T$8,VLOOKUP($C$2,#REF!,21,0)*VALUE(K21-T$8)*24+VLOOKUP($C$2,#REF!,19,0),VLOOKUP($C$2,#REF!,20,0)*VALUE(K21-T$8)*24+VLOOKUP($C$2,#REF!,19,0))),"") -> #REF!
A22: =IF(COUNTIFS(祝日参照用!A:A,C22)=1,1,IF(D22="土",1,IF(D22="日",1,0))) -> 0 | C22: =IF(C21="","",IF(DAY(C21+1)=1,"",C21+1)) | D22: =TEXT(C22,"ddd") | H22: =IF(G22="","","～") | J22: =IFERROR(IF(G22="",0,I22-G22),"") -> 0 | K22: =IFERROR(IF(E22="",0,F22-E22-J22),"") -> 0 | L22: =IF(E22="",0,IF($A22=1,$K22,IF($C22="",0,IF($K22-$T$8<0,0,$K22-$T$8)))) -> 0 | V22: =IFERROR(IF(T22="",0,U22-T22-J22),"") -> 0 | W22: =IFERROR(FLOOR(K22,TIME(0,VLOOKUP($C$2,#REF!,22,0),0)),"") | X22: =IF(VLOOKUP($C$2,#REF!,24,0)="日当",IF(K22=0,"",IF(K22<T$8,VLOOKUP($C$2,#REF!,21,0)*VALUE(K22-T$8)*24+VLOOKUP($C$2,#REF!,19,0),VLOOKUP($C$2,#REF!,20,0)*VALUE(K22-T$8)*24+VLOOKUP($C$2,#REF!,19,0))),"") -> #REF!
A23: =IF(COUNTIFS(祝日参照用!A:A,C23)=1,1,IF(D23="土",1,IF(D23="日",1,0))) -> 0 | C23: =IF(C22="","",IF(DAY(C22+1)=1,"",C22+1)) | D23: =TEXT(C23,"ddd") | H23: =IF(G23="","","～") | J23: =IFERROR(IF(G23="",0,I23-G23),"") -> 0 | K23: =IFERROR(IF(E23="",0,F23-E23-J23),"") -> 0 | L23: =IF(E23="",0,IF($A23=1,$K23,IF($C23="",0,IF($K23-$T$8<0,0,$K23-$T$8)))) -> 0 | V23: =IFERROR(IF(T23="",0,U23-T23-J23),"") -> 0 | W23: =IFERROR(FLOOR(K23,TIME(0,VLOOKUP($C$2,#REF!,22,0),0)),"") | X23: =IF(VLOOKUP($C$2,#REF!,24,0)="日当",IF(K23=0,"",IF(K23<T$8,VLOOKUP($C$2,#REF!,21,0)*VALUE(K23-T$8)*24+VLOOKUP($C$2,#REF!,19,0),VLOOKUP($C$2,#REF!,20,0)*VALUE(K23-T$8)*24+VLOOKUP($C$2,#REF!,19,0))),"") -> #REF!
A24: =IF(COUNTIFS(祝日参照用!A:A,C24)=1,1,IF(D24="土",1,IF(D24="日",1,0))) -> 0 | C24: =IF(C23="","",IF(DAY(C23+1)=1,"",C23+1)) | D24: =TEXT(C24,"ddd") | H24: =IF(G24="","","～") | J24: =IFERROR(IF(G24="",0,I24-G24),"") -> 0 | K24: =IFERROR(IF(E24="",0,F24-E24-J24),"") -> 0 | L24: =IF(E24="",0,IF($A24=1,$K24,IF($C24="",0,IF($K24-$T$8<0,0,$K24-$T$8)))) -> 0 | V24: =IFERROR(IF(T24="",0,U24-T24-J24),"") -> 0 | W24: =IFERROR(FLOOR(K24,TIME(0,VLOOKUP($C$2,#REF!,22,0),0)),"") | X24: =IF(VLOOKUP($C$2,#REF!,24,0)="日当",IF(K24=0,"",IF(K24<T$8,VLOOKUP($C$2,#REF!,21,0)*VALUE(K24-T$8)*24+VLOOKUP($C$2,#REF!,19,0),VLOOKUP($C$2,#REF!,20,0)*VALUE(K24-T$8)*24+VLOOKUP($C$2,#REF!,19,0))),"") -> #REF!
A25: =IF(COUNTIFS(祝日参照用!A:A,C25)=1,1,IF(D25="土",1,IF(D25="日",1,0))) -> 0 | C25: =IF(C24="","",IF(DAY(C24+1)=1,"",C24+1)) | D25: =TEXT(C25,"ddd") | H25: =IF(G25="","","～") | J25: =IFERROR(IF(G25="",0,I25-G25),"") -> 0 | K25: =IFERROR(IF(E25="",0,F25-E25-J25),"") -> 0 | L25: =IF(E25="",0,IF($A25=1,$K25,IF($C25="",0,IF($K25-$T$8<0,0,$K25-$T$8)))) -> 0 | V25: =IFERROR(IF(T25="",0,U25-T25-J25),"") -> 0 | W25: =IFERROR(FLOOR(K25,TIME(0,VLOOKUP($C$2,#REF!,22,0),0)),"") | X25: =IF(VLOOKUP($C$2,#REF!,24,0)="日当",IF(K25=0,"",IF(K25<T$8,VLOOKUP($C$2,#REF!,21,0)*VALUE(K25-T$8)*24+VLOOKUP($C$2,#REF!,19,0),VLOOKUP($C$2,#REF!,20,0)*VALUE(K25-T$8)*24+VLOOKUP($C$2,#REF!,19,0))),"") -> #REF!
A26: =IF(COUNTIFS(祝日参照用!A:A,C26)=1,1,IF(D26="土",1,IF(D26="日",1,0))) -> 0 | C26: =IF(C25="","",IF(DAY(C25+1)=1,"",C25+1)) | D26: =TEXT(C26,"ddd") | H26: =IF(G26="","","～") | J26: =IFERROR(IF(G26="",0,I26-G26),"") -> 0 | K26: =IFERROR(IF(E26="",0,F26-E26-J26),"") -> 0 | L26: =IF(E26="",0,IF($A26=1,$K26,IF($C26="",0,IF($K26-$T$8<0,0,$K26-$T$8)))) -> 0 | V26: =IFERROR(IF(T26="",0,U26-T26-J26),"") -> 0 | W26: =IFERROR(FLOOR(K26,TIME(0,VLOOKUP($C$2,#REF!,22,0),0)),"") | X26: =IF(VLOOKUP($C$2,#REF!,24,0)="日当",IF(K26=0,"",IF(K26<T$8,VLOOKUP($C$2,#REF!,21,0)*VALUE(K26-T$8)*24+VLOOKUP($C$2,#REF!,19,0),VLOOKUP($C$2,#REF!,20,0)*VALUE(K26-T$8)*24+VLOOKUP($C$2,#REF!,19,0))),"") -> #REF!
... A44: =IF(COUNTIFS(祝日参照用!A:A,C44)=1,1,IF(D44="土",1,IF(D44="日",1,0))) -> 0 | C44: =IF(C43="","",IF(DAY(C43+1)=1,"",C43+1)) | D44: =TEXT(C44,"ddd") | H44: =IF(G44="","","～") | J44: =IFERROR(IF(G44="",0,I44-G44),"") -> 0 | K44: =IFERROR(IF(E44="",0,F44-E44-J44),"") -> 0 | L44: =IF(E44="",0,IF($A44=1,$K44,IF($C44="",0,IF($K44-$T$8<0,0,$K44-$T$8)))) -> 0 | V44: =IFERROR(IF(T44="",0,U44-T44-J44),"") -> 0 | W44: =IFERROR(FLOOR(K44,TIME(0,VLOOKUP($C$2,#REF!,22,0),0)),"") | X44: =IF(VLOOKUP($C$2,#REF!,24,0)="日当",IF(K44=0,"",IF(K44<T$8,VLOOKUP($C$2,#REF!,21,0)*VALUE(K44-T$8)*24+VLOOKUP($C$2,#REF!,19,0),VLOOKUP($C$2,#REF!,20,0)*VALUE(K44-T$8)*24+VLOOKUP($C$2,#REF!,19,0))),"") -> #REF!
J45: =SUM(J14:J44) -> 0 | K45: =SUM(K14:K44) -> 0 | L45: =SUM(L14:L44) -> 0 | M45: =SUM(M14:M44) -> 0 | N45: =SUM(N14:N44) -> 0 | V45: =SUM(V14:V44) -> 0 | W45: =SUM(W14:W44) -> 0 | X45: =IF(Z5="日当",SUM(X14:X44),"")

Sheet 社員32
C1: SuccessHolders 勤務報告書 | M1: (西暦) | O1: =#REF! -> #REF! | Q1: 年 | R1: =#REF! -> #REF! | S1: 月分 | Y1: 勤怠サマリーへ
C2: 社員32 | Q2: 勤務日数： | S2: =COUNTA(E14:E44)&"日" -> 0日
C3: 派遣先企業名 | F3: =VLOOKUP($C$2,#REF!,4,0) -> #REF! | N3: 派遣先事業所名
C4: 派遣先住所
C5: 就業部署名 | N5: 連絡先
C6: 業務に伴う 責任の程度 | F6: (業務内容) | N6: 役職名 | R6: 部下 人数
C7: 実際の就業場所 | M7: 勤怠パターン | O7: 勤務時間 | R7: 休憩時間 | T7: 規定時間
O8: 0.375 | P8: ～ | Q8: 0.72916667 | R8: 0.041666667 | T8: =Q8-O8-R8 -> 0.3125
P9: ～ | T9: =Q9-O9-R9 -> 0
B10: 氏名 | C10: 氏名 | F10: =VLOOKUP($C$2,#REF!,3,0) -> #REF! | O10: フレックスタイム制
O11: 変形労働時間制
A13: 祝日判定 | B13: チェック | C13: 月 日 | D13: 曜 日 | E13: 出勤 時刻 | F13: 退勤 時刻 | G13: 休憩 時刻 | J13: 休憩 時間 | K13: 所定 時間 | L13: 法定外 残業 | M13: 深夜 時間 | N13: 不就労 | O13: 業務内容・作業進捗状況・その他 | T13: 出勤時刻(KOT) | U13: 退勤時刻 (KOT) | V13: 所定時間 (KOT) | W13: 所定時間 (調整) | X13: 日当計算
A14: =IF(COUNTIFS(祝日参照用!A:A,C14)=1,1,IF(D14="土",1,IF(D14="日",1,0))) -> 0 | C14: =IFERROR(DATE(O1,R1,1),"") | D14: =TEXT(C14,"ddd") | H14: =IF(G14="","","～") | J14: =IFERROR(IF(G14="",0,I14-G14),"") -> 0 | K14: =IFERROR(IF(E14="",0,F14-E14-J14),"") -> 0 | L14: =IF(E14="",0,IF($A14=1,$K14,IF($C14="",0,IF($K14-$T$8<0,0,$K14-$T$8)))) -> 0 | V14: =IFERROR(IF(T14="",0,U14-T14-J14),"") -> 0 | W14: =IFERROR(FLOOR(K14,TIME(0,VLOOKUP($C$2,#REF!,22,0),0)),"") | X14: =IF(VLOOKUP($C$2,#REF!,24,0)="日当",IF(K14=0,"",IF(K14<T$8,VLOOKUP($C$2,#REF!,21,0)*VALUE(K14-T$8)*24+VLOOKUP($C$2,#REF!,19,0),VLOOKUP($C$2,#REF!,20,0)*VALUE(K14-T$8)*24+VLOOKUP($C$2,#REF!,19,0))),"") -> #REF!
A15: =IF(COUNTIFS(祝日参照用!A:A,C15)=1,1,IF(D15="土",1,IF(D15="日",1,0))) -> 0 | C15: =IF(C14="","",IF(DAY(C14+1)=1,"",C14+1)) | D15: =TEXT(C15,"ddd") | H15: =IF(G15="","","～") | J15: =IFERROR(IF(G15="",0,I15-G15),"") -> 0 | K15: =IFERROR(IF(E15="",0,F15-E15-J15),"") -> 0 | L15: =IF(E15="",0,IF($A15=1,$K15,IF($C15="",0,IF($K15-$T$8<0,0,$K15-$T$8)))) -> 0 | V15: =IFERROR(IF(T15="",0,U15-T15-J15),"") -> 0 | W15: =IFERROR(FLOOR(K15,TIME(0,VLOOKUP($C$2,#REF!,22,0),0)),"") | X15: =IF(VLOOKUP($C$2,#REF!,24,0)="日当",IF(K15=0,"",IF(K15<T$8,VLOOKUP($C$2,#REF!,21,0)*VALUE(K15-T$8)*24+VLOOKUP($C$2,#REF!,19,0),VLOOKUP($C$2,#REF!,20,0)*VALUE(K15-T$8)*24+VLOOKUP($C$2,#REF!,19,0))),"") -> #REF!
A16: =IF(COUNTIFS(祝日参照用!A:A,C16)=1,1,IF(D16="土",1,IF(D16="日",1,0))) -> 0 | C16: =IF(C15="","",IF(DAY(C15+1)=1,"",C15+1)) | D16: =TEXT(C16,"ddd") | H16: =IF(G16="","","～") | J16: =IFERROR(IF(G16="",0,I16-G16),"") -> 0 | K16: =IFERROR(IF(E16="",0,F16-E16-J16),"") -> 0 | L16: =IF(E16="",0,IF($A16=1,$K16,IF($C16="",0,IF($K16-$T$8<0,0,$K16-$T$8)))) -> 0 | V16: =IFERROR(IF(T16="",0,U16-T16-J16),"") -> 0 | W16: =IFERROR(FLOOR(K16,TIME(0,VLOOKUP($C$2,#REF!,22,0),0)),"") | X16: =IF(VLOOKUP($C$2,#REF!,24,0)="日当",IF(K16=0,"",IF(K16<T$8,VLOOKUP($C$2,#REF!,21,0)*VALUE(K16-T$8)*24+VLOOKUP($C$2,#REF!,19,0),VLOOKUP($C$2,#REF!,20,0)*VALUE(K16-T$8)*24+VLOOKUP($C$2,#REF!,19,0))),"") -> #REF!
A17: =IF(COUNTIFS(祝日参照用!A:A,C17)=1,1,IF(D17="土",1,IF(D17="日",1,0))) -> 0 | C17: =IF(C16="","",IF(DAY(C16+1)=1,"",C16+1)) | D17: =TEXT(C17,"ddd") | H17: =IF(G17="","","～") | J17: =IFERROR(IF(G17="",0,I17-G17),"") -> 0 | K17: =IFERROR(IF(E17="",0,F17-E17-J17),"") -> 0 | L17: =IF(E17="",0,IF($A17=1,$K17,IF($C17="",0,IF($K17-$T$8<0,0,$K17-$T$8)))) -> 0 | V17: =IFERROR(IF(T17="",0,U17-T17-J17),"") -> 0 | W17: =IFERROR(FLOOR(K17,TIME(0,VLOOKUP($C$2,#REF!,22,0),0)),"") | X17: =IF(VLOOKUP($C$2,#REF!,24,0)="日当",IF(K17=0,"",IF(K17<T$8,VLOOKUP($C$2,#REF!,21,0)*VALUE(K17-T$8)*24+VLOOKUP($C$2,#REF!,19,0),VLOOKUP($C$2,#REF!,20,0)*VALUE(K17-T$8)*24+VLOOKUP($C$2,#REF!,19,0))),"") -> #REF!
A18: =IF(COUNTIFS(祝日参照用!A:A,C18)=1,1,IF(D18="土",1,IF(D18="日",1,0))) -> 0 | C18: =IF(C17="","",IF(DAY(C17+1)=1,"",C17+1)) | D18: =TEXT(C18,"ddd") | H18: =IF(G18="","","～") | J18: =IFERROR(IF(G18="",0,I18-G18),"") -> 0 | K18: =IFERROR(IF(E18="",0,F18-E18-J18),"") -> 0 | L18: =IF(E18="",0,IF($A18=1,$K18,IF($C18="",0,IF($K18-$T$8<0,0,$K18-$T$8)))) -> 0 | V18: =IFERROR(IF(T18="",0,U18-T18-J18),"") -> 0 | W18: =IFERROR(FLOOR(K18,TIME(0,VLOOKUP($C$2,#REF!,22,0),0)),"") | X18: =IF(VLOOKUP($C$2,#REF!,24,0)="日当",IF(K18=0,"",IF(K18<T$8,VLOOKUP($C$2,#REF!,21,0)*VALUE(K18-T$8)*24+VLOOKUP($C$2,#REF!,19,0),VLOOKUP($C$2,#REF!,20,0)*VALUE(K18-T$8)*24+VLOOKUP($C$2,#REF!,19,0))),"") -> #REF!
A19: =IF(COUNTIFS(祝日参照用!A:A,C19)=1,1,IF(D19="土",1,IF(D19="日",1,0))) -> 0 | C19: =IF(C18="","",IF(DAY(C18+1)=1,"",C18+1)) | D19: =TEXT(C19,"ddd") | H19: =IF(G19="","","～") | J19: =IFERROR(IF(G19="",0,I19-G19),"") -> 0 | K19: =IFERROR(IF(E19="",0,F19-E19-J19),"") -> 0 | L19: =IF(E19="",0,IF($A19=1,$K19,IF($C19="",0,IF($K19-$T$8<0,0,$K19-$T$8)))) -> 0 | V19: =IFERROR(IF(T19="",0,U19-T19-J19),"") -> 0 | W19: =IFERROR(FLOOR(K19,TIME(0,VLOOKUP($C$2,#REF!,22,0),0)),"") | X19: =IF(VLOOKUP($C$2,#REF!,24,0)="日当",IF(K19=0,"",IF(K19<T$8,VLOOKUP($C$2,#REF!,21,0)*VALUE(K19-T$8)*24+VLOOKUP($C$2,#REF!,19,0),VLOOKUP($C$2,#REF!,20,0)*VALUE(K19-T$8)*24+VLOOKUP($C$2,#REF!,19,0))),"") -> #REF!
A20: =IF(COUNTIFS(祝日参照用!A:A,C20)=1,1,IF(D20="土",1,IF(D20="日",1,0))) -> 0 | C20: =IF(C19="","",IF(DAY(C19+1)=1,"",C19+1)) | D20: =TEXT(C20,"ddd") | H20: =IF(G20="","","～") | J20: =IFERROR(IF(G20="",0,I20-G20),"") -> 0 | K20: =IFERROR(IF(E20="",0,F20-E20-J20),"") -> 0 | L20: =IF(E20="",0,IF($A20=1,$K20,IF($C20="",0,IF($K20-$T$8<0,0,$K20-$T$8)))) -> 0 | V20: =IFERROR(IF(T20="",0,U20-T20-J20),"") -> 0 | W20: =IFERROR(FLOOR(K20,TIME(0,VLOOKUP($C$2,#REF!,22,0),0)),"") | X20: =IF(VLOOKUP($C$2,#REF!,24,0)="日当",IF(K20=0,"",IF(K20<T$8,VLOOKUP($C$2,#REF!,21,0)*VALUE(K20-T$8)*24+VLOOKUP($C$2,#REF!,19,0),VLOOKUP($C$2,#REF!,20,0)*VALUE(K20-T$8)*24+VLOOKUP($C$2,#REF!,19,0))),"") -> #REF!
A21: =IF(COUNTIFS(祝日参照用!A:A,C21)=1,1,IF(D21="土",1,IF(D21="日",1,0))) -> 0 | C21: =IF(C20="","",IF(DAY(C20+1)=1,"",C20+1)) | D21: =TEXT(C21,"ddd") | H21: =IF(G21="","","～") | J21: =IFERROR(IF(G21="",0,I21-G21),"") -> 0 | K21: =IFERROR(IF(E21="",0,F21-E21-J21),"") -> 0 | L21: =IF(E21="",0,IF($A21=1,$K21,IF($C21="",0,IF($K21-$T$8<0,0,$K21-$T$8)))) -> 0 | V21: =IFERROR(IF(T21="",0,U21-T21-J21),"") -> 0 | W21: =IFERROR(FLOOR(K21,TIME(0,VLOOKUP($C$2,#REF!,22,0),0)),"") | X21: =IF(VLOOKUP($C$2,#REF!,24,0)="日当",IF(K21=0,"",IF(K21<T$8,VLOOKUP($C$2,#REF!,21,0)*VALUE(K21-T$8)*24+VLOOKUP($C$2,#REF!,19,0),VLOOKUP($C$2,#REF!,20,0)*VALUE(K21-T$8)*24+VLOOKUP($C$2,#REF!,19,0))),"") -> #REF!
A22: =IF(COUNTIFS(祝日参照用!A:A,C22)=1,1,IF(D22="土",1,IF(D22="日",1,0))) -> 0 | C22: =IF(C21="","",IF(DAY(C21+1)=1,"",C21+1)) | D22: =TEXT(C22,"ddd") | H22: =IF(G22="","","～") | J22: =IFERROR(IF(G22="",0,I22-G22),"") -> 0 | K22: =IFERROR(IF(E22="",0,F22-E22-J22),"") -> 0 | L22: =IF(E22="",0,IF($A22=1,$K22,IF($C22="",0,IF($K22-$T$8<0,0,$K22-$T$8)))) -> 0 | V22: =IFERROR(IF(T22="",0,U22-T22-J22),"") -> 0 | W22: =IFERROR(FLOOR(K22,TIME(0,VLOOKUP($C$2,#REF!,22,0),0)),"") | X22: =IF(VLOOKUP($C$2,#REF!,24,0)="日当",IF(K22=0,"",IF(K22<T$8,VLOOKUP($C$2,#REF!,21,0)*VALUE(K22-T$8)*24+VLOOKUP($C$2,#REF!,19,0),VLOOKUP($C$2,#REF!,20,0)*VALUE(K22-T$8)*24+VLOOKUP($C$2,#REF!,19,0))),"") -> #REF!
A23: =IF(COUNTIFS(祝日参照用!A:A,C23)=1,1,IF(D23="土",1,IF(D23="日",1,0))) -> 0 | C23: =IF(C22="","",IF(DAY(C22+1)=1,"",C22+1)) | D23: =TEXT(C23,"ddd") | H23: =IF(G23="","","～") | J23: =IFERROR(IF(G23="",0,I23-G23),"") -> 0 | K23: =IFERROR(IF(E23="",0,F23-E23-J23),"") -> 0 | L23: =IF(E23="",0,IF($A23=1,$K23,IF($C23="",0,IF($K23-$T$8<0,0,$K23-$T$8)))) -> 0 | V23: =IFERROR(IF(T23="",0,U23-T23-J23),"") -> 0 | W23: =IFERROR(FLOOR(K23,TIME(0,VLOOKUP($C$2,#REF!,22,0),0)),"") | X23: =IF(VLOOKUP($C$2,#REF!,24,0)="日当",IF(K23=0,"",IF(K23<T$8,VLOOKUP($C$2,#REF!,21,0)*VALUE(K23-T$8)*24+VLOOKUP($C$2,#REF!,19,0),VLOOKUP($C$2,#REF!,20,0)*VALUE(K23-T$8)*24+VLOOKUP($C$2,#REF!,19,0))),"") -> #REF!
A24: =IF(COUNTIFS(祝日参照用!A:A,C24)=1,1,IF(D24="土",1,IF(D24="日",1,0))) -> 0 | C24: =IF(C23="","",IF(DAY(C23+1)=1,"",C23+1)) | D24: =TEXT(C24,"ddd") | H24: =IF(G24="","","～") | J24: =IFERROR(IF(G24="",0,I24-G24),"") -> 0 | K24: =IFERROR(IF(E24="",0,F24-E24-J24),"") -> 0 | L24: =IF(E24="",0,IF($A24=1,$K24,IF($C24="",0,IF($K24-$T$8<0,0,$K24-$T$8)))) -> 0 | V24: =IFERROR(IF(T24="",0,U24-T24-J24),"") -> 0 | W24: =IFERROR(FLOOR(K24,TIME(0,VLOOKUP($C$2,#REF!,22,0),0)),"") | X24: =IF(VLOOKUP($C$2,#REF!,24,0)="日当",IF(K24=0,"",IF(K24<T$8,VLOOKUP($C$2,#REF!,21,0)*VALUE(K24-T$8)*24+VLOOKUP($C$2,#REF!,19,0),VLOOKUP($C$2,#REF!,20,0)*VALUE(K24-T$8)*24+VLOOKUP($C$2,#REF!,19,0))),"") -> #REF!
A25: =IF(COUNTIFS(祝日参照用!A:A,C25)=1,1,IF(D25="土",1,IF(D25="日",1,0))) -> 0 | C25: =IF(C24="","",IF(DAY(C24+1)=1,"",C24+1)) | D25: =TEXT(C25,"ddd") | H25: =IF(G25="","","～") | J25: =IFERROR(IF(G25="",0,I25-G25),"") -> 0 | K25: =IFERROR(IF(E25="",0,F25-E25-J25),"") -> 0 | L25: =IF(E25="",0,IF($A25=1,$K25,IF($C25="",0,IF($K25-$T$8<0,0,$K25-$T$8)))) -> 0 | V25: =IFERROR(IF(T25="",0,U25-T25-J25),"") -> 0 | W25: =IFERROR(FLOOR(K25,TIME(0,VLOOKUP($C$2,#REF!,22,0),0)),"") | X25: =IF(VLOOKUP($C$2,#REF!,24,0)="日当",IF(K25=0,"",IF(K25<T$8,VLOOKUP($C$2,#REF!,21,0)*VALUE(K25-T$8)*24+VLOOKUP($C$2,#REF!,19,0),VLOOKUP($C$2,#REF!,20,0)*VALUE(K25-T$8)*24+VLOOKUP($C$2,#REF!,19,0))),"") -> #REF!
A26: =IF(COUNTIFS(祝日参照用!A:A,C26)=1,1,IF(D26="土",1,IF(D26="日",1,0))) -> 0 | C26: =IF(C25="","",IF(DAY(C25+1)=1,"",C25+1)) | D26: =TEXT(C26,"ddd") | H26: =IF(G26="","","～") | J26: =IFERROR(IF(G26="",0,I26-G26),"") -> 0 | K26: =IFERROR(IF(E26="",0,F26-E26-J26),"") -> 0 | L26: =IF(E26="",0,IF($A26=1,$K26,IF($C26="",0,IF($K26-$T$8<0,0,$K26-$T$8)))) -> 0 | V26: =IFERROR(IF(T26="",0,U26-T26-J26),"") -> 0 | W26: =IFERROR(FLOOR(K26,TIME(0,VLOOKUP($C$2,#REF!,22,0),0)),"") | X26: =IF(VLOOKUP($C$2,#REF!,24,0)="日当",IF(K26=0,"",IF(K26<T$8,VLOOKUP($C$2,#REF!,21,0)*VALUE(K26-T$8)*24+VLOOKUP($C$2,#REF!,19,0),VLOOKUP($C$2,#REF!,20,0)*VALUE(K26-T$8)*24+VLOOKUP($C$2,#REF!,19,0))),"") -> #REF!
... A44: =IF(COUNTIFS(祝日参照用!A:A,C44)=1,1,IF(D44="土",1,IF(D44="日",1,0))) -> 0 | C44: =IF(C43="","",IF(DAY(C43+1)=1,"",C43+1)) | D44: =TEXT(C44,"ddd") | H44: =IF(G44="","","～") | J44: =IFERROR(IF(G44="",0,I44-G44),"") -> 0 | K44: =IFERROR(IF(E44="",0,F44-E44-J44),"") -> 0 | L44: =IF(E44="",0,IF($A44=1,$K44,IF($C44="",0,IF($K44-$T$8<0,0,$K44-$T$8)))) -> 0 | V44: =IFERROR(IF(T44="",0,U44-T44-J44),"") -> 0 | W44: =IFERROR(FLOOR(K44,TIME(0,VLOOKUP($C$2,#REF!,22,0),0)),"") | X44: =IF(VLOOKUP($C$2,#REF!,24,0)="日当",IF(K44=0,"",IF(K44<T$8,VLOOKUP($C$2,#REF!,21,0)*VALUE(K44-T$8)*24+VLOOKUP($C$2,#REF!,19,0),VLOOKUP($C$2,#REF!,20,0)*VALUE(K44-T$8)*24+VLOOKUP($C$2,#REF!,19,0))),"") -> #REF!
J45: =SUM(J14:J44) -> 0 | K45: =SUM(K14:K44) -> 0 | L45: =SUM(L14:L44) -> 0 | M45: =SUM(M14:M44) -> 0 | N45: =SUM(N14:N44) -> 0 | V45: =SUM(V14:V44) -> 0 | W45: =SUM(W14:W44) -> 0 | X45: =IF(Z5="日当",SUM(X14:X44),"")

Sheet 社員33
C1: SuccessHolders 勤務報告書 | M1: (西暦) | O1: =#REF! -> #REF! | Q1: 年 | R1: =#REF! -> #REF! | S1: 月分 | Y1: 勤怠サマリーへ
C2: 社員33 | Q2: 勤務日数： | S2: =COUNTA(E14:E44)&"日" -> 0日
C3: 派遣先企業名 | F3: =VLOOKUP($C$2,#REF!,4,0) -> #REF! | N3: 派遣先事業所名
C4: 派遣先住所
C5: 就業部署名 | N5: 連絡先
C6: 業務に伴う 責任の程度 | F6: (業務内容) | N6: 役職名 | R6: 部下 人数
C7: 実際の就業場所 | M7: 勤怠パターン | O7: 勤務時間 | R7: 休憩時間 | T7: 規定時間
O8: 0.39583333 | P8: ～ | Q8: 0.75 | R8: 0.041666667 | T8: =Q8-O8-R8 -> 0.3125
P9: ～ | T9: =Q9-O9-R9 -> 0
B10: 氏名 | C10: 氏名 | F10: =VLOOKUP($C$2,#REF!,3,0) -> #REF! | O10: フレックスタイム制
O11: 変形労働時間制
A13: 祝日判定 | B13: チェック | C13: 月 日 | D13: 曜 日 | E13: 出勤 時刻 | F13: 退勤 時刻 | G13: 休憩 時刻 | J13: 休憩 時間 | K13: 所定 時間 | L13: 法定外 残業 | M13: 深夜 時間 | N13: 不就労 | O13: 業務内容・作業進捗状況・その他 | T13: 出勤時刻(KOT) | U13: 退勤時刻 (KOT) | V13: 所定時間 (KOT) | W13: 所定時間 (調整) | X13: 日当計算
A14: =IF(COUNTIFS(祝日参照用!A:A,C14)=1,1,IF(D14="土",1,IF(D14="日",1,0))) -> 0 | C14: =IFERROR(DATE(O1,R1,1),"") | D14: =TEXT(C14,"ddd") | H14: =IF(G14="","","～") | J14: =IFERROR(IF(G14="",0,I14-G14),"") -> 0 | K14: =IFERROR(IF(E14="",0,F14-E14-J14),"") -> 0 | L14: =IF(E14="",0,IF($A14=1,$K14,IF($C14="",0,IF($K14-$T$8<0,0,$K14-$T$8)))) -> 0 | V14: =IFERROR(IF(T14="",0,U14-T14-J14),"") -> 0 | W14: =IFERROR(FLOOR(K14,TIME(0,VLOOKUP($C$2,#REF!,22,0),0)),"") | X14: =IF(VLOOKUP($C$2,#REF!,24,0)="日当",IF(K14=0,"",IF(K14<T$8,VLOOKUP($C$2,#REF!,21,0)*VALUE(K14-T$8)*24+VLOOKUP($C$2,#REF!,19,0),VLOOKUP($C$2,#REF!,20,0)*VALUE(K14-T$8)*24+VLOOKUP($C$2,#REF!,19,0))),"") -> #REF!
A15: =IF(COUNTIFS(祝日参照用!A:A,C15)=1,1,IF(D15="土",1,IF(D15="日",1,0))) -> 0 | C15: =IF(C14="","",IF(DAY(C14+1)=1,"",C14+1)) | D15: =TEXT(C15,"ddd") | H15: =IF(G15="","","～") | J15: =IFERROR(IF(G15="",0,I15-G15),"") -> 0 | K15: =IFERROR(IF(E15="",0,F15-E15-J15),"") -> 0 | L15: =IF(E15="",0,IF($A15=1,$K15,IF($C15="",0,IF($K15-$T$8<0,0,$K15-$T$8)))) -> 0 | V15: =IFERROR(IF(T15="",0,U15-T15-J15),"") -> 0 | W15: =IFERROR(FLOOR(K15,TIME(0,VLOOKUP($C$2,#REF!,22,0),0)),"") | X15: =IF(VLOOKUP($C$2,#REF!,24,0)="日当",IF(K15=0,"",IF(K15<T$8,VLOOKUP($C$2,#REF!,21,0)*VALUE(K15-T$8)*24+VLOOKUP($C$2,#REF!,19,0),VLOOKUP($C$2,#REF!,20,0)*VALUE(K15-T$8)*24+VLOOKUP($C$2,#REF!,19,0))),"") -> #REF!
A16: =IF(COUNTIFS(祝日参照用!A:A,C16)=1,1,IF(D16="土",1,IF(D16="日",1,0))) -> 0 | C16: =IF(C15="","",IF(DAY(C15+1)=1,"",C15+1)) | D16: =TEXT(C16,"ddd") | H16: =IF(G16="","","～") | J16: =IFERROR(IF(G16="",0,I16-G16),"") -> 0 | K16: =IFERROR(IF(E16="",0,F16-E16-J16),"") -> 0 | L16: =IF(E16="",0,IF($A16=1,$K16,IF($C16="",0,IF($K16-$T$8<0,0,$K16-$T$8)))) -> 0 | V16: =IFERROR(IF(T16="",0,U16-T16-J16),"") -> 0 | W16: =IFERROR(FLOOR(K16,TIME(0,VLOOKUP($C$2,#REF!,22,0),0)),"") | X16: =IF(VLOOKUP($C$2,#REF!,24,0)="日当",IF(K16=0,"",IF(K16<T$8,VLOOKUP($C$2,#REF!,21,0)*VALUE(K16-T$8)*24+VLOOKUP($C$2,#REF!,19,0),VLOOKUP($C$2,#REF!,20,0)*VALUE(K16-T$8)*24+VLOOKUP($C$2,#REF!,19,0))),"") -> #REF!
A17: =IF(COUNTIFS(祝日参照用!A:A,C17)=1,1,IF(D17="土",1,IF(D17="日",1,0))) -> 0 | C17: =IF(C16="","",IF(DAY(C16+1)=1,"",C16+1)) | D17: =TEXT(C17,"ddd") | H17: =IF(G17="","","～") | J17: =IFERROR(IF(G17="",0,I17-G17),"") -> 0 | K17: =IFERROR(IF(E17="",0,F17-E17-J17),"") -> 0 | L17: =IF(E17="",0,IF($A17=1,$K17,IF($C17="",0,IF($K17-$T$8<0,0,$K17-$T$8)))) -> 0 | V17: =IFERROR(IF(T17="",0,U17-T17-J17),"") -> 0 | W17: =IFERROR(FLOOR(K17,TIME(0,VLOOKUP($C$2,#REF!,22,0),0)),"") | X17: =IF(VLOOKUP($C$2,#REF!,24,0)="日当",IF(K17=0,"",IF(K17<T$8,VLOOKUP($C$2,#REF!,21,0)*VALUE(K17-T$8)*24+VLOOKUP($C$2,#REF!,19,0),VLOOKUP($C$2,#REF!,20,0)*VALUE(K17-T$8)*24+VLOOKUP($C$2,#REF!,19,0))),"") -> #REF!
A18: =IF(COUNTIFS(祝日参照用!A:A,C18)=1,1,IF(D18="土",1,IF(D18="日",1,0))) -> 0 | C18: =IF(C17="","",IF(DAY(C17+1)=1,"",C17+1)) | D18: =TEXT(C18,"ddd") | H18: =IF(G18="","","～") | J18: =IFERROR(IF(G18="",0,I18-G18),"") -> 0 | K18: =IFERROR(IF(E18="",0,F18-E18-J18),"") -> 0 | L18: =IF(E18="",0,IF($A18=1,$K18,IF($C18="",0,IF($K18-$T$8<0,0,$K18-$T$8)))) -> 0 | V18: =IFERROR(IF(T18="",0,U18-T18-J18),"") -> 0 | W18: =IFERROR(FLOOR(K18,TIME(0,VLOOKUP($C$2,#REF!,22,0),0)),"") | X18: =IF(VLOOKUP($C$2,#REF!,24,0)="日当",IF(K18=0,"",IF(K18<T$8,VLOOKUP($C$2,#REF!,21,0)*VALUE(K18-T$8)*24+VLOOKUP($C$2,#REF!,19,0),VLOOKUP($C$2,#REF!,20,0)*VALUE(K18-T$8)*24+VLOOKUP($C$2,#REF!,19,0))),"") -> #REF!
A19: =IF(COUNTIFS(祝日参照用!A:A,C19)=1,1,IF(D19="土",1,IF(D19="日",1,0))) -> 0 | C19: =IF(C18="","",IF(DAY(C18+1)=1,"",C18+1)) | D19: =TEXT(C19,"ddd") | H19: =IF(G19="","","～") | J19: =IFERROR(IF(G19="",0,I19-G19),"") -> 0 | K19: =IFERROR(IF(E19="",0,F19-E19-J19),"") -> 0 | L19: =IF(E19="",0,IF($A19=1,$K19,IF($C19="",0,IF($K19-$T$8<0,0,$K19-$T$8)))) -> 0 | V19: =IFERROR(IF(T19="",0,U19-T19-J19),"") -> 0 | W19: =IFERROR(FLOOR(K19,TIME(0,VLOOKUP($C$2,#REF!,22,0),0)),"") | X19: =IF(VLOOKUP($C$2,#REF!,24,0)="日当",IF(K19=0,"",IF(K19<T$8,VLOOKUP($C$2,#REF!,21,0)*VALUE(K19-T$8)*24+VLOOKUP($C$2,#REF!,19,0),VLOOKUP($C$2,#REF!,20,0)*VALUE(K19-T$8)*24+VLOOKUP($C$2,#REF!,19,0))),"") -> #REF!
A20: =IF(COUNTIFS(祝日参照用!A:A,C20)=1,1,IF(D20="土",1,IF(D20="日",1,0))) -> 0 | C20: =IF(C19="","",IF(DAY(C19+1)=1,"",C19+1)) | D20: =TEXT(C20,"ddd") | H20: =IF(G20="","","～") | J20: =IFERROR(IF(G20="",0,I20-G20),"") -> 0 | K20: =IFERROR(IF(E20="",0,F20-E20-J20),"") -> 0 | L20: =IF(E20="",0,IF($A20=1,$K20,IF($C20="",0,IF($K20-$T$8<0,0,$K20-$T$8)))) -> 0 | V20: =IFERROR(IF(T20="",0,U20-T20-J20),"") -> 0 | W20: =IFERROR(FLOOR(K20,TIME(0,VLOOKUP($C$2,#REF!,22,0),0)),"") | X20: =IF(VLOOKUP($C$2,#REF!,24,0)="日当",IF(K20=0,"",IF(K20<T$8,VLOOKUP($C$2,#REF!,21,0)*VALUE(K20-T$8)*24+VLOOKUP($C$2,#REF!,19,0),VLOOKUP($C$2,#REF!,20,0)*VALUE(K20-T$8)*24+VLOOKUP($C$2,#REF!,19,0))),"") -> #REF!
A21: =IF(COUNTIFS(祝日参照用!A:A,C21)=1,1,IF(D21="土",1,IF(D21="日",1,0))) -> 0 | C21: =IF(C20="","",IF(DAY(C20+1)=1,"",C20+1)) | D21: =TEXT(C21,"ddd") | H21: =IF(G21="","","～") | J21: =IFERROR(IF(G21="",0,I21-G21),"") -> 0 | K21: =IFERROR(IF(E21="",0,F21-E21-J21),"") -> 0 | L21: =IF(E21="",0,IF($A21=1,$K21,IF($C21="",0,IF($K21-$T$8<0,0,$K21-$T$8)))) -> 0 | V21: =IFERROR(IF(T21="",0,U21-T21-J21),"") -> 0 | W21: =IFERROR(FLOOR(K21,TIME(0,VLOOKUP($C$2,#REF!,22,0),0)),"") | X21: =IF(VLOOKUP($C$2,#REF!,24,0)="日当",IF(K21=0,"",IF(K21<T$8,VLOOKUP($C$2,#REF!,21,0)*VALUE(K21-T$8)*24+VLOOKUP($C$2,#REF!,19,0),VLOOKUP($C$2,#REF!,20,0)*VALUE(K21-T$8)*24+VLOOKUP($C$2,#REF!,19,0))),"") -> #REF!
A22: =IF(COUNTIFS(祝日参照用!A:A,C22)=1,1,IF(D22="土",1,IF(D22="日",1,0))) -> 0 | C22: =IF(C21="","",IF(DAY(C21+1)=1,"",C21+1)) | D22: =TEXT(C22,"ddd") | H22: =IF(G22="","","～") | J22: =IFERROR(IF(G22="",0,I22-G22),"") -> 0 | K22: =IFERROR(IF(E22="",0,F22-E22-J22),"") -> 0 | L22: =IF(E22="",0,IF($A22=1,$K22,IF($C22="",0,IF($K22-$T$8<0,0,$K22-$T$8)))) -> 0 | V22: =IFERROR(IF(T22="",0,U22-T22-J22),"") -> 0 | W22: =IFERROR(FLOOR(K22,TIME(0,VLOOKUP($C$2,#REF!,22,0),0)),"") | X22: =IF(VLOOKUP($C$2,#REF!,24,0)="日当",IF(K22=0,"",IF(K22<T$8,VLOOKUP($C$2,#REF!,21,0)*VALUE(K22-T$8)*24+VLOOKUP($C$2,#REF!,19,0),VLOOKUP($C$2,#REF!,20,0)*VALUE(K22-T$8)*24+VLOOKUP($C$2,#REF!,19,0))),"") -> #REF!
A23: =IF(COUNTIFS(祝日参照用!A:A,C23)=1,1,IF(D23="土",1,IF(D23="日",1,0))) -> 0 | C23: =IF(C22="","",IF(DAY(C22+1)=1,"",C22+1)) | D23: =TEXT(C23,"ddd") | H23: =IF(G23="","","～") | J23: =IFERROR(IF(G23="",0,I23-G23),"") -> 0 | K23: =IFERROR(IF(E23="",0,F23-E23-J23),"") -> 0 | L23: =IF(E23="",0,IF($A23=1,$K23,IF($C23="",0,IF($K23-$T$8<0,0,$K23-$T$8)))) -> 0 | V23: =IFERROR(IF(T23="",0,U23-T23-J23),"") -> 0 | W23: =IFERROR(FLOOR(K23,TIME(0,VLOOKUP($C$2,#REF!,22,0),0)),"") | X23: =IF(VLOOKUP($C$2,#REF!,24,0)="日当",IF(K23=0,"",IF(K23<T$8,VLOOKUP($C$2,#REF!,21,0)*VALUE(K23-T$8)*24+VLOOKUP($C$2,#REF!,19,0),VLOOKUP($C$2,#REF!,20,0)*VALUE(K23-T$8)*24+VLOOKUP($C$2,#REF!,19,0))),"") -> #REF!
A24: =IF(COUNTIFS(祝日参照用!A:A,C24)=1,1,IF(D24="土",1,IF(D24="日",1,0))) -> 0 | C24: =IF(C23="","",IF(DAY(C23+1)=1,"",C23+1)) | D24: =TEXT(C24,"ddd") | H24: =IF(G24="","","～") | J24: =IFERROR(IF(G24="",0,I24-G24),"") -> 0 | K24: =IFERROR(IF(E24="",0,F24-E24-J24),"") -> 0 | L24: =IF(E24="",0,IF($A24=1,$K24,IF($C24="",0,IF($K24-$T$8<0,0,$K24-$T$8)))) -> 0 | V24: =IFERROR(IF(T24="",0,U24-T24-J24),"") -> 0 | W24: =IFERROR(FLOOR(K24,TIME(0,VLOOKUP($C$2,#REF!,22,0),0)),"") | X24: =IF(VLOOKUP($C$2,#REF!,24,0)="日当",IF(K24=0,"",IF(K24<T$8,VLOOKUP($C$2,#REF!,21,0)*VALUE(K24-T$8)*24+VLOOKUP($C$2,#REF!,19,0),VLOOKUP($C$2,#REF!,20,0)*VALUE(K24-T$8)*24+VLOOKUP($C$2,#REF!,19,0))),"") -> #REF!
A25: =IF(COUNTIFS(祝日参照用!A:A,C25)=1,1,IF(D25="土",1,IF(D25="日",1,0))) -> 0 | C25: =IF(C24="","",IF(DAY(C24+1)=1,"",C24+1)) | D25: =TEXT(C25,"ddd") | H25: =IF(G25="","","～") | J25: =IFERROR(IF(G25="",0,I25-G25),"") -> 0 | K25: =IFERROR(IF(E25="",0,F25-E25-J25),"") -> 0 | L25: =IF(E25="",0,IF($A25=1,$K25,IF($C25="",0,IF($K25-$T$8<0,0,$K25-$T$8)))) -> 0 | V25: =IFERROR(IF(T25="",0,U25-T25-J25),"") -> 0 | W25: =IFERROR(FLOOR(K25,TIME(0,VLOOKUP($C$2,#REF!,22,0),0)),"") | X25: =IF(VLOOKUP($C$2,#REF!,24,0)="日当",IF(K25=0,"",IF(K25<T$8,VLOOKUP($C$2,#REF!,21,0)*VALUE(K25-T$8)*24+VLOOKUP($C$2,#REF!,19,0),VLOOKUP($C$2,#REF!,20,0)*VALUE(K25-T$8)*24+VLOOKUP($C$2,#REF!,19,0))),"") -> #REF!
A26: =IF(COUNTIFS(祝日参照用!A:A,C26)=1,1,IF(D26="土",1,IF(D26="日",1,0))) -> 0 | C26: =IF(C25="","",IF(DAY(C25+1)=1,"",C25+1)) | D26: =TEXT(C26,"ddd") | H26: =IF(G26="","","～") | J26: =IFERROR(IF(G26="",0,I26-G26),"") -> 0 | K26: =IFERROR(IF(E26="",0,F26-E26-J26),"") -> 0 | L26: =IF(E26="",0,IF($A26=1,$K26,IF($C26="",0,IF($K26-$T$8<0,0,$K26-$T$8)))) -> 0 | V26: =IFERROR(IF(T26="",0,U26-T26-J26),"") -> 0 | W26: =IFERROR(FLOOR(K26,TIME(0,VLOOKUP($C$2,#REF!,22,0),0)),"") | X26: =IF(VLOOKUP($C$2,#REF!,24,0)="日当",IF(K26=0,"",IF(K26<T$8,VLOOKUP($C$2,#REF!,21,0)*VALUE(K26-T$8)*24+VLOOKUP($C$2,#REF!,19,0),VLOOKUP($C$2,#REF!,20,0)*VALUE(K26-T$8)*24+VLOOKUP($C$2,#REF!,19,0))),"") -> #REF!
... A44: =IF(COUNTIFS(祝日参照用!A:A,C44)=1,1,IF(D44="土",1,IF(D44="日",1,0))) -> 0 | C44: =IF(C43="","",IF(DAY(C43+1)=1,"",C43+1)) | D44: =TEXT(C44,"ddd") | H44: =IF(G44="","","～") | J44: =IFERROR(IF(G44="",0,I44-G44),"") -> 0 | K44: =IFERROR(IF(E44="",0,F44-E44-J44),"") -> 0 | L44: =IF(E44="",0,IF($A44=1,$K44,IF($C44="",0,IF($K44-$T$8<0,0,$K44-$T$8)))) -> 0 | V44: =IFERROR(IF(T44="",0,U44-T44-J44),"") -> 0 | W44: =IFERROR(FLOOR(K44,TIME(0,VLOOKUP($C$2,#REF!,22,0),0)),"") | X44: =IF(VLOOKUP($C$2,#REF!,24,0)="日当",IF(K44=0,"",IF(K44<T$8,VLOOKUP($C$2,#REF!,21,0)*VALUE(K44-T$8)*24+VLOOKUP($C$2,#REF!,19,0),VLOOKUP($C$2,#REF!,20,0)*VALUE(K44-T$8)*24+VLOOKUP($C$2,#REF!,19,0))),"") -> #REF!
J45: =SUM(J14:J44) -> 0 | K45: =SUM(K14:K44) -> 0 | L45: =SUM(L14:L44) -> 0 | M45: =SUM(M14:M44) -> 0 | N45: =SUM(N14:N44) -> 0 | V45: =SUM(V14:V44) -> 0 | W45: =SUM(W14:W44) -> 0 | X45: =IF(Z5="日当",SUM(X14:X44),"")

Sheet 社員39
C1: SuccessHolders 勤務報告書 | M1: (西暦) | O1: =#REF! -> #REF! | Q1: 年 | R1: =#REF! -> #REF! | S1: 月分 | Y1: 勤怠サマリーへ
C2: 社員39 | Q2: 勤務日数： | S2: =COUNTA(E14:E44)&"日" -> 0日
C3: 派遣先企業名 | F3: =VLOOKUP($C$2,#REF!,4,0) -> #REF! | N3: 派遣先事業所名
C4: 派遣先住所
C5: 就業部署名 | N5: 連絡先
C6: 業務に伴う 責任の程度 | F6: (業務内容) | N6: 役職名 | R6: 部下 人数
C7: 実際の就業場所 | M7: 勤怠パターン | O7: 勤務時間 | R7: 休憩時間 | T7: 規定時間
P8: ～ | T8: =Q8-O8-R8 -> 0
P9: ～ | T9: =Q9-O9-R9 -> 0
B10: 氏名 | C10: 氏名 | F10: =VLOOKUP($C$2,#REF!,3,0) -> #REF! | O10: フレックスタイム制
O11: 変形労働時間制
A13: 祝日判定 | B13: チェック | C13: 月 日 | D13: 曜 日 | E13: 出勤 時刻 | F13: 退勤 時刻 | G13: 休憩 時刻 | J13: 休憩 時間 | K13: 所定 時間 | L13: 法定外 残業 | M13: 深夜 時間 | N13: 不就労 | O13: 業務内容・作業進捗状況・その他 | T13: 出勤時刻(KOT) | U13: 退勤時刻 (KOT) | V13: 所定時間 (KOT) | W13: 所定時間 (調整) | X13: 日当計算
A14: =IF(COUNTIFS(祝日参照用!A:A,C14)=1,1,IF(D14="土",1,IF(D14="日",1,0))) -> 0 | C14: =IFERROR(DATE(O1,R1,1),"") | D14: =TEXT(C14,"ddd") | H14: =IF(G14="","","～") | J14: =IFERROR(IF(G14="",0,I14-G14),"") -> 0 | K14: =IFERROR(IF(E14="",0,F14-E14-J14),"") -> 0 | L14: =IF(E14="",0,IF($A14=1,$K14,IF($C14="",0,IF($K14-$T$8<0,0,$K14-$T$8)))) -> 0 | V14: =IFERROR(IF(T14="",0,U14-T14-J14),"") -> 0 | W14: =IFERROR(FLOOR(K14,TIME(0,VLOOKUP($C$2,#REF!,22,0),0)),"") | X14: =IF(VLOOKUP($C$2,#REF!,24,0)="日当",IF(K14=0,"",IF(K14<T$8,VLOOKUP($C$2,#REF!,21,0)*VALUE(K14-T$8)*24+VLOOKUP($C$2,#REF!,19,0),VLOOKUP($C$2,#REF!,20,0)*VALUE(K14-T$8)*24+VLOOKUP($C$2,#REF!,19,0))),"") -> #REF!
A15: =IF(COUNTIFS(祝日参照用!A:A,C15)=1,1,IF(D15="土",1,IF(D15="日",1,0))) -> 0 | C15: =IF(C14="","",IF(DAY(C14+1)=1,"",C14+1)) | D15: =TEXT(C15,"ddd") | H15: =IF(G15="","","～") | J15: =IFERROR(IF(G15="",0,I15-G15),"") -> 0 | K15: =IFERROR(IF(E15="",0,F15-E15-J15),"") -> 0 | L15: =IF(E15="",0,IF($A15=1,$K15,IF($C15="",0,IF($K15-$T$8<0,0,$K15-$T$8)))) -> 0 | V15: =IFERROR(IF(T15="",0,U15-T15-J15),"") -> 0 | W15: =IFERROR(FLOOR(K15,TIME(0,VLOOKUP($C$2,#REF!,22,0),0)),"") | X15: =IF(VLOOKUP($C$2,#REF!,24,0)="日当",IF(K15=0,"",IF(K15<T$8,VLOOKUP($C$2,#REF!,21,0)*VALUE(K15-T$8)*24+VLOOKUP($C$2,#REF!,19,0),VLOOKUP($C$2,#REF!,20,0)*VALUE(K15-T$8)*24+VLOOKUP($C$2,#REF!,19,0))),"") -> #REF!
A16: =IF(COUNTIFS(祝日参照用!A:A,C16)=1,1,IF(D16="土",1,IF(D16="日",1,0))) -> 0 | C16: =IF(C15="","",IF(DAY(C15+1)=1,"",C15+1)) | D16: =TEXT(C16,"ddd") | H16: =IF(G16="","","～") | J16: =IFERROR(IF(G16="",0,I16-G16),"") -> 0 | K16: =IFERROR(IF(E16="",0,F16-E16-J16),"") -> 0 | L16: =IF(E16="",0,IF($A16=1,$K16,IF($C16="",0,IF($K16-$T$8<0,0,$K16-$T$8)))) -> 0 | V16: =IFERROR(IF(T16="",0,U16-T16-J16),"") -> 0 | W16: =IFERROR(FLOOR(K16,TIME(0,VLOOKUP($C$2,#REF!,22,0),0)),"") | X16: =IF(VLOOKUP($C$2,#REF!,24,0)="日当",IF(K16=0,"",IF(K16<T$8,VLOOKUP($C$2,#REF!,21,0)*VALUE(K16-T$8)*24+VLOOKUP($C$2,#REF!,19,0),VLOOKUP($C$2,#REF!,20,0)*VALUE(K16-T$8)*24+VLOOKUP($C$2,#REF!,19,0))),"") -> #REF!
A17: =IF(COUNTIFS(祝日参照用!A:A,C17)=1,1,IF(D17="土",1,IF(D17="日",1,0))) -> 0 | C17: =IF(C16="","",IF(DAY(C16+1)=1,"",C16+1)) | D17: =TEXT(C17,"ddd") | H17: =IF(G17="","","～") | J17: =IFERROR(IF(G17="",0,I17-G17),"") -> 0 | K17: =IFERROR(IF(E17="",0,F17-E17-J17),"") -> 0 | L17: =IF(E17="",0,IF($A17=1,$K17,IF($C17="",0,IF($K17-$T$8<0,0,$K17-$T$8)))) -> 0 | V17: =IFERROR(IF(T17="",0,U17-T17-J17),"") -> 0 | W17: =IFERROR(FLOOR(K17,TIME(0,VLOOKUP($C$2,#REF!,22,0),0)),"") | X17: =IF(VLOOKUP($C$2,#REF!,24,0)="日当",IF(K17=0,"",IF(K17<T$8,VLOOKUP($C$2,#REF!,21,0)*VALUE(K17-T$8)*24+VLOOKUP($C$2,#REF!,19,0),VLOOKUP($C$2,#REF!,20,0)*VALUE(K17-T$8)*24+VLOOKUP($C$2,#REF!,19,0))),"") -> #REF!
A18: =IF(COUNTIFS(祝日参照用!A:A,C18)=1,1,IF(D18="土",1,IF(D18="日",1,0))) -> 0 | C18: =IF(C17="","",IF(DAY(C17+1)=1,"",C17+1)) | D18: =TEXT(C18,"ddd") | H18: =IF(G18="","","～") | J18: =IFERROR(IF(G18="",0,I18-G18),"") -> 0 | K18: =IFERROR(IF(E18="",0,F18-E18-J18),"") -> 0 | L18: =IF(E18="",0,IF($A18=1,$K18,IF($C18="",0,IF($K18-$T$8<0,0,$K18-$T$8)))) -> 0 | V18: =IFERROR(IF(T18="",0,U18-T18-J18),"") -> 0 | W18: =IFERROR(FLOOR(K18,TIME(0,VLOOKUP($C$2,#REF!,22,0),0)),"") | X18: =IF(VLOOKUP($C$2,#REF!,24,0)="日当",IF(K18=0,"",IF(K18<T$8,VLOOKUP($C$2,#REF!,21,0)*VALUE(K18-T$8)*24+VLOOKUP($C$2,#REF!,19,0),VLOOKUP($C$2,#REF!,20,0)*VALUE(K18-T$8)*24+VLOOKUP($C$2,#REF!,19,0))),"") -> #REF!
A19: =IF(COUNTIFS(祝日参照用!A:A,C19)=1,1,IF(D19="土",1,IF(D19="日",1,0))) -> 0 | C19: =IF(C18="","",IF(DAY(C18+1)=1,"",C18+1)) | D19: =TEXT(C19,"ddd") | H19: =IF(G19="","","～") | J19: =IFERROR(IF(G19="",0,I19-G19),"") -> 0 | K19: =IFERROR(IF(E19="",0,F19-E19-J19),"") -> 0 | L19: =IF(E19="",0,IF($A19=1,$K19,IF($C19="",0,IF($K19-$T$8<0,0,$K19-$T$8)))) -> 0 | V19: =IFERROR(IF(T19="",0,U19-T19-J19),"") -> 0 | W19: =IFERROR(FLOOR(K19,TIME(0,VLOOKUP($C$2,#REF!,22,0),0)),"") | X19: =IF(VLOOKUP($C$2,#REF!,24,0)="日当",IF(K19=0,"",IF(K19<T$8,VLOOKUP($C$2,#REF!,21,0)*VALUE(K19-T$8)*24+VLOOKUP($C$2,#REF!,19,0),VLOOKUP($C$2,#REF!,20,0)*VALUE(K19-T$8)*24+VLOOKUP($C$2,#REF!,19,0))),"") -> #REF!
A20: =IF(COUNTIFS(祝日参照用!A:A,C20)=1,1,IF(D20="土",1,IF(D20="日",1,0))) -> 0 | C20: =IF(C19="","",IF(DAY(C19+1)=1,"",C19+1)) | D20: =TEXT(C20,"ddd") | H20: =IF(G20="","","～") | J20: =IFERROR(IF(G20="",0,I20-G20),"") -> 0 | K20: =IFERROR(IF(E20="",0,F20-E20-J20),"") -> 0 | L20: =IF(E20="",0,IF($A20=1,$K20,IF($C20="",0,IF($K20-$T$8<0,0,$K20-$T$8)))) -> 0 | V20: =IFERROR(IF(T20="",0,U20-T20-J20),"") -> 0 | W20: =IFERROR(FLOOR(K20,TIME(0,VLOOKUP($C$2,#REF!,22,0),0)),"") | X20: =IF(VLOOKUP($C$2,#REF!,24,0)="日当",IF(K20=0,"",IF(K20<T$8,VLOOKUP($C$2,#REF!,21,0)*VALUE(K20-T$8)*24+VLOOKUP($C$2,#REF!,19,0),VLOOKUP($C$2,#REF!,20,0)*VALUE(K20-T$8)*24+VLOOKUP($C$2,#REF!,19,0))),"") -> #REF!
A21: =IF(COUNTIFS(祝日参照用!A:A,C21)=1,1,IF(D21="土",1,IF(D21="日",1,0))) -> 0 | C21: =IF(C20="","",IF(DAY(C20+1)=1,"",C20+1)) | D21: =TEXT(C21,"ddd") | H21: =IF(G21="","","～") | J21: =IFERROR(IF(G21="",0,I21-G21),"") -> 0 | K21: =IFERROR(IF(E21="",0,F21-E21-J21),"") -> 0 | L21: =IF(E21="",0,IF($A21=1,$K21,IF($C21="",0,IF($K21-$T$8<0,0,$K21-$T$8)))) -> 0 | V21: =IFERROR(IF(T21="",0,U21-T21-J21),"") -> 0 | W21: =IFERROR(FLOOR(K21,TIME(0,VLOOKUP($C$2,#REF!,22,0),0)),"") | X21: =IF(VLOOKUP($C$2,#REF!,24,0)="日当",IF(K21=0,"",IF(K21<T$8,VLOOKUP($C$2,#REF!,21,0)*VALUE(K21-T$8)*24+VLOOKUP($C$2,#REF!,19,0),VLOOKUP($C$2,#REF!,20,0)*VALUE(K21-T$8)*24+VLOOKUP($C$2,#REF!,19,0))),"") -> #REF!
A22: =IF(COUNTIFS(祝日参照用!A:A,C22)=1,1,IF(D22="土",1,IF(D22="日",1,0))) -> 0 | C22: =IF(C21="","",IF(DAY(C21+1)=1,"",C21+1)) | D22: =TEXT(C22,"ddd") | H22: =IF(G22="","","～") | J22: =IFERROR(IF(G22="",0,I22-G22),"") -> 0 | K22: =IFERROR(IF(E22="",0,F22-E22-J22),"") -> 0 | L22: =IF(E22="",0,IF($A22=1,$K22,IF($C22="",0,IF($K22-$T$8<0,0,$K22-$T$8)))) -> 0 | V22: =IFERROR(IF(T22="",0,U22-T22-J22),"") -> 0 | W22: =IFERROR(FLOOR(K22,TIME(0,VLOOKUP($C$2,#REF!,22,0),0)),"") | X22: =IF(VLOOKUP($C$2,#REF!,24,0)="日当",IF(K22=0,"",IF(K22<T$8,VLOOKUP($C$2,#REF!,21,0)*VALUE(K22-T$8)*24+VLOOKUP($C$2,#REF!,19,0),VLOOKUP($C$2,#REF!,20,0)*VALUE(K22-T$8)*24+VLOOKUP($C$2,#REF!,19,0))),"") -> #REF!
A23: =IF(COUNTIFS(祝日参照用!A:A,C23)=1,1,IF(D23="土",1,IF(D23="日",1,0))) -> 0 | C23: =IF(C22="","",IF(DAY(C22+1)=1,"",C22+1)) | D23: =TEXT(C23,"ddd") | H23: =IF(G23="","","～") | J23: =IFERROR(IF(G23="",0,I23-G23),"") -> 0 | K23: =IFERROR(IF(E23="",0,F23-E23-J23),"") -> 0 | L23: =IF(E23="",0,IF($A23=1,$K23,IF($C23="",0,IF($K23-$T$8<0,0,$K23-$T$8)))) -> 0 | V23: =IFERROR(IF(T23="",0,U23-T23-J23),"") -> 0 | W23: =IFERROR(FLOOR(K23,TIME(0,VLOOKUP($C$2,#REF!,22,0),0)),"") | X23: =IF(VLOOKUP($C$2,#REF!,24,0)="日当",IF(K23=0,"",IF(K23<T$8,VLOOKUP($C$2,#REF!,21,0)*VALUE(K23-T$8)*24+VLOOKUP($C$2,#REF!,19,0),VLOOKUP($C$2,#REF!,20,0)*VALUE(K23-T$8)*24+VLOOKUP($C$2,#REF!,19,0))),"") -> #REF!
A24: =IF(COUNTIFS(祝日参照用!A:A,C24)=1,1,IF(D24="土",1,IF(D24="日",1,0))) -> 0 | C24: =IF(C23="","",IF(DAY(C23+1)=1,"",C23+1)) | D24: =TEXT(C24,"ddd") | H24: =IF(G24="","","～") | J24: =IFERROR(IF(G24="",0,I24-G24),"") -> 0 | K24: =IFERROR(IF(E24="",0,F24-E24-J24),"") -> 0 | L24: =IF(E24="",0,IF($A24=1,$K24,IF($C24="",0,IF($K24-$T$8<0,0,$K24-$T$8)))) -> 0 | V24: =IFERROR(IF(T24="",0,U24-T24-J24),"") -> 0 | W24: =IFERROR(FLOOR(K24,TIME(0,VLOOKUP($C$2,#REF!,22,0),0)),"") | X24: =IF(VLOOKUP($C$2,#REF!,24,0)="日当",IF(K24=0,"",IF(K24<T$8,VLOOKUP($C$2,#REF!,21,0)*VALUE(K24-T$8)*24+VLOOKUP($C$2,#REF!,19,0),VLOOKUP($C$2,#REF!,20,0)*VALUE(K24-T$8)*24+VLOOKUP($C$2,#REF!,19,0))),"") -> #REF!
A25: =IF(COUNTIFS(祝日参照用!A:A,C25)=1,1,IF(D25="土",1,IF(D25="日",1,0))) -> 0 | C25: =IF(C24="","",IF(DAY(C24+1)=1,"",C24+1)) | D25: =TEXT(C25,"ddd") | H25: =IF(G25="","","～") | J25: =IFERROR(IF(G25="",0,I25-G25),"") -> 0 | K25: =IFERROR(IF(E25="",0,F25-E25-J25),"") -> 0 | L25: =IF(E25="",0,IF($A25=1,$K25,IF($C25="",0,IF($K25-$T$8<0,0,$K25-$T$8)))) -> 0 | V25: =IFERROR(IF(T25="",0,U25-T25-J25),"") -> 0 | W25: =IFERROR(FLOOR(K25,TIME(0,VLOOKUP($C$2,#REF!,22,0),0)),"") | X25: =IF(VLOOKUP($C$2,#REF!,24,0)="日当",IF(K25=0,"",IF(K25<T$8,VLOOKUP($C$2,#REF!,21,0)*VALUE(K25-T$8)*24+VLOOKUP($C$2,#REF!,19,0),VLOOKUP($C$2,#REF!,20,0)*VALUE(K25-T$8)*24+VLOOKUP($C$2,#REF!,19,0))),"") -> #REF!
A26: =IF(COUNTIFS(祝日参照用!A:A,C26)=1,1,IF(D26="土",1,IF(D26="日",1,0))) -> 0 | C26: =IF(C25="","",IF(DAY(C25+1)=1,"",C25+1)) | D26: =TEXT(C26,"ddd") | H26: =IF(G26="","","～") | J26: =IFERROR(IF(G26="",0,I26-G26),"") -> 0 | K26: =IFERROR(IF(E26="",0,F26-E26-J26),"") -> 0 | L26: =IF(E26="",0,IF($A26=1,$K26,IF($C26="",0,IF($K26-$T$8<0,0,$K26-$T$8)))) -> 0 | V26: =IFERROR(IF(T26="",0,U26-T26-J26),"") -> 0 | W26: =IFERROR(FLOOR(K26,TIME(0,VLOOKUP($C$2,#REF!,22,0),0)),"") | X26: =IF(VLOOKUP($C$2,#REF!,24,0)="日当",IF(K26=0,"",IF(K26<T$8,VLOOKUP($C$2,#REF!,21,0)*VALUE(K26-T$8)*24+VLOOKUP($C$2,#REF!,19,0),VLOOKUP($C$2,#REF!,20,0)*VALUE(K26-T$8)*24+VLOOKUP($C$2,#REF!,19,0))),"") -> #REF!
... A44: =IF(COUNTIFS(祝日参照用!A:A,C44)=1,1,IF(D44="土",1,IF(D44="日",1,0))) -> 0 | C44: =IF(C43="","",IF(DAY(C43+1)=1,"",C43+1)) | D44: =TEXT(C44,"ddd") | H44: =IF(G44="","","～") | J44: =IFERROR(IF(G44="",0,I44-G44),"") -> 0 | K44: =IFERROR(IF(E44="",0,F44-E44-J44),"") -> 0 | L44: =IF(E44="",0,IF($A44=1,$K44,IF($C44="",0,IF($K44-$T$8<0,0,$K44-$T$8)))) -> 0 | V44: =IFERROR(IF(T44="",0,U44-T44-J44),"") -> 0 | W44: =IFERROR(FLOOR(K44,TIME(0,VLOOKUP($C$2,#REF!,22,0),0)),"") | X44: =IF(VLOOKUP($C$2,#REF!,24,0)="日当",IF(K44=0,"",IF(K44<T$8,VLOOKUP($C$2,#REF!,21,0)*VALUE(K44-T$8)*24+VLOOKUP($C$2,#REF!,19,0),VLOOKUP($C$2,#REF!,20,0)*VALUE(K44-T$8)*24+VLOOKUP($C$2,#REF!,19,0))),"") -> #REF!
J45: =SUM(J14:J44) -> 0 | K45: =SUM(K14:K44) -> 0 | L45: =SUM(L14:L44) -> 0 | M45: =SUM(M14:M44) -> 0 | N45: =SUM(N14:N44) -> 0 | V45: =SUM(V14:V44) -> 0 | W45: =SUM(W14:W44) -> 0 | X45: =IF(Z5="日当",SUM(X14:X44),"")

Sheet 社員40
C1: SuccessHolders 勤務報告書 | M1: (西暦) | O1: =#REF! -> #REF! | Q1: 年 | R1: =#REF! -> #REF! | S1: 月分 | Y1: 勤怠サマリーへ
C2: 社員40 | Q2: 勤務日数： | S2: =COUNTA(E14:E44)&"日" -> 0日
C3: 派遣先企業名 | F3: =VLOOKUP($C$2,#REF!,4,0) -> #REF! | N3: 派遣先事業所名
C4: 派遣先住所
C5: 就業部署名 | N5: 連絡先
C6: 業務に伴う 責任の程度 | F6: (業務内容) | N6: 役職名 | R6: 部下 人数
C7: 実際の就業場所 | M7: 勤怠パターン | O7: 勤務時間 | R7: 休憩時間 | T7: 規定時間
P8: ～ | T8: =Q8-O8-R8 -> 0
P9: ～ | T9: =Q9-O9-R9 -> 0
B10: 氏名 | C10: 氏名 | F10: =VLOOKUP($C$2,#REF!,3,0) -> #REF! | O10: フレックスタイム制
O11: 変形労働時間制
A13: 祝日判定 | B13: チェック | C13: 月 日 | D13: 曜 日 | E13: 出勤 時刻 | F13: 退勤 時刻 | G13: 休憩 時刻 | J13: 休憩 時間 | K13: 所定 時間 | L13: 法定外 残業 | M13: 深夜 時間 | N13: 不就労 | O13: 業務内容・作業進捗状況・その他 | T13: 出勤時刻(KOT) | U13: 退勤時刻 (KOT) | V13: 所定時間 (KOT) | W13: 所定時間 (調整) | X13: 日当計算
A14: =IF(COUNTIFS(祝日参照用!A:A,C14)=1,1,IF(D14="土",1,IF(D14="日",1,0))) -> 0 | C14: =IFERROR(DATE(O1,R1,1),"") | D14: =TEXT(C14,"ddd") | H14: =IF(G14="","","～") | J14: =IFERROR(IF(G14="",0,I14-G14),"") -> 0 | K14: =IFERROR(IF(E14="",0,F14-E14-J14),"") -> 0 | L14: =IF(E14="",0,IF($A14=1,$K14,IF($C14="",0,IF($K14-$T$8<0,0,$K14-$T$8)))) -> 0 | V14: =IFERROR(IF(T14="",0,U14-T14-J14),"") -> 0 | W14: =IFERROR(FLOOR(K14,TIME(0,VLOOKUP($C$2,#REF!,22,0),0)),"") | X14: =IF(VLOOKUP($C$2,#REF!,24,0)="日当",IF(K14=0,"",IF(K14<T$8,VLOOKUP($C$2,#REF!,21,0)*VALUE(K14-T$8)*24+VLOOKUP($C$2,#REF!,19,0),VLOOKUP($C$2,#REF!,20,0)*VALUE(K14-T$8)*24+VLOOKUP($C$2,#REF!,19,0))),"") -> #REF!
A15: =IF(COUNTIFS(祝日参照用!A:A,C15)=1,1,IF(D15="土",1,IF(D15="日",1,0))) -> 0 | C15: =IF(C14="","",IF(DAY(C14+1)=1,"",C14+1)) | D15: =TEXT(C15,"ddd") | H15: =IF(G15="","","～") | J15: =IFERROR(IF(G15="",0,I15-G15),"") -> 0 | K15: =IFERROR(IF(E15="",0,F15-E15-J15),"") -> 0 | L15: =IF(E15="",0,IF($A15=1,$K15,IF($C15="",0,IF($K15-$T$8<0,0,$K15-$T$8)))) -> 0 | V15: =IFERROR(IF(T15="",0,U15-T15-J15),"") -> 0 | W15: =IFERROR(FLOOR(K15,TIME(0,VLOOKUP($C$2,#REF!,22,0),0)),"") | X15: =IF(VLOOKUP($C$2,#REF!,24,0)="日当",IF(K15=0,"",IF(K15<T$8,VLOOKUP($C$2,#REF!,21,0)*VALUE(K15-T$8)*24+VLOOKUP($C$2,#REF!,19,0),VLOOKUP($C$2,#REF!,20,0)*VALUE(K15-T$8)*24+VLOOKUP($C$2,#REF!,19,0))),"") -> #REF!
A16: =IF(COUNTIFS(祝日参照用!A:A,C16)=1,1,IF(D16="土",1,IF(D16="日",1,0))) -> 0 | C16: =IF(C15="","",IF(DAY(C15+1)=1,"",C15+1)) | D16: =TEXT(C16,"ddd") | H16: =IF(G16="","","～") | J16: =IFERROR(IF(G16="",0,I16-G16),"") -> 0 | K16: =IFERROR(IF(E16="",0,F16-E16-J16),"") -> 0 | L16: =IF(E16="",0,IF($A16=1,$K16,IF($C16="",0,IF($K16-$T$8<0,0,$K16-$T$8)))) -> 0 | V16: =IFERROR(IF(T16="",0,U16-T16-J16),"") -> 0 | W16: =IFERROR(FLOOR(K16,TIME(0,VLOOKUP($C$2,#REF!,22,0),0)),"") | X16: =IF(VLOOKUP($C$2,#REF!,24,0)="日当",IF(K16=0,"",IF(K16<T$8,VLOOKUP($C$2,#REF!,21,0)*VALUE(K16-T$8)*24+VLOOKUP($C$2,#REF!,19,0),VLOOKUP($C$2,#REF!,20,0)*VALUE(K16-T$8)*24+VLOOKUP($C$2,#REF!,19,0))),"") -> #REF!
A17: =IF(COUNTIFS(祝日参照用!A:A,C17)=1,1,IF(D17="土",1,IF(D17="日",1,0))) -> 0 | C17: =IF(C16="","",IF(DAY(C16+1)=1,"",C16+1)) | D17: =TEXT(C17,"ddd") | H17: =IF(G17="","","～") | J17: =IFERROR(IF(G17="",0,I17-G17),"") -> 0 | K17: =IFERROR(IF(E17="",0,F17-E17-J17),"") -> 0 | L17: =IF(E17="",0,IF($A17=1,$K17,IF($C17="",0,IF($K17-$T$8<0,0,$K17-$T$8)))) -> 0 | V17: =IFERROR(IF(T17="",0,U17-T17-J17),"") -> 0 | W17: =IFERROR(FLOOR(K17,TIME(0,VLOOKUP($C$2,#REF!,22,0),0)),"") | X17: =IF(VLOOKUP($C$2,#REF!,24,0)="日当",IF(K17=0,"",IF(K17<T$8,VLOOKUP($C$2,#REF!,21,0)*VALUE(K17-T$8)*24+VLOOKUP($C$2,#REF!,19,0),VLOOKUP($C$2,#REF!,20,0)*VALUE(K17-T$8)*24+VLOOKUP($C$2,#REF!,19,0))),"") -> #REF!
A18: =IF(COUNTIFS(祝日参照用!A:A,C18)=1,1,IF(D18="土",1,IF(D18="日",1,0))) -> 0 | C18: =IF(C17="","",IF(DAY(C17+1)=1,"",C17+1)) | D18: =TEXT(C18,"ddd") | H18: =IF(G18="","","～") | J18: =IFERROR(IF(G18="",0,I18-G18),"") -> 0 | K18: =IFERROR(IF(E18="",0,F18-E18-J18),"") -> 0 | L18: =IF(E18="",0,IF($A18=1,$K18,IF($C18="",0,IF($K18-$T$8<0,0,$K18-$T$8)))) -> 0 | V18: =IFERROR(IF(T18="",0,U18-T18-J18),"") -> 0 | W18: =IFERROR(FLOOR(K18,TIME(0,VLOOKUP($C$2,#REF!,22,0),0)),"") | X18: =IF(VLOOKUP($C$2,#REF!,24,0)="日当",IF(K18=0,"",IF(K18<T$8,VLOOKUP($C$2,#REF!,21,0)*VALUE(K18-T$8)*24+VLOOKUP($C$2,#REF!,19,0),VLOOKUP($C$2,#REF!,20,0)*VALUE(K18-T$8)*24+VLOOKUP($C$2,#REF!,19,0))),"") -> #REF!
A19: =IF(COUNTIFS(祝日参照用!A:A,C19)=1,1,IF(D19="土",1,IF(D19="日",1,0))) -> 0 | C19: =IF(C18="","",IF(DAY(C18+1)=1,"",C18+1)) | D19: =TEXT(C19,"ddd") | H19: =IF(G19="","","～") | J19: =IFERROR(IF(G19="",0,I19-G19),"") -> 0 | K19: =IFERROR(IF(E19="",0,F19-E19-J19),"") -> 0 | L19: =IF(E19="",0,IF($A19=1,$K19,IF($C19="",0,IF($K19-$T$8<0,0,$K19-$T$8)))) -> 0 | V19: =IFERROR(IF(T19="",0,U19-T19-J19),"") -> 0 | W19: =IFERROR(FLOOR(K19,TIME(0,VLOOKUP($C$2,#REF!,22,0),0)),"") | X19: =IF(VLOOKUP($C$2,#REF!,24,0)="日当",IF(K19=0,"",IF(K19<T$8,VLOOKUP($C$2,#REF!,21,0)*VALUE(K19-T$8)*24+VLOOKUP($C$2,#REF!,19,0),VLOOKUP($C$2,#REF!,20,0)*VALUE(K19-T$8)*24+VLOOKUP($C$2,#REF!,19,0))),"") -> #REF!
